Workbook
Name f_ini: 'PAINEL'!$B$7
Name f_fim: 'PAINEL'!$D$7
Name f_un: 'PAINEL'!$F$7
Name f_tr: 'PAINEL'!$I$7
Name f_de: 'PAINEL'!$L$7
Name f_res: 'PAINEL'!$O$7
Name f_sit: 'PAINEL'!$Q$7
Name r_ini: 'RELATÓRIOS'!$B$7
Name r_fim: 'RELATÓRIOS'!$C$7
Name r_un: 'RELATÓRIOS'!$D$7
Name r_de: 'RELATÓRIOS'!$F$7
Name cfg_org: 'CONFIGURAÇÕES'!$C$6
Name cfg_massa: 'CONFIGURAÇÕES'!$C$7
Name cfg_rec: 'CONFIGURAÇÕES'!$C$8
Name cfg_cdf: 'CONFIGURAÇÕES'!$C$9
Name cfg_tol: 'CONFIGURAÇÕES'!$C$10
Name cfg_cancel: 'CONFIGURAÇÕES'!$C$11
Name cfg_versao: 'CONFIGURAÇÕES'!$C$12
Name lst_sistemas: OFFSET('CONFIGURAÇÕES'!$B$17,0,0,MAX(1,COUNTA('CONFIGURAÇÕES'!$B$17:$B$26)),1)
Name lst_sit_mtr: OFFSET('CONFIGURAÇÕES'!$C$17,0,0,MAX(1,COUNTA('CONFIGURAÇÕES'!$C$17:$C$28)),1)
Name lst_sit_cdf: OFFSET('CONFIGURAÇÕES'!$D$17,0,0,MAX(1,COUNTA('CONFIGURAÇÕES'!$D$17:$D$26)),1)
Name lst_modal: OFFSET('CONFIGURAÇÕES'!$E$17,0,0,MAX(1,COUNTA('CONFIGURAÇÕES'!$E$17:$E$36)),1)
Name lst_uf: OFFSET('CONFIGURAÇÕES'!$F$17,0,0,MAX(1,COUNTA('CONFIGURAÇÕES'!$F$17:$F$43)),1)
Name lst_un: OFFSET('CONFIGURAÇÕES'!$G$17,0,0,MAX(1,COUNTA('CONFIGURAÇÕES'!$G$17:$G$26)),1)
Name lst_simnao: OFFSET('CONFIGURAÇÕES'!$I$17,0,0,MAX(1,COUNTA('CONFIGURAÇÕES'!$I$17:$I$18)),1)
Name lst_tipo: OFFSET('CONFIGURAÇÕES'!$J$17,0,0,MAX(1,COUNTA('CONFIGURAÇÕES'!$J$17:$J$24)),1)
Name lst_papel: OFFSET('CONFIGURAÇÕES'!$K$17,0,0,MAX(1,COUNTA('CONFIGURAÇÕES'!$K$17:$K$24)),1)
Name lst_sitcad: OFFSET('CONFIGURAÇÕES'!$L$17,0,0,MAX(1,COUNTA('CONFIGURAÇÕES'!$L$17:$L$21)),1)
Name cfg_units: 'CONFIGURAÇÕES'!$G$17:$G$26
Name cfg_fac: 'CONFIGURAÇÕES'!$H$17:$H$26
Name cfg_pt: 'CONFIGURAÇÕES'!$B$52:$B$58
Name cfg_pp: 'CONFIGURAÇÕES'!$C$52:$C$58
Name cfg_pv: 'CONFIGURAÇÕES'!$D$52:$D$58
Name lst_unidades: OFFSET('CONFIGURAÇÕES'!$AA$6,0,0,MAX(1,MAX('CAD_UNIDADES'!$N$6:$N$105)),1)
Name lst_transp: OFFSET('CONFIGURAÇÕES'!$AB$6,0,0,MAX(1,MAX('CAD_PARCEIROS'!$S$6:$S$205)),1)
Name cmp_transp: 'CONFIGURAÇÕES'!$AB$6:$AB$205
Name lst_dest: OFFSET('CONFIGURAÇÕES'!$AC$6,0,0,MAX(1,MAX('CAD_PARCEIROS'!$U$6:$U$205)),1)
Name cmp_dest: 'CONFIGURAÇÕES'!$AC$6:$AC$205
Name lst_res: OFFSET('CONFIGURAÇÕES'!$AD$6,0,0,MAX(1,MAX('CAD_RESÍDUOS'!$L$6:$L$205)),1)
Name lst_mtr: OFFSET('CONFIGURAÇÕES'!$AE$6,0,0,MAX(1,MAX('MTRs'!$BE$6:$BE$505)),1)
Name lst_itens: OFFSET('CONFIGURAÇÕES'!$AF$6,0,0,MAX(1,MAX('ITENS_MTR'!$AT$6:$AT$1005)),1)
Name lst_cdf: OFFSET('CONFIGURAÇÕES'!$AG$6,0,0,MAX(1,MAX('CDFs'!$Z$6:$Z$505)),1)
Name lst_f_unid: OFFSET('CONFIGURAÇÕES'!$AH$6,0,0,MAX(1,MAX('CAD_UNIDADES'!$N$6:$N$105))+1,1)
Name lst_f_transp: OFFSET('CONFIGURAÇÕES'!$AI$6,0,0,MAX(1,MAX('CAD_PARCEIROS'!$S$6:$S$205))+1,1)
Name lst_f_dest: OFFSET('CONFIGURAÇÕES'!$AJ$6,0,0,MAX(1,MAX('CAD_PARCEIROS'!$U$6:$U$205))+1,1)
Name lst_f_res: OFFSET('CONFIGURAÇÕES'!$AK$6,0,0,MAX(1,MAX('CAD_RESÍDUOS'!$L$6:$L$205))+1,1)
Name lst_f_sit: 'CONFIGURAÇÕES'!$AL$6:$AL$14

Sheet INÍCIO
B2: PLANILHA PRONTA DE CONTROLE DE MTR E CDF | N2: BÔNUS 02
B3: Organize movimentações, acompanhe documentos e identifique pendências. | N3: ♻
B6: 📄 MTR | E6: ➜ | F6: 🚚 TRANSPORTE | I6: ➜ | J6: 🏭 DESTINATÁRIO | M6: ➜ | N6: 📜 CDF
B7: Recebimento e destinação são etapas diferentes: a planilha acompanha cada uma separadamente.
B9: COMECE EM 5 PASSOS
B10: 01 | E10: 02 | H10: 03 | K10: 04 | N10: 05
B11: CADASTRE AS UNIDADES | E11: CADASTRE OS PARCEIROS | H11: REGISTRE OS MTRs | K11: ACOMPANHE O RECEBIMENTO | N11: VINCULE OS CDFs
B12: Informe os estabelecimentos que serão utilizados. | E12: Adicione transportadores e destinadores. | H12: Inclua os documentos e seus resíduos. | K12: Atualize a situação com base nos registros disponíveis. | N12: Registre os certificados e confira o painel.
B13: abrir CAD_UNIDADES ▶ | E13: abrir CAD_PARCEIROS ▶ | H13: abrir MTRs ▶ | K13: abrir RECEBIMENTOS ▶ | N13: abrir CDFs ▶
B15: NAVEGAÇÃO RÁPIDA
B16: ABRIR PAINEL ▶ | G16: CADASTRAR MTR ▶ | L16: CONSULTAR RECEBIMENTOS ▶
B18: REGISTRAR CDF ▶ | G18: VER PENDÊNCIAS ▶ | L18: ABRIR RELATÓRIOS ▶
B21: LEGENDA DE CORES
B22: AZUL-CLARO | E22: CINZA-CLARO | H22: VERDE | K22: AMARELO | N22: VERMELHO-CLARO
B23: informações para preencher. | E23: informações calculadas automaticamente. | H23: informação conferida. | K23: atenção ou revisão necessária. | N23: inconsistência relevante ou registro que exige providência.
B24: Na Central de Pendências, LARANJA indica pendência em acompanhamento e CINZA indica informação não disponível ou cancelamento informado.
B26: COMO A PLANILHA FUNCIONA
B27: 1 | C27: Sequência de preenchimento: CADASTROS → MTRs → ITENS_MTR → RECEBIMENTOS → CDFs → VÍNCULOS_CDF → PAINEL.
B28: 2 | C28: Cada registro já tem um ID interno fixo (MTR-000001, IT-000001, CDF-000001). Ele não muda ao ordenar ou filtrar. Nas outras abas, escolha o MTR, o item ou o CDF pela lista suspensa.
B29: 3 | C29: Você registra o que leu nos documentos e sistemas oficiais. A planilha não emite MTR nem CDF, não se conecta ao SINIR e não altera registros oficiais.
B30: 4 | C30: O recebimento só conta como confirmado com RECEBIMENTO CONFERIDO? = Sim e um documento ou link de evidência. Recebimento confirmado não significa destinação comprovada: isso depende do CDF.
B31: 5 | C31: Um CDF pode cobrir vários MTRs. Na aba VÍNCULOS_CDF, cada linha liga o CDF a um item, com a quantidade documentada. A planilha mostra quanto já tem vínculo e quanto ainda falta.
B32: 6 | C32: Diferenças de quantidade geram alerta de revisão, nunca conclusão automática de irregularidade. Depois de analisar, marque DIFERENÇA ANALISADA? = Sim no item.
B33: 7 | C33: MTR com cancelamento informado continua no histórico, mas sai dos cards 02 a 06 e das quantidades em kg. O termo de cancelamento é definido em CONFIGURAÇÕES.
B34: 8 | C34: Prazos de alerta (15 dias como sugestão) são parâmetros internos, ajustáveis em CONFIGURAÇÕES. Não são prazos legais.
B35: 9 | C35: Capacidade pronta: 500 MTRs, 1.000 itens, 1.000 recebimentos, 500 CDFs e 1.000 vínculos. Para volumes maiores, recomendamos usar um arquivo por ano.
B36: 10 | C36: Compatibilidade: Excel 365 ou Excel 2019 em diante (usa a função MÁXIMOSES). Sem macros e sem internet. O funcionamento no Google Sheets não foi testado.
B37: 11 | C37: As colunas automáticas ficam protegidas sem senha para evitar que fórmulas sejam apagadas. Filtros funcionam normalmente. Se precisar ordenar ou mudar a estrutura, use Revisão > Desproteger Planilha.
B39: Esta ferramenta organiza registros internos e não substitui os documentos oficiais nem os procedimentos exigíveis.
B40: Versão 1.0 | outubro de 2026

Sheet PAINEL
B2: ♻ PAINEL DE CONTROLE — MTR E CDF | Q2: BÔNUS 02
B3: Acompanhe movimentações, documentos e pendências em um só lugar. | Q3: =IF(cfg_org="","Atualizado em "&TEXT(DAY(TODAY()),"00")&"/"&TEXT(MONTH(TODAY()),"00")&"/"&YEAR(TODAY()),cfg_org) -> Atualizado em 19/10/2026
B4: ◀ INÍCIO | D4: PENDÊNCIAS | F4: RELATÓRIOS | H4: MTRs
V5: DADOS DOS GRÁFICOS (automático)
B6: ▼ Período inicial | D6: ▼ Período final | F6: ▼ Unidade geradora | I6: ▼ Transportador | L6: ▼ Destinador | O6: ▼ Tipo de resíduo | Q6: ▼ Situação documental | V6: Situação | W6: MTRs
F7: (Todas) | I7: (Todos) | L7: (Todos) | O7: (Todos) | Q7: (Todas) | V7: Cadastro incompleto | W7: =COUNTIFS('MTRs'!$AY$6:$AY$505,1,'MTRs'!$S$6:$S$505,V7) -> 0
B8: Os filtros de período usam a DATA DE EMISSÃO DO MTR. Deixe as datas em branco e as listas em (Todas)/(Todos) para ver tudo. MTRs com cancelamento informado ficam fora dos cards 02 a 06 e das quantidades. | V8: Informação a revisar | W8: =COUNTIFS('MTRs'!$AY$6:$AY$505,1,'MTRs'!$S$6:$S$505,V8) -> 0
V9: Aguardando recebimento | W9: =COUNTIFS('MTRs'!$AY$6:$AY$505,1,'MTRs'!$S$6:$S$505,V9) -> 0
B10: 📄 TOTAL DE MTRs | E10: 🚚⏱ AGUARDANDO RECEBIMENTO | H10: ✅ RECEBIMENTO CONFIRMADO | K10: 🔎 AGUARDANDO CDF | N10: 🗂 DOCUMENTAÇÃO CONFERIDA | Q10: ⚠ REGISTROS A REVISAR | V10: Aguardando CDF | W10: =COUNTIFS('MTRs'!$AY$6:$AY$505,1,'MTRs'!$S$6:$S$505,V10) -> 0
B11: =COUNTIFS('MTRs'!$AY$6:$AY$505,1) -> 0 | E11: =COUNTIFS('MTRs'!$AY$6:$AY$505,1,'MTRs'!$AA$6:$AA$505,0,'MTRs'!$AN$6:$AN$505,0) -> 0 | H11: =COUNTIFS('MTRs'!$AY$6:$AY$505,1,'MTRs'!$AA$6:$AA$505,0,'MTRs'!$AN$6:$AN$505,1) -> 0 | K11: =COUNTIFS('MTRs'!$AY$6:$AY$505,1,'MTRs'!$AA$6:$AA$505,0,'MTRs'!$AN$6:$AN$505,1,'MTRs'!$AO$6:$AO$505,0) -> 0 | N11: =COUNTIFS('MTRs'!$AY$6:$AY$505,1,'MTRs'!$S$6:$S$505,"Documentação conferida") -> 0 | Q11: =COUNTIFS('MTRs'!$AY$6:$AY$505,1,'MTRs'!$S$6:$S$505,"Informação a revisar")+COUNTIFS('MTRs'!$AY$6:$AY$505,1,'MTRs'!$S$6:$S$505,"Cadastro incompleto") -> 0 | V11: Vínculo de CDF parcial | W11: =COUNTIFS('MTRs'!$AY$6:$AY$505,1,'MTRs'!$S$6:$S$505,V11) -> 0
V12: CDF localizado, a conferir | W12: =COUNTIFS('MTRs'!$AY$6:$AY$505,1,'MTRs'!$S$6:$S$505,V12) -> 0
B13: ="Inclui "&COUNTIFS('MTRs'!$AY$6:$AY$505,1,'MTRs'!$AA$6:$AA$505,1)&" com cancelamento informado" -> Inclui 0 com cancelamento informado | E13: ="Sem recebimento informado e conferido" -> Sem recebimento informado e conferido | H13: ="Todos os itens com recebimento conferido" -> Todos os itens com recebimento conferido | K13: ="Recebidos, sem CDF suficiente ou conferido" -> Recebidos, sem CDF suficiente ou conferido | N13: ="Conferência interna concluída" -> Conferência interna concluída | Q13: ="Inconsistências pelas regras internas" -> Inconsistências pelas regras internas | V13: Documentação conferida | W13: =COUNTIFS('MTRs'!$AY$6:$AY$505,1,'MTRs'!$S$6:$S$505,V13) -> 0
V14: Cancelado (informado) | W14: =COUNTIFS('MTRs'!$AY$6:$AY$505,1,'MTRs'!$S$6:$S$505,V14) -> 0
B15: INDICADORES COMPLEMENTARES
B16: Quantidade movimentada (kg) | E16: Com recebimento informado (kg) | H16: Vinculada a CDF (kg) | K16: CDFs cadastrados | N16: CDFs conferidos | Q16: Pendências acompanhadas
B17: =SUMIFS('ITENS_MTR'!$I$6:$I$1005,'ITENS_MTR'!$AP$6:$AP$1005,1,'ITENS_MTR'!$Y$6:$Y$1005,1) -> 0 | E17: =SUMIFS('ITENS_MTR'!$L$6:$L$1005,'ITENS_MTR'!$AP$6:$AP$1005,1) -> 0 | H17: =SUMIFS('ITENS_MTR'!$M$6:$M$1005,'ITENS_MTR'!$AP$6:$AP$1005,1) -> 0 | K17: =COUNTIF('CDFs'!$S$6:$S$505,1) -> 0 | N17: =COUNTIF('CDFs'!$Q$6:$Q$505,"Conferido") -> 0 | Q17: =COUNTIFS('MTRs'!$AY$6:$AY$505,1,'MTRs'!$AV$6:$AV$505,1) -> 0 | V17: Mês | W17: Mês/ano | X17: kg | Y17: Base
B18: ="Itens fora da soma por unidade ou quantidade a conferir: "&COUNTIFS('ITENS_MTR'!$AP$6:$AP$1005,1,'ITENS_MTR'!$Y$6:$Y$1005,0) -> Itens fora da soma por unidade ou quantidade a conferir: 0 | E18: ="Soma dos recebimentos registrados" -> Soma dos recebimentos registrados | H18: ="Soma dos vínculos registrados" -> Soma dos vínculos registrados | K18: ="Total geral, sem filtros" -> Total geral, sem filtros | N18: ="Total geral, sem filtros" -> Total geral, sem filtros | Q18: ="MTRs com pendência principal" -> MTRs com pendência principal | V18: =IF(ISNUMBER(f_ini),DATE(YEAR(f_ini),MONTH(f_ini),1),EDATE(DATE(YEAR(Y18),MONTH(Y18),1),-11)) -> 45962 | W18: =CHOOSE(MONTH(V18),"jan","fev","mar","abr","mai","jun","jul","ago","set","out","nov","dez")&"/"&RIGHT(YEAR(V18),2) -> nov/25 | X18: =SUMIFS('ITENS_MTR'!$I$6:$I$1005,'ITENS_MTR'!$AP$6:$AP$1005,1,'ITENS_MTR'!$Y$6:$Y$1005,1,'ITENS_MTR'!$AQ$6:$AQ$1005,V18) -> 0 | Y18: =IF(ISNUMBER(f_fim),f_fim,IF(MAX('MTRs'!$E$6:$E$505)>0,MAX('MTRs'!$E$6:$E$505),TODAY())) -> 46314
V19: =EDATE(V18,1) -> 45992 | W19: =CHOOSE(MONTH(V19),"jan","fev","mar","abr","mai","jun","jul","ago","set","out","nov","dez")&"/"&RIGHT(YEAR(V19),2) -> dez/25 | X19: =SUMIFS('ITENS_MTR'!$I$6:$I$1005,'ITENS_MTR'!$AP$6:$AP$1005,1,'ITENS_MTR'!$Y$6:$Y$1005,1,'ITENS_MTR'!$AQ$6:$AQ$1005,V19) -> 0
B20: GRÁFICOS | V20: =EDATE(V19,1) -> 46023 | W20: =CHOOSE(MONTH(V20),"jan","fev","mar","abr","mai","jun","jul","ago","set","out","nov","dez")&"/"&RIGHT(YEAR(V20),2) -> jan/26 | X20: =SUMIFS('ITENS_MTR'!$I$6:$I$1005,'ITENS_MTR'!$AP$6:$AP$1005,1,'ITENS_MTR'!$Y$6:$Y$1005,1,'ITENS_MTR'!$AQ$6:$AQ$1005,V20) -> 0
V21: =EDATE(V20,1) -> 46054 | W21: =CHOOSE(MONTH(V21),"jan","fev","mar","abr","mai","jun","jul","ago","set","out","nov","dez")&"/"&RIGHT(YEAR(V21),2) -> fev/26 | X21: =SUMIFS('ITENS_MTR'!$I$6:$I$1005,'ITENS_MTR'!$AP$6:$AP$1005,1,'ITENS_MTR'!$Y$6:$Y$1005,1,'ITENS_MTR'!$AQ$6:$AQ$1005,V21) -> 0
V22: =EDATE(V21,1) -> 46082 | W22: =CHOOSE(MONTH(V22),"jan","fev","mar","abr","mai","jun","jul","ago","set","out","nov","dez")&"/"&RIGHT(YEAR(V22),2) -> mar/26 | X22: =SUMIFS('ITENS_MTR'!$I$6:$I$1005,'ITENS_MTR'!$AP$6:$AP$1005,1,'ITENS_MTR'!$Y$6:$Y$1005,1,'ITENS_MTR'!$AQ$6:$AQ$1005,V22) -> 0
V23: =EDATE(V22,1) -> 46113 | W23: =CHOOSE(MONTH(V23),"jan","fev","mar","abr","mai","jun","jul","ago","set","out","nov","dez")&"/"&RIGHT(YEAR(V23),2) -> abr/26 | X23: =SUMIFS('ITENS_MTR'!$I$6:$I$1005,'ITENS_MTR'!$AP$6:$AP$1005,1,'ITENS_MTR'!$Y$6:$Y$1005,1,'ITENS_MTR'!$AQ$6:$AQ$1005,V23) -> 0
V24: =EDATE(V23,1) -> 46143 | W24: =CHOOSE(MONTH(V24),"jan","fev","mar","abr","mai","jun","jul","ago","set","out","nov","dez")&"/"&RIGHT(YEAR(V24),2) -> mai/26 | X24: =SUMIFS('ITENS_MTR'!$I$6:$I$1005,'ITENS_MTR'!$AP$6:$AP$1005,1,'ITENS_MTR'!$Y$6:$Y$1005,1,'ITENS_MTR'!$AQ$6:$AQ$1005,V24) -> 0
V25: =EDATE(V24,1) -> 46174 | W25: =CHOOSE(MONTH(V25),"jan","fev","mar","abr","mai","jun","jul","ago","set","out","nov","dez")&"/"&RIGHT(YEAR(V25),2) -> jun/26 | X25: =SUMIFS('ITENS_MTR'!$I$6:$I$1005,'ITENS_MTR'!$AP$6:$AP$1005,1,'ITENS_MTR'!$Y$6:$Y$1005,1,'ITENS_MTR'!$AQ$6:$AQ$1005,V25) -> 0
V26: =EDATE(V25,1) -> 46204 | W26: =CHOOSE(MONTH(V26),"jan","fev","mar","abr","mai","jun","jul","ago","set","out","nov","dez")&"/"&RIGHT(YEAR(V26),2) -> jul/26 | X26: =SUMIFS('ITENS_MTR'!$I$6:$I$1005,'ITENS_MTR'!$AP$6:$AP$1005,1,'ITENS_MTR'!$Y$6:$Y$1005,1,'ITENS_MTR'!$AQ$6:$AQ$1005,V26) -> 0
V27: =EDATE(V26,1) -> 46235 | W27: =CHOOSE(MONTH(V27),"jan","fev","mar","abr","mai","jun","jul","ago","set","out","nov","dez")&"/"&RIGHT(YEAR(V27),2) -> ago/26 | X27: =SUMIFS('ITENS_MTR'!$I$6:$I$1005,'ITENS_MTR'!$AP$6:$AP$1005,1,'ITENS_MTR'!$Y$6:$Y$1005,1,'ITENS_MTR'!$AQ$6:$AQ$1005,V27) -> 0
V28: =EDATE(V27,1) -> 46266 | W28: =CHOOSE(MONTH(V28),"jan","fev","mar","abr","mai","jun","jul","ago","set","out","nov","dez")&"/"&RIGHT(YEAR(V28),2) -> set/26 | X28: =SUMIFS('ITENS_MTR'!$I$6:$I$1005,'ITENS_MTR'!$AP$6:$AP$1005,1,'ITENS_MTR'!$Y$6:$Y$1005,1,'ITENS_MTR'!$AQ$6:$AQ$1005,V28) -> 0
V29: =EDATE(V28,1) -> 46296 | W29: =CHOOSE(MONTH(V29),"jan","fev","mar","abr","mai","jun","jul","ago","set","out","nov","dez")&"/"&RIGHT(YEAR(V29),2) -> out/26 | X29: =SUMIFS('ITENS_MTR'!$I$6:$I$1005,'ITENS_MTR'!$AP$6:$AP$1005,1,'ITENS_MTR'!$Y$6:$Y$1005,1,'ITENS_MTR'!$AQ$6:$AQ$1005,V29) -> 0
V32: chave | W32: Resíduo | X32: kg
V33: =IFERROR(LARGE('CAD_RESÍDUOS'!$N$6:$N$205,1),"") | W33: =IF(V33="","",INDEX('CAD_RESÍDUOS'!$B$6:$B$205,MATCH(V33,'CAD_RESÍDUOS'!$N$6:$N$205,0))) | X33: =IF(V33="",0,INDEX('CAD_RESÍDUOS'!$M$6:$M$205,MATCH(V33,'CAD_RESÍDUOS'!$N$6:$N$205,0))) -> 0
V34: =IFERROR(LARGE('CAD_RESÍDUOS'!$N$6:$N$205,2),"") | W34: =IF(V34="","",INDEX('CAD_RESÍDUOS'!$B$6:$B$205,MATCH(V34,'CAD_RESÍDUOS'!$N$6:$N$205,0))) | X34: =IF(V34="",0,INDEX('CAD_RESÍDUOS'!$M$6:$M$205,MATCH(V34,'CAD_RESÍDUOS'!$N$6:$N$205,0))) -> 0
V35: =IFERROR(LARGE('CAD_RESÍDUOS'!$N$6:$N$205,3),"") | W35: =IF(V35="","",INDEX('CAD_RESÍDUOS'!$B$6:$B$205,MATCH(V35,'CAD_RESÍDUOS'!$N$6:$N$205,0))) | X35: =IF(V35="",0,INDEX('CAD_RESÍDUOS'!$M$6:$M$205,MATCH(V35,'CAD_RESÍDUOS'!$N$6:$N$205,0))) -> 0
V36: =IFERROR(LARGE('CAD_RESÍDUOS'!$N$6:$N$205,4),"") | W36: =IF(V36="","",INDEX('CAD_RESÍDUOS'!$B$6:$B$205,MATCH(V36,'CAD_RESÍDUOS'!$N$6:$N$205,0))) | X36: =IF(V36="",0,INDEX('CAD_RESÍDUOS'!$M$6:$M$205,MATCH(V36,'CAD_RESÍDUOS'!$N$6:$N$205,0))) -> 0
V37: =IFERROR(LARGE('CAD_RESÍDUOS'!$N$6:$N$205,5),"") | W37: =IF(V37="","",INDEX('CAD_RESÍDUOS'!$B$6:$B$205,MATCH(V37,'CAD_RESÍDUOS'!$N$6:$N$205,0))) | X37: =IF(V37="",0,INDEX('CAD_RESÍDUOS'!$M$6:$M$205,MATCH(V37,'CAD_RESÍDUOS'!$N$6:$N$205,0))) -> 0
V38: =IFERROR(LARGE('CAD_RESÍDUOS'!$N$6:$N$205,6),"") | W38: =IF(V38="","",INDEX('CAD_RESÍDUOS'!$B$6:$B$205,MATCH(V38,'CAD_RESÍDUOS'!$N$6:$N$205,0))) | X38: =IF(V38="",0,INDEX('CAD_RESÍDUOS'!$M$6:$M$205,MATCH(V38,'CAD_RESÍDUOS'!$N$6:$N$205,0))) -> 0
V39: =IFERROR(LARGE('CAD_RESÍDUOS'!$N$6:$N$205,7),"") | W39: =IF(V39="","",INDEX('CAD_RESÍDUOS'!$B$6:$B$205,MATCH(V39,'CAD_RESÍDUOS'!$N$6:$N$205,0))) | X39: =IF(V39="",0,INDEX('CAD_RESÍDUOS'!$M$6:$M$205,MATCH(V39,'CAD_RESÍDUOS'!$N$6:$N$205,0))) -> 0
V40: =IFERROR(LARGE('CAD_RESÍDUOS'!$N$6:$N$205,8),"") | W40: =IF(V40="","",INDEX('CAD_RESÍDUOS'!$B$6:$B$205,MATCH(V40,'CAD_RESÍDUOS'!$N$6:$N$205,0))) | X40: =IF(V40="",0,INDEX('CAD_RESÍDUOS'!$M$6:$M$205,MATCH(V40,'CAD_RESÍDUOS'!$N$6:$N$205,0))) -> 0
V43: chave | W43: Destinador | X43: MTRs
V44: =IFERROR(LARGE('CAD_PARCEIROS'!$W$6:$W$205,1),"") | W44: =IF(V44="","",INDEX('CAD_PARCEIROS'!$P$6:$P$205,MATCH(V44,'CAD_PARCEIROS'!$W$6:$W$205,0))) | X44: =IF(V44="",0,INDEX('CAD_PARCEIROS'!$V$6:$V$205,MATCH(V44,'CAD_PARCEIROS'!$W$6:$W$205,0))) -> 0
V45: =IFERROR(LARGE('CAD_PARCEIROS'!$W$6:$W$205,2),"") | W45: =IF(V45="","",INDEX('CAD_PARCEIROS'!$P$6:$P$205,MATCH(V45,'CAD_PARCEIROS'!$W$6:$W$205,0))) | X45: =IF(V45="",0,INDEX('CAD_PARCEIROS'!$V$6:$V$205,MATCH(V45,'CAD_PARCEIROS'!$W$6:$W$205,0))) -> 0
...

Sheet MTRs
A1: CADASTRO DE MTRs
A2: Cada linha é um MTR. Preencha as colunas azuis com os dados do documento oficial. As colunas cinzas são calculadas pela planilha. Depois de cadastrar o MTR, registre os resíduos dele na aba ITENS_MTR.
A3: ◀ INÍCIO | B3: PAINEL | C3: PENDÊNCIAS | D3: Azul-claro = preencher | Cinza = automático | Linhas prontas: 500 registros
A4: ID FIXO | B4: PREENCHER | C4: PREENCHER | D4: PREENCHER | E4: PREENCHER | F4: PREENCHER | G4: PREENCHER | H4: PREENCHER | I4: PREENCHER | J4: PREENCHER | K4: PREENCHER | L4: PREENCHER | M4: PREENCHER | N4: PREENCHER | O4: PREENCHER | P4: AUTOMÁTICO | Q4: AUTOMÁTICO | R4: AUTOMÁTICO | S4: AUTOMÁTICO | T4: AUTOMÁTICO | U4: AUTOMÁTICO | V4: AUTOMÁTICO | W4: AUTOMÁTICO | X4: AUTOMÁTICO | Y4: AUTOMÁTICO
A5: ID interno do MTR | B5: Número oficial do MTR | C5: Sistema de origem | D5: UF do sistema | E5: Data de emissão | F5: Data de saída | G5: Unidade geradora | H5: Transportador | I5: Unidade destinatária | J5: UF de destino | K5: Situação informada no sistema | L5: Data da última consulta | M5: Link ou caminho do arquivo MTR | N5: Responsável pelo lançamento | O5: Observações | P5: Quantidade total vinculada ao MTR (kg) | Q5: Quantidade recebida registrada (kg) | R5: Quantidade vinculada a CDF (kg) | S5: Situação interna de acompanhamento | T5: Pendência principal | U5: Dias em acompanhamento | V5: Quantidade recebida conferida (kg) | W5: Nº de itens | X5: Alerta de duplicidade | Y5: Todas as pendências identificadas | Z5: aux registro ativo | AA5: aux cancelado | AB5: aux chave duplicidade | AC5: aux duplicado | AD5: aux identificação a revisar | AE5: aux incompleto | AF5: aux itens com dado a revisar | AG5: aux itens recebidos conferidos | AH5: aux itens com quantidade a revisar | AI5: aux itens com CDF ok | AJ5: aux itens com cobertura | AK5: aux recebimentos com alerta | AL5: aux vínculos com alerta | AM5: aux nº recebimentos | AN5: aux recebimento conferido | AO5: aux cdf completo | AP5: aux última data recebimento | AQ5: aux data de referência | AR5: aux acima do prazo interno | AS5: aux prioridade | AT5: aux providência | AU5: aux ordem pendência | AV5: aux tem pendência | AW5: aux texto pendências | AX5: aux filtro painel sem resíduo | AY5: aux filtro painel | AZ5: aux mês emissão | BA5: aux filtro relatórios | BB5: aux ordem relatório 06 | BC5: aux ordem relatório 05 | BD5: aux rótulo seleção | BE5: aux ordem seleção | BF5: aux participante
A6: MTR-000001 | P6: =IF(Z6=0,"",SUMIFS('ITENS_MTR'!$I$6:$I$1005,'ITENS_MTR'!$S$6:$S$1005,A6,'ITENS_MTR'!$Y$6:$Y$1005,1)) | Q6: =IF(Z6=0,"",SUMIFS('RECEBIMENTOS'!$H$6:$H$1005,'RECEBIMENTOS'!$B$6:$B$1005,A6,'RECEBIMENTOS'!$X$6:$X$1005,1)) | R6: =IF(Z6=0,"",SUMIFS('VÍNCULOS_CDF'!$H$6:$H$1005,'VÍNCULOS_CDF'!$D$6:$D$1005,A6,'VÍNCULOS_CDF'!$V$6:$V$1005,1)) | S6: =IF(Z6=0,"",IF(AA6=1,"Cancelado (informado)",IF(AE6=1,"Cadastro incompleto",IF(OR(AC6=1,AD6=1,AF6>0,AH6>0,AK6>0,AL6>0),"Informação a revisar",IF(AN6=0,"Aguardando recebimento",IF(N(R6)=0,"Aguardando CDF",IF(AJ6<N(W6),"Vínculo de CDF parcial",IF(AO6=0,"CDF localizado, a conferir","Documentação conferida")))))))) | T6: =IF(Z6=0,"",IF(S6="Cadastro incompleto","MTR INCOMPLETO",IF(S6="Informação a revisar",IF(AND(AH6>0,AC6=0,AD6=0,AF6=0,AK6=0,AL6=0),"QUANTIDADE A REVISAR","IDENTIFICAÇÃO A REVISAR"),IF(S6="Aguardando recebimento","RECEBIMENTO NÃO CONFIRMADO",IF(S6="Aguardando CDF","CDF NÃO LOCALIZADO",IF(S6="Vínculo de CDF parcial","VÍNCULO INCOMPLETO",IF(S6="CDF localizado, a conferir","CDF A CONFERIR",""))))))) | U6: =IF(T6="","",IF(AQ6="","Não calculável",IF(AQ6>TODAY(),"Data futura",TODAY()-AQ6))) | V6: =IF(Z6=0,"",SUMIFS('RECEBIMENTOS'!$H$6:$H$1005,'RECEBIMENTOS'!$B$6:$B$1005,A6,'RECEBIMENTOS'!$Z$6:$Z$1005,1)) | W6: =IF(Z6=0,"",COUNTIFS('ITENS_MTR'!$S$6:$S$1005,A6,'ITENS_MTR'!$R$6:$R$1005,1)) | X6: =IF(AC6=1,"POSSÍVEL DUPLICIDADE","") | Y6: =IF(Z6=0,"",IF(AW6="","Nenhuma",LEFT(AW6,LEN(AW6)-2))) | Z6: =IF(COUNTA(B6:O6)>0,1,0) -> 0 | AA6: =IF(AND(Z6=1,K6<>""),IF(TRIM(K6)=TRIM(cfg_cancel),1,0),0) -> 0 | AB6: =IF(AND(Z6=1,B6<>""),C6&"|"&D6&"|"&G6&"|"&TRIM(B6),"") | AC6: =IF(AB6="",0,IF(SUMPRODUCT(--($AB$6:$AB$505=AB6))>1,1,0)) -> 0 | AD6: =IF(Z6=0,0,IF(OR(AND(G6<>"",ISNA(MATCH(G6,'CAD_UNIDADES'!$C$6:$C$105,0))),AND(H6<>"",ISNA(MATCH(H6,cmp_transp,0))),AND(I6<>"",ISNA(MATCH(I6,cmp_dest,0))),AND(E6<>"",NOT(ISNUMBER(E6))),AND(F6<>"",NOT(ISNUMBER(F6))),AND(ISNUMBER(E6),ISNUMBER(F6),F6<E6)),1,0)) -> 0 | AE6: =IF(Z6=0,0,IF(OR(B6="",C6="",E6="",G6="",H6="",I6="",N(W6)=0),1,0)) -> 0 | AF6: =IF(Z6=0,0,COUNTIFS('ITENS_MTR'!$S$6:$S$1005,A6,'ITENS_MTR'!$AI$6:$AI$1005,1)) -> 0 | AG6: =IF(Z6=0,0,COUNTIFS('ITENS_MTR'!$S$6:$S$1005,A6,'ITENS_MTR'!$AJ$6:$AJ$1005,1)) -> 0 | AH6: =IF(Z6=0,0,COUNTIFS('ITENS_MTR'!$S$6:$S$1005,A6,'ITENS_MTR'!$AM$6:$AM$1005,1)) -> 0 | AI6: =IF(Z6=0,0,COUNTIFS('ITENS_MTR'!$S$6:$S$1005,A6,'ITENS_MTR'!$AO$6:$AO$1005,1)) -> 0 | AJ6: =IF(Z6=0,0,COUNTIFS('ITENS_MTR'!$S$6:$S$1005,A6,'ITENS_MTR'!$AN$6:$AN$1005,1)) -> 0 | AK6: =IF(Z6=0,0,COUNTIFS('RECEBIMENTOS'!$B$6:$B$1005,A6,'RECEBIMENTOS'!$Y$6:$Y$1005,1)) -> 0 | AL6: =IF(Z6=0,0,COUNTIFS('VÍNCULOS_CDF'!$D$6:$D$1005,A6,'VÍNCULOS_CDF'!$Y$6:$Y$1005,1)) -> 0 | AM6: =IF(Z6=0,0,COUNTIFS('RECEBIMENTOS'!$B$6:$B$1005,A6,'RECEBIMENTOS'!$Q$6:$Q$1005,1)) -> 0 | AN6: =IF(AND(Z6=1,N(W6)>0,AG6=N(W6)),1,0) -> 0 | AO6: =IF(AND(Z6=1,N(W6)>0,AI6=N(W6)),1,0) -> 0 | AP6: =IF(Z6=0,0,_xlfn.MAXIFS('RECEBIMENTOS'!$E$6:$E$1005,'RECEBIMENTOS'!$B$6:$B$1005,A6)) -> 0 | AQ6: =IF(T6="","",IF(T6="RECEBIMENTO NÃO CONFIRMADO",IF(ISNUMBER(F6),F6,IF(ISNUMBER(E6),E6,"")),IF(OR(T6="CDF NÃO LOCALIZADO",T6="VÍNCULO INCOMPLETO",T6="CDF A CONFERIR"),IF(AP6>0,AP6,IF(ISNUMBER(E6),E6,"")),IF(ISNUMBER(E6),E6,"")))) | AR6: =IF(NOT(ISNUMBER(U6)),0,IF(T6="RECEBIMENTO NÃO CONFIRMADO",IF(AND(ISNUMBER(cfg_rec),U6>cfg_rec),1,0),IF(OR(T6="CDF NÃO LOCALIZADO",T6="VÍNCULO INCOMPLETO",T6="CDF A CONFERIR"),IF(AND(ISNUMBER(cfg_cdf),U6>cfg_cdf),1,0),0))) -> 0 | AS6: =IF(T6="","",IF(AR6=1,"Alta",IFERROR(INDEX(cfg_pp,MATCH(T6,cfg_pt,0))&"","Média"))) | AT6: =IF(T6="","",IFERROR(INDEX(cfg_pv,MATCH(T6,cfg_pt,0))&"","")) | AU6: =IF(T6="","",IF(AS6="Alta",1,IF(AS6="Média",2,3))*1000000000+(999999-IF(ISNUMBER(U6),MIN(U6,999999),0))*1000+1) | AV6: =IF(T6<>"",1,0) -> 0 | AW6: =IF(Z6=0,"",IF(AA6=1,"Cancelamento informado; ","")&IF(AE6=1,"Campos essenciais ou itens faltando; ","")&IF(AC6=1,"Possível duplicidade do número; ","")&IF(AD6=1,"Cadastro ou datas a revisar; ","")&IF(AF6>0,"Item de resíduo com dado a revisar; ","")&IF(AH6>0,"Diferença de quantidade a analisar; ","")&IF(AK6>0,"Recebimento com alerta; ","")&IF(AL6>0,"Vínculo de CDF com alerta; ","")&IF(AND(AA6=0,AN6=0),"Recebimento não confirmado; ","")&IF(AND(AA6=0,AN6=1,AO6=0),"CDF pendente ou a conferir; ","")) | AX6: =IF(Z6=0,0,IF(AND(OR(f_ini="",AND(ISNUMBER(E6),E6>=f_ini)),OR(f_fim="",AND(ISNUMBER(E6),E6<=f_fim)),OR(f_un="",f_un="(Todas)",G6=f_un),OR(f_tr="",f_tr="(Todos)",H6=f_tr),OR(f_de="",f_de="(Todos)",I6=f_de),OR(f_sit="",f_sit="(Todas)",S6=f_sit)),1,0)) -> 0 | AY6: =IF(AX6=0,0,IF(OR(f_res="",f_res="(Todos)"),1,IF(COUNTIFS('ITENS_MTR'!$S$6:$S$1005,A6,'ITENS_MTR'!$C$6:$C$1005,f_res)>0,1,0))) -> 0 | AZ6: =IF(ISNUMBER(E6),DATE(YEAR(E6),MONTH(E6),1),"") | BA6: =IF(Z6=0,0,IF(AND(OR(r_ini="",AND(ISNUMBER(E6),E6>=r_ini)),OR(r_fim="",AND(ISNUMBER(E6),E6<=r_fim)),OR(r_un="",r_un="(Todas)",G6=r_un),OR(r_de="",r_de="(Todos)",I6=r_de)),1,0)) -> 0 | BB6: =IF(BA6=1,COUNTIF($BA$6:BA6,1),"") | BC6: =IF(AND(AU6<>"",OR(r_un="",r_un="(Todas)",G6=r_un),OR(r_de="",r_de="(Todos)",I6=r_de)),AU6,"") | BD6: =IF(Z6=1,A6&" | nº "&IF(B6="","(sem número)",B6)&" | "&IF(G6="","(sem unidade)",G6),"") | BE6: =IF(Z6=1,COUNTIF($Z$6:Z6,1),"") | BF6: =IF(T6="","",IF(T6="RECEBIMENTO NÃO CONFIRMADO","Transp.: "&H6&" | Dest.: "&I6,IF(OR(T6="CDF NÃO LOCALIZADO",T6="VÍNCULO INCOMPLETO",T6="CDF A CONFERIR"),"Dest.: "&I6,"Gerador: "&G6)))
A7: MTR-000002 | P7: =IF(Z7=0,"",SUMIFS('ITENS_MTR'!$I$6:$I$1005,'ITENS_MTR'!$S$6:$S$1005,A7,'ITENS_MTR'!$Y$6:$Y$1005,1)) | Q7: =IF(Z7=0,"",SUMIFS('RECEBIMENTOS'!$H$6:$H$1005,'RECEBIMENTOS'!$B$6:$B$1005,A7,'RECEBIMENTOS'!$X$6:$X$1005,1)) | R7: =IF(Z7=0,"",SUMIFS('VÍNCULOS_CDF'!$H$6:$H$1005,'VÍNCULOS_CDF'!$D$6:$D$1005,A7,'VÍNCULOS_CDF'!$V$6:$V$1005,1)) | S7: =IF(Z7=0,"",IF(AA7=1,"Cancelado (informado)",IF(AE7=1,"Cadastro incompleto",IF(OR(AC7=1,AD7=1,AF7>0,AH7>0,AK7>0,AL7>0),"Informação a revisar",IF(AN7=0,"Aguardando recebimento",IF(N(R7)=0,"Aguardando CDF",IF(AJ7<N(W7),"Vínculo de CDF parcial",IF(AO7=0,"CDF localizado, a conferir","Documentação conferida")))))))) | T7: =IF(Z7=0,"",IF(S7="Cadastro incompleto","MTR INCOMPLETO",IF(S7="Informação a revisar",IF(AND(AH7>0,AC7=0,AD7=0,AF7=0,AK7=0,AL7=0),"QUANTIDADE A REVISAR","IDENTIFICAÇÃO A REVISAR"),IF(S7="Aguardando recebimento","RECEBIMENTO NÃO CONFIRMADO",IF(S7="Aguardando CDF","CDF NÃO LOCALIZADO",IF(S7="Vínculo de CDF parcial","VÍNCULO INCOMPLETO",IF(S7="CDF localizado, a conferir","CDF A CONFERIR",""))))))) | U7: =IF(T7="","",IF(AQ7="","Não calculável",IF(AQ7>TODAY(),"Data futura",TODAY()-AQ7))) | V7: =IF(Z7=0,"",SUMIFS('RECEBIMENTOS'!$H$6:$H$1005,'RECEBIMENTOS'!$B$6:$B$1005,A7,'RECEBIMENTOS'!$Z$6:$Z$1005,1)) | W7: =IF(Z7=0,"",COUNTIFS('ITENS_MTR'!$S$6:$S$1005,A7,'ITENS_MTR'!$R$6:$R$1005,1)) | X7: =IF(AC7=1,"POSSÍVEL DUPLICIDADE","") | Y7: =IF(Z7=0,"",IF(AW7="","Nenhuma",LEFT(AW7,LEN(AW7)-2))) | Z7: =IF(COUNTA(B7:O7)>0,1,0) -> 0 | AA7: =IF(AND(Z7=1,K7<>""),IF(TRIM(K7)=TRIM(cfg_cancel),1,0),0) -> 0 | AB7: =IF(AND(Z7=1,B7<>""),C7&"|"&D7&"|"&G7&"|"&TRIM(B7),"") | AC7: =IF(AB7="",0,IF(SUMPRODUCT(--($AB$6:$AB$505=AB7))>1,1,0)) -> 0 | AD7: =IF(Z7=0,0,IF(OR(AND(G7<>"",ISNA(MATCH(G7,'CAD_UNIDADES'!$C$6:$C$105,0))),AND(H7<>"",ISNA(MATCH(H7,cmp_transp,0))),AND(I7<>"",ISNA(MATCH(I7,cmp_dest,0))),AND(E7<>"",NOT(ISNUMBER(E7))),AND(F7<>"",NOT(ISNUMBER(F7))),AND(ISNUMBER(E7),ISNUMBER(F7),F7<E7)),1,0)) -> 0 | AE7: =IF(Z7=0,0,IF(OR(B7="",C7="",E7="",G7="",H7="",I7="",N(W7)=0),1,0)) -> 0 | AF7: =IF(Z7=0,0,COUNTIFS('ITENS_MTR'!$S$6:$S$1005,A7,'ITENS_MTR'!$AI$6:$AI$1005,1)) -> 0 | AG7: =IF(Z7=0,0,COUNTIFS('ITENS_MTR'!$S$6:$S$1005,A7,'ITENS_MTR'!$AJ$6:$AJ$1005,1)) -> 0 | AH7: =IF(Z7=0,0,COUNTIFS('ITENS_MTR'!$S$6:$S$1005,A7,'ITENS_MTR'!$AM$6:$AM$1005,1)) -> 0 | AI7: =IF(Z7=0,0,COUNTIFS('ITENS_MTR'!$S$6:$S$1005,A7,'ITENS_MTR'!$AO$6:$AO$1005,1)) -> 0 | AJ7: =IF(Z7=0,0,COUNTIFS('ITENS_MTR'!$S$6:$S$1005,A7,'ITENS_MTR'!$AN$6:$AN$1005,1)) -> 0 | AK7: =IF(Z7=0,0,COUNTIFS('RECEBIMENTOS'!$B$6:$B$1005,A7,'RECEBIMENTOS'!$Y$6:$Y$1005,1)) -> 0 | AL7: =IF(Z7=0,0,COUNTIFS('VÍNCULOS_CDF'!$D$6:$D$1005,A7,'VÍNCULOS_CDF'!$Y$6:$Y$1005,1)) -> 0 | AM7: =IF(Z7=0,0,COUNTIFS('RECEBIMENTOS'!$B$6:$B$1005,A7,'RECEBIMENTOS'!$Q$6:$Q$1005,1)) -> 0 | AN7: =IF(AND(Z7=1,N(W7)>0,AG7=N(W7)),1,0) -> 0 | AO7: =IF(AND(Z7=1,N(W7)>0,AI7=N(W7)),1,0) -> 0 | AP7: =IF(Z7=0,0,_xlfn.MAXIFS('RECEBIMENTOS'!$E$6:$E$1005,'RECEBIMENTOS'!$B$6:$B$1005,A7)) -> 0 | AQ7: =IF(T7="","",IF(T7="RECEBIMENTO NÃO CONFIRMADO",IF(ISNUMBER(F7),F7,IF(ISNUMBER(E7),E7,"")),IF(OR(T7="CDF NÃO LOCALIZADO",T7="VÍNCULO INCOMPLETO",T7="CDF A CONFERIR"),IF(AP7>0,AP7,IF(ISNUMBER(E7),E7,"")),IF(ISNUMBER(E7),E7,"")))) | AR7: =IF(NOT(ISNUMBER(U7)),0,IF(T7="RECEBIMENTO NÃO CONFIRMADO",IF(AND(ISNUMBER(cfg_rec),U7>cfg_rec),1,0),IF(OR(T7="CDF NÃO LOCALIZADO",T7="VÍNCULO INCOMPLETO",T7="CDF A CONFERIR"),IF(AND(ISNUMBER(cfg_cdf),U7>cfg_cdf),1,0),0))) -> 0 | AS7: =IF(T7="","",IF(AR7=1,"Alta",IFERROR(INDEX(cfg_pp,MATCH(T7,cfg_pt,0))&"","Média"))) | AT7: =IF(T7="","",IFERROR(INDEX(cfg_pv,MATCH(T7,cfg_pt,0))&"","")) | AU7: =IF(T7="","",IF(AS7="Alta",1,IF(AS7="Média",2,3))*1000000000+(999999-IF(ISNUMBER(U7),MIN(U7,999999),0))*1000+2) | AV7: =IF(T7<>"",1,0) -> 0 | AW7: =IF(Z7=0,"",IF(AA7=1,"Cancelamento informado; ","")&IF(AE7=1,"Campos essenciais ou itens faltando; ","")&IF(AC7=1,"Possível duplicidade do número; ","")&IF(AD7=1,"Cadastro ou datas a revisar; ","")&IF(AF7>0,"Item de resíduo com dado a revisar; ","")&IF(AH7>0,"Diferença de quantidade a analisar; ","")&IF(AK7>0,"Recebimento com alerta; ","")&IF(AL7>0,"Vínculo de CDF com alerta; ","")&IF(AND(AA7=0,AN7=0),"Recebimento não confirmado; ","")&IF(AND(AA7=0,AN7=1,AO7=0),"CDF pendente ou a conferir; ","")) | AX7: =IF(Z7=0,0,IF(AND(OR(f_ini="",AND(ISNUMBER(E7),E7>=f_ini)),OR(f_fim="",AND(ISNUMBER(E7),E7<=f_fim)),OR(f_un="",f_un="(Todas)",G7=f_un),OR(f_tr="",f_tr="(Todos)",H7=f_tr),OR(f_de="",f_de="(Todos)",I7=f_de),OR(f_sit="",f_sit="(Todas)",S7=f_sit)),1,0)) -> 0 | AY7: =IF(AX7=0,0,IF(OR(f_res="",f_res="(Todos)"),1,IF(COUNTIFS('ITENS_MTR'!$S$6:$S$1005,A7,'ITENS_MTR'!$C$6:$C$1005,f_res)>0,1,0))) -> 0 | AZ7: =IF(ISNUMBER(E7),DATE(YEAR(E7),MONTH(E7),1),"") | BA7: =IF(Z7=0,0,IF(AND(OR(r_ini="",AND(ISNUMBER(E7),E7>=r_ini)),OR(r_fim="",AND(ISNUMBER(E7),E7<=r_fim)),OR(r_un="",r_un="(Todas)",G7=r_un),OR(r_de="",r_de="(Todos)",I7=r_de)),1,0)) -> 0 | BB7: =IF(BA7=1,COUNTIF($BA$6:BA7,1),"") | BC7: =IF(AND(AU7<>"",OR(r_un="",r_un="(Todas)",G7=r_un),OR(r_de="",r_de="(Todos)",I7=r_de)),AU7,"") | BD7: =IF(Z7=1,A7&" | nº "&IF(B7="","(sem número)",B7)&" | "&IF(G7="","(sem unidade)",G7),"") | BE7: =IF(Z7=1,COUNTIF($Z$6:Z7,1),"") | BF7: =IF(T7="","",IF(T7="RECEBIMENTO NÃO CONFIRMADO","Transp.: "&H7&" | Dest.: "&I7,IF(OR(T7="CDF NÃO LOCALIZADO",T7="VÍNCULO INCOMPLETO",T7="CDF A CONFERIR"),"Dest.: "&I7,"Gerador: "&G7)))
A8: MTR-000003 | P8: =IF(Z8=0,"",SUMIFS('ITENS_MTR'!$I$6:$I$1005,'ITENS_MTR'!$S$6:$S$1005,A8,'ITENS_MTR'!$Y$6:$Y$1005,1)) | Q8: =IF(Z8=0,"",SUMIFS('RECEBIMENTOS'!$H$6:$H$1005,'RECEBIMENTOS'!$B$6:$B$1005,A8,'RECEBIMENTOS'!$X$6:$X$1005,1)) | R8: =IF(Z8=0,"",SUMIFS('VÍNCULOS_CDF'!$H$6:$H$1005,'VÍNCULOS_CDF'!$D$6:$D$1005,A8,'VÍNCULOS_CDF'!$V$6:$V$1005,1)) | S8: =IF(Z8=0,"",IF(AA8=1,"Cancelado (informado)",IF(AE8=1,"Cadastro incompleto",IF(OR(AC8=1,AD8=1,AF8>0,AH8>0,AK8>0,AL8>0),"Informação a revisar",IF(AN8=0,"Aguardando recebimento",IF(N(R8)=0,"Aguardando CDF",IF(AJ8<N(W8),"Vínculo de CDF parcial",IF(AO8=0,"CDF localizado, a conferir","Documentação conferida")))))))) | T8: =IF(Z8=0,"",IF(S8="Cadastro incompleto","MTR INCOMPLETO",IF(S8="Informação a revisar",IF(AND(AH8>0,AC8=0,AD8=0,AF8=0,AK8=0,AL8=0),"QUANTIDADE A REVISAR","IDENTIFICAÇÃO A REVISAR"),IF(S8="Aguardando recebimento","RECEBIMENTO NÃO CONFIRMADO",IF(S8="Aguardando CDF","CDF NÃO LOCALIZADO",IF(S8="Vínculo de CDF parcial","VÍNCULO INCOMPLETO",IF(S8="CDF localizado, a conferir","CDF A CONFERIR",""))))))) | U8: =IF(T8="","",IF(AQ8="","Não calculável",IF(AQ8>TODAY(),"Data futura",TODAY()-AQ8))) | V8: =IF(Z8=0,"",SUMIFS('RECEBIMENTOS'!$H$6:$H$1005,'RECEBIMENTOS'!$B$6:$B$1005,A8,'RECEBIMENTOS'!$Z$6:$Z$1005,1)) | W8: =IF(Z8=0,"",COUNTIFS('ITENS_MTR'!$S$6:$S$1005,A8,'ITENS_MTR'!$R$6:$R$1005,1)) | X8: =IF(AC8=1,"POSSÍVEL DUPLICIDADE","") | Y8: =IF(Z8=0,"",IF(AW8="","Nenhuma",LEFT(AW8,LEN(AW8)-2))) | Z8: =IF(COUNTA(B8:O8)>0,1,0) -> 0 | AA8: =IF(AND(Z8=1,K8<>""),IF(TRIM(K8)=TRIM(cfg_cancel),1,0),0) -> 0 | AB8: =IF(AND(Z8=1,B8<>""),C8&"|"&D8&"|"&G8&"|"&TRIM(B8),"") | AC8: =IF(AB8="",0,IF(SUMPRODUCT(--($AB$6:$AB$505=AB8))>1,1,0)) -> 0 | AD8: =IF(Z8=0,0,IF(OR(AND(G8<>"",ISNA(MATCH(G8,'CAD_UNIDADES'!$C$6:$C$105,0))),AND(H8<>"",ISNA(MATCH(H8,cmp_transp,0))),AND(I8<>"",ISNA(MATCH(I8,cmp_dest,0))),AND(E8<>"",NOT(ISNUMBER(E8))),AND(F8<>"",NOT(ISNUMBER(F8))),AND(ISNUMBER(E8),ISNUMBER(F8),F8<E8)),1,0)) -> 0 | AE8: =IF(Z8=0,0,IF(OR(B8="",C8="",E8="",G8="",H8="",I8="",N(W8)=0),1,0)) -> 0 | AF8: =IF(Z8=0,0,COUNTIFS('ITENS_MTR'!$S$6:$S$1005,A8,'ITENS_MTR'!$AI$6:$AI$1005,1)) -> 0 | AG8: =IF(Z8=0,0,COUNTIFS('ITENS_MTR'!$S$6:$S$1005,A8,'ITENS_MTR'!$AJ$6:$AJ$1005,1)) -> 0 | AH8: =IF(Z8=0,0,COUNTIFS('ITENS_MTR'!$S$6:$S$1005,A8,'ITENS_MTR'!$AM$6:$AM$1005,1)) -> 0 | AI8: =IF(Z8=0,0,COUNTIFS('ITENS_MTR'!$S$6:$S$1005,A8,'ITENS_MTR'!$AO$6:$AO$1005,1)) -> 0 | AJ8: =IF(Z8=0,0,COUNTIFS('ITENS_MTR'!$S$6:$S$1005,A8,'ITENS_MTR'!$AN$6:$AN$1005,1)) -> 0 | AK8: =IF(Z8=0,0,COUNTIFS('RECEBIMENTOS'!$B$6:$B$1005,A8,'RECEBIMENTOS'!$Y$6:$Y$1005,1)) -> 0 | AL8: =IF(Z8=0,0,COUNTIFS('VÍNCULOS_CDF'!$D$6:$D$1005,A8,'VÍNCULOS_CDF'!$Y$6:$Y$1005,1)) -> 0 | AM8: =IF(Z8=0,0,COUNTIFS('RECEBIMENTOS'!$B$6:$B$1005,A8,'RECEBIMENTOS'!$Q$6:$Q$1005,1)) -> 0 | AN8: =IF(AND(Z8=1,N(W8)>0,AG8=N(W8)),1,0) -> 0 | AO8: =IF(AND(Z8=1,N(W8)>0,AI8=N(W8)),1,0) -> 0 | AP8: =IF(Z8=0,0,_xlfn.MAXIFS('RECEBIMENTOS'!$E$6:$E$1005,'RECEBIMENTOS'!$B$6:$B$1005,A8)) -> 0 | AQ8: =IF(T8="","",IF(T8="RECEBIMENTO NÃO CONFIRMADO",IF(ISNUMBER(F8),F8,IF(ISNUMBER(E8),E8,"")),IF(OR(T8="CDF NÃO LOCALIZADO",T8="VÍNCULO INCOMPLETO",T8="CDF A CONFERIR"),IF(AP8>0,AP8,IF(ISNUMBER(E8),E8,"")),IF(ISNUMBER(E8),E8,"")))) | AR8: =IF(NOT(ISNUMBER(U8)),0,IF(T8="RECEBIMENTO NÃO CONFIRMADO",IF(AND(ISNUMBER(cfg_rec),U8>cfg_rec),1,0),IF(OR(T8="CDF NÃO LOCALIZADO",T8="VÍNCULO INCOMPLETO",T8="CDF A CONFERIR"),IF(AND(ISNUMBER(cfg_cdf),U8>cfg_cdf),1,0),0))) -> 0 | AS8: =IF(T8="","",IF(AR8=1,"Alta",IFERROR(INDEX(cfg_pp,MATCH(T8,cfg_pt,0))&"","Média"))) | AT8: =IF(T8="","",IFERROR(INDEX(cfg_pv,MATCH(T8,cfg_pt,0))&"","")) | AU8: =IF(T8="","",IF(AS8="Alta",1,IF(AS8="Média",2,3))*1000000000+(999999-IF(ISNUMBER(U8),MIN(U8,999999),0))*1000+3) | AV8: =IF(T8<>"",1,0) -> 0 | AW8: =IF(Z8=0,"",IF(AA8=1,"Cancelamento informado; ","")&IF(AE8=1,"Campos essenciais ou itens faltando; ","")&IF(AC8=1,"Possível duplicidade do número; ","")&IF(AD8=1,"Cadastro ou datas a revisar; ","")&IF(AF8>0,"Item de resíduo com dado a revisar; ","")&IF(AH8>0,"Diferença de quantidade a analisar; ","")&IF(AK8>0,"Recebimento com alerta; ","")&IF(AL8>0,"Vínculo de CDF com alerta; ","")&IF(AND(AA8=0,AN8=0),"Recebimento não confirmado; ","")&IF(AND(AA8=0,AN8=1,AO8=0),"CDF pendente ou a conferir; ","")) | AX8: =IF(Z8=0,0,IF(AND(OR(f_ini="",AND(ISNUMBER(E8),E8>=f_ini)),OR(f_fim="",AND(ISNUMBER(E8),E8<=f_fim)),OR(f_un="",f_un="(Todas)",G8=f_un),OR(f_tr="",f_tr="(Todos)",H8=f_tr),OR(f_de="",f_de="(Todos)",I8=f_de),OR(f_sit="",f_sit="(Todas)",S8=f_sit)),1,0)) -> 0 | AY8: =IF(AX8=0,0,IF(OR(f_res="",f_res="(Todos)"),1,IF(COUNTIFS('ITENS_MTR'!$S$6:$S$1005,A8,'ITENS_MTR'!$C$6:$C$1005,f_res)>0,1,0))) -> 0 | AZ8: =IF(ISNUMBER(E8),DATE(YEAR(E8),MONTH(E8),1),"") | BA8: =IF(Z8=0,0,IF(AND(OR(r_ini="",AND(ISNUMBER(E8),E8>=r_ini)),OR(r_fim="",AND(ISNUMBER(E8),E8<=r_fim)),OR(r_un="",r_un="(Todas)",G8=r_un),OR(r_de="",r_de="(Todos)",I8=r_de)),1,0)) -> 0 | BB8: =IF(BA8=1,COUNTIF($BA$6:BA8,1),"") | BC8: =IF(AND(AU8<>"",OR(r_un="",r_un="(Todas)",G8=r_un),OR(r_de="",r_de="(Todos)",I8=r_de)),AU8,"") | BD8: =IF(Z8=1,A8&" | nº "&IF(B8="","(sem número)",B8)&" | "&IF(G8="","(sem unidade)",G8),"") | BE8: =IF(Z8=1,COUNTIF($Z$6:Z8,1),"") | BF8: =IF(T8="","",IF(T8="RECEBIMENTO NÃO CONFIRMADO","Transp.: "&H8&" | Dest.: "&I8,IF(OR(T8="CDF NÃO LOCALIZADO",T8="VÍNCULO INCOMPLETO",T8="CDF A CONFERIR"),"Dest.: "&I8,"Gerador: "&G8)))
A9: MTR-000004 | P9: =IF(Z9=0,"",SUMIFS('ITENS_MTR'!$I$6:$I$1005,'ITENS_MTR'!$S$6:$S$1005,A9,'ITENS_MTR'!$Y$6:$Y$1005,1)) | Q9: =IF(Z9=0,"",SUMIFS('RECEBIMENTOS'!$H$6:$H$1005,'RECEBIMENTOS'!$B$6:$B$1005,A9,'RECEBIMENTOS'!$X$6:$X$1005,1)) | R9: =IF(Z9=0,"",SUMIFS('VÍNCULOS_CDF'!$H$6:$H$1005,'VÍNCULOS_CDF'!$D$6:$D$1005,A9,'VÍNCULOS_CDF'!$V$6:$V$1005,1)) | S9: =IF(Z9=0,"",IF(AA9=1,"Cancelado (informado)",IF(AE9=1,"Cadastro incompleto",IF(OR(AC9=1,AD9=1,AF9>0,AH9>0,AK9>0,AL9>0),"Informação a revisar",IF(AN9=0,"Aguardando recebimento",IF(N(R9)=0,"Aguardando CDF",IF(AJ9<N(W9),"Vínculo de CDF parcial",IF(AO9=0,"CDF localizado, a conferir","Documentação conferida")))))))) | T9: =IF(Z9=0,"",IF(S9="Cadastro incompleto","MTR INCOMPLETO",IF(S9="Informação a revisar",IF(AND(AH9>0,AC9=0,AD9=0,AF9=0,AK9=0,AL9=0),"QUANTIDADE A REVISAR","IDENTIFICAÇÃO A REVISAR"),IF(S9="Aguardando recebimento","RECEBIMENTO NÃO CONFIRMADO",IF(S9="Aguardando CDF","CDF NÃO LOCALIZADO",IF(S9="Vínculo de CDF parcial","VÍNCULO INCOMPLETO",IF(S9="CDF localizado, a conferir","CDF A CONFERIR",""))))))) | U9: =IF(T9="","",IF(AQ9="","Não calculável",IF(AQ9>TODAY(),"Data futura",TODAY()-AQ9))) | V9: =IF(Z9=0,"",SUMIFS('RECEBIMENTOS'!$H$6:$H$1005,'RECEBIMENTOS'!$B$6:$B$1005,A9,'RECEBIMENTOS'!$Z$6:$Z$1005,1)) | W9: =IF(Z9=0,"",COUNTIFS('ITENS_MTR'!$S$6:$S$1005,A9,'ITENS_MTR'!$R$6:$R$1005,1)) | X9: =IF(AC9=1,"POSSÍVEL DUPLICIDADE","") | Y9: =IF(Z9=0,"",IF(AW9="","Nenhuma",LEFT(AW9,LEN(AW9)-2))) | Z9: =IF(COUNTA(B9:O9)>0,1,0) -> 0 | AA9: =IF(AND(Z9=1,K9<>""),IF(TRIM(K9)=TRIM(cfg_cancel),1,0),0) -> 0 | AB9: =IF(AND(Z9=1,B9<>""),C9&"|"&D9&"|"&G9&"|"&TRIM(B9),"") | AC9: =IF(AB9="",0,IF(SUMPRODUCT(--($AB$6:$AB$505=AB9))>1,1,0)) -> 0 | AD9: =IF(Z9=0,0,IF(OR(AND(G9<>"",ISNA(MATCH(G9,'CAD_UNIDADES'!$C$6:$C$105,0))),AND(H9<>"",ISNA(MATCH(H9,cmp_transp,0))),AND(I9<>"",ISNA(MATCH(I9,cmp_dest,0))),AND(E9<>"",NOT(ISNUMBER(E9))),AND(F9<>"",NOT(ISNUMBER(F9))),AND(ISNUMBER(E9),ISNUMBER(F9),F9<E9)),1,0)) -> 0 | AE9: =IF(Z9=0,0,IF(OR(B9="",C9="",E9="",G9="",H9="",I9="",N(W9)=0),1,0)) -> 0 | AF9: =IF(Z9=0,0,COUNTIFS('ITENS_MTR'!$S$6:$S$1005,A9,'ITENS_MTR'!$AI$6:$AI$1005,1)) -> 0 | AG9: =IF(Z9=0,0,COUNTIFS('ITENS_MTR'!$S$6:$S$1005,A9,'ITENS_MTR'!$AJ$6:$AJ$1005,1)) -> 0 | AH9: =IF(Z9=0,0,COUNTIFS('ITENS_MTR'!$S$6:$S$1005,A9,'ITENS_MTR'!$AM$6:$AM$1005,1)) -> 0 | AI9: =IF(Z9=0,0,COUNTIFS('ITENS_MTR'!$S$6:$S$1005,A9,'ITENS_MTR'!$AO$6:$AO$1005,1)) -> 0 | AJ9: =IF(Z9=0,0,COUNTIFS('ITENS_MTR'!$S$6:$S$1005,A9,'ITENS_MTR'!$AN$6:$AN$1005,1)) -> 0 | AK9: =IF(Z9=0,0,COUNTIFS('RECEBIMENTOS'!$B$6:$B$1005,A9,'RECEBIMENTOS'!$Y$6:$Y$1005,1)) -> 0 | AL9: =IF(Z9=0,0,COUNTIFS('VÍNCULOS_CDF'!$D$6:$D$1005,A9,'VÍNCULOS_CDF'!$Y$6:$Y$1005,1)) -> 0 | AM9: =IF(Z9=0,0,COUNTIFS('RECEBIMENTOS'!$B$6:$B$1005,A9,'RECEBIMENTOS'!$Q$6:$Q$1005,1)) -> 0 | AN9: =IF(AND(Z9=1,N(W9)>0,AG9=N(W9)),1,0) -> 0 | AO9: =IF(AND(Z9=1,N(W9)>0,AI9=N(W9)),1,0) -> 0 | AP9: =IF(Z9=0,0,_xlfn.MAXIFS('RECEBIMENTOS'!$E$6:$E$1005,'RECEBIMENTOS'!$B$6:$B$1005,A9)) -> 0 | AQ9: =IF(T9="","",IF(T9="RECEBIMENTO NÃO CONFIRMADO",IF(ISNUMBER(F9),F9,IF(ISNUMBER(E9),E9,"")),IF(OR(T9="CDF NÃO LOCALIZADO",T9="VÍNCULO INCOMPLETO",T9="CDF A CONFERIR"),IF(AP9>0,AP9,IF(ISNUMBER(E9),E9,"")),IF(ISNUMBER(E9),E9,"")))) | AR9: =IF(NOT(ISNUMBER(U9)),0,IF(T9="RECEBIMENTO NÃO CONFIRMADO",IF(AND(ISNUMBER(cfg_rec),U9>cfg_rec),1,0),IF(OR(T9="CDF NÃO LOCALIZADO",T9="VÍNCULO INCOMPLETO",T9="CDF A CONFERIR"),IF(AND(ISNUMBER(cfg_cdf),U9>cfg_cdf),1,0),0))) -> 0 | AS9: =IF(T9="","",IF(AR9=1,"Alta",IFERROR(INDEX(cfg_pp,MATCH(T9,cfg_pt,0))&"","Média"))) | AT9: =IF(T9="","",IFERROR(INDEX(cfg_pv,MATCH(T9,cfg_pt,0))&"","")) | AU9: =IF(T9="","",IF(AS9="Alta",1,IF(AS9="Média",2,3))*1000000000+(999999-IF(ISNUMBER(U9),MIN(U9,999999),0))*1000+4) | AV9: =IF(T9<>"",1,0) -> 0 | AW9: =IF(Z9=0,"",IF(AA9=1,"Cancelamento informado; ","")&IF(AE9=1,"Campos essenciais ou itens faltando; ","")&IF(AC9=1,"Possível duplicidade do número; ","")&IF(AD9=1,"Cadastro ou datas a revisar; ","")&IF(AF9>0,"Item de resíduo com dado a revisar; ","")&IF(AH9>0,"Diferença de quantidade a analisar; ","")&IF(AK9>0,"Recebimento com alerta; ","")&IF(AL9>0,"Vínculo de CDF com alerta; ","")&IF(AND(AA9=0,AN9=0),"Recebimento não confirmado; ","")&IF(AND(AA9=0,AN9=1,AO9=0),"CDF pendente ou a conferir; ","")) | AX9: =IF(Z9=0,0,IF(AND(OR(f_ini="",AND(ISNUMBER(E9),E9>=f_ini)),OR(f_fim="",AND(ISNUMBER(E9),E9<=f_fim)),OR(f_un="",f_un="(Todas)",G9=f_un),OR(f_tr="",f_tr="(Todos)",H9=f_tr),OR(f_de="",f_de="(Todos)",I9=f_de),OR(f_sit="",f_sit="(Todas)",S9=f_sit)),1,0)) -> 0 | AY9: =IF(AX9=0,0,IF(OR(f_res="",f_res="(Todos)"),1,IF(COUNTIFS('ITENS_MTR'!$S$6:$S$1005,A9,'ITENS_MTR'!$C$6:$C$1005,f_res)>0,1,0))) -> 0 | AZ9: =IF(ISNUMBER(E9),DATE(YEAR(E9),MONTH(E9),1),"") | BA9: =IF(Z9=0,0,IF(AND(OR(r_ini="",AND(ISNUMBER(E9),E9>=r_ini)),OR(r_fim="",AND(ISNUMBER(E9),E9<=r_fim)),OR(r_un="",r_un="(Todas)",G9=r_un),OR(r_de="",r_de="(Todos)",I9=r_de)),1,0)) -> 0 | BB9: =IF(BA9=1,COUNTIF($BA$6:BA9,1),"") | BC9: =IF(AND(AU9<>"",OR(r_un="",r_un="(Todas)",G9=r_un),OR(r_de="",r_de="(Todos)",I9=r_de)),AU9,"") | BD9: =IF(Z9=1,A9&" | nº "&IF(B9="","(sem número)",B9)&" | "&IF(G9="","(sem unidade)",G9),"") | BE9: =IF(Z9=1,COUNTIF($Z$6:Z9,1),"") | BF9: =IF(T9="","",IF(T9="RECEBIMENTO NÃO CONFIRMADO","Transp.: "&H9&" | Dest.: "&I9,IF(OR(T9="CDF NÃO LOCALIZADO",T9="VÍNCULO INCOMPLETO",T9="CDF A CONFERIR"),"Dest.: "&I9,"Gerador: "&G9)))
A10: MTR-000005 | P10: =IF(Z10=0,"",SUMIFS('ITENS_MTR'!$I$6:$I$1005,'ITENS_MTR'!$S$6:$S$1005,A10,'ITENS_MTR'!$Y$6:$Y$1005,1)) | Q10: =IF(Z10=0,"",SUMIFS('RECEBIMENTOS'!$H$6:$H$1005,'RECEBIMENTOS'!$B$6:$B$1005,A10,'RECEBIMENTOS'!$X$6:$X$1005,1)) | R10: =IF(Z10=0,"",SUMIFS('VÍNCULOS_CDF'!$H$6:$H$1005,'VÍNCULOS_CDF'!$D$6:$D$1005,A10,'VÍNCULOS_CDF'!$V$6:$V$1005,1)) | S10: =IF(Z10=0,"",IF(AA10=1,"Cancelado (informado)",IF(AE10=1,"Cadastro incompleto",IF(OR(AC10=1,AD10=1,AF10>0,AH10>0,AK10>0,AL10>0),"Informação a revisar",IF(AN10=0,"Aguardando recebimento",IF(N(R10)=0,"Aguardando CDF",IF(AJ10<N(W10),"Vínculo de CDF parcial",IF(AO10=0,"CDF localizado, a conferir","Documentação conferida")))))))) | T10: =IF(Z10=0,"",IF(S10="Cadastro incompleto","MTR INCOMPLETO",IF(S10="Informação a revisar",IF(AND(AH10>0,AC10=0,AD10=0,AF10=0,AK10=0,AL10=0),"QUANTIDADE A REVISAR","IDENTIFICAÇÃO A REVISAR"),IF(S10="Aguardando recebimento","RECEBIMENTO NÃO CONFIRMADO",IF(S10="Aguardando CDF","CDF NÃO LOCALIZADO",IF(S10="Vínculo de CDF parcial","VÍNCULO INCOMPLETO",IF(S10="CDF localizado, a conferir","CDF A CONFERIR",""))))))) | U10: =IF(T10="","",IF(AQ10="","Não calculável",IF(AQ10>TODAY(),"Data futura",TODAY()-AQ10))) | V10: =IF(Z10=0,"",SUMIFS('RECEBIMENTOS'!$H$6:$H$1005,'RECEBIMENTOS'!$B$6:$B$1005,A10,'RECEBIMENTOS'!$Z$6:$Z$1005,1)) | W10: =IF(Z10=0,"",COUNTIFS('ITENS_MTR'!$S$6:$S$1005,A10,'ITENS_MTR'!$R$6:$R$1005,1)) | X10: =IF(AC10=1,"POSSÍVEL DUPLICIDADE","") | Y10: =IF(Z10=0,"",IF(AW10="","Nenhuma",LEFT(AW10,LEN(AW10)-2))) | Z10: =IF(COUNTA(B10:O10)>0,1,0) -> 0 | AA10: =IF(AND(Z10=1,K10<>""),IF(TRIM(K10)=TRIM(cfg_cancel),1,0),0) -> 0 | AB10: =IF(AND(Z10=1,B10<>""),C10&"|"&D10&"|"&G10&"|"&TRIM(B10),"") | AC10: =IF(AB10="",0,IF(SUMPRODUCT(--($AB$6:$AB$505=AB10))>1,1,0)) -> 0 | AD10: =IF(Z10=0,0,IF(OR(AND(G10<>"",ISNA(MATCH(G10,'CAD_UNIDADES'!$C$6:$C$105,0))),AND(H10<>"",ISNA(MATCH(H10,cmp_transp,0))),AND(I10<>"",ISNA(MATCH(I10,cmp_dest,0))),AND(E10<>"",NOT(ISNUMBER(E10))),AND(F10<>"",NOT(ISNUMBER(F10))),AND(ISNUMBER(E10),ISNUMBER(F10),F10<E10)),1,0)) -> 0 | AE10: =IF(Z10=0,0,IF(OR(B10="",C10="",E10="",G10="",H10="",I10="",N(W10)=0),1,0)) -> 0 | AF10: =IF(Z10=0,0,COUNTIFS('ITENS_MTR'!$S$6:$S$1005,A10,'ITENS_MTR'!$AI$6:$AI$1005,1)) -> 0 | AG10: =IF(Z10=0,0,COUNTIFS('ITENS_MTR'!$S$6:$S$1005,A10,'ITENS_MTR'!$AJ$6:$AJ$1005,1)) -> 0 | AH10: =IF(Z10=0,0,COUNTIFS('ITENS_MTR'!$S$6:$S$1005,A10,'ITENS_MTR'!$AM$6:$AM$1005,1)) -> 0 | AI10: =IF(Z10=0,0,COUNTIFS('ITENS_MTR'!$S$6:$S$1005,A10,'ITENS_MTR'!$AO$6:$AO$1005,1)) -> 0 | AJ10: =IF(Z10=0,0,COUNTIFS('ITENS_MTR'!$S$6:$S$1005,A10,'ITENS_MTR'!$AN$6:$AN$1005,1)) -> 0 | AK10: =IF(Z10=0,0,COUNTIFS('RECEBIMENTOS'!$B$6:$B$1005,A10,'RECEBIMENTOS'!$Y$6:$Y$1005,1)) -> 0 | AL10: =IF(Z10=0,0,COUNTIFS('VÍNCULOS_CDF'!$D$6:$D$1005,A10,'VÍNCULOS_CDF'!$Y$6:$Y$1005,1)) -> 0 | AM10: =IF(Z10=0,0,COUNTIFS('RECEBIMENTOS'!$B$6:$B$1005,A10,'RECEBIMENTOS'!$Q$6:$Q$1005,1)) -> 0 | AN10: =IF(AND(Z10=1,N(W10)>0,AG10=N(W10)),1,0) -> 0 | AO10: =IF(AND(Z10=1,N(W10)>0,AI10=N(W10)),1,0) -> 0 | AP10: =IF(Z10=0,0,_xlfn.MAXIFS('RECEBIMENTOS'!$E$6:$E$1005,'RECEBIMENTOS'!$B$6:$B$1005,A10)) -> 0 | AQ10: =IF(T10="","",IF(T10="RECEBIMENTO NÃO CONFIRMADO",IF(ISNUMBER(F10),F10,IF(ISNUMBER(E10),E10,"")),IF(OR(T10="CDF NÃO LOCALIZADO",T10="VÍNCULO INCOMPLETO",T10="CDF A CONFERIR"),IF(AP10>0,AP10,IF(ISNUMBER(E10),E10,"")),IF(ISNUMBER(E10),E10,"")))) | AR10: =IF(NOT(ISNUMBER(U10)),0,IF(T10="RECEBIMENTO NÃO CONFIRMADO",IF(AND(ISNUMBER(cfg_rec),U10>cfg_rec),1,0),IF(OR(T10="CDF NÃO LOCALIZADO",T10="VÍNCULO INCOMPLETO",T10="CDF A CONFERIR"),IF(AND(ISNUMBER(cfg_cdf),U10>cfg_cdf),1,0),0))) -> 0 | AS10: =IF(T10="","",IF(AR10=1,"Alta",IFERROR(INDEX(cfg_pp,MATCH(T10,cfg_pt,0))&"","Média"))) | AT10: =IF(T10="","",IFERROR(INDEX(cfg_pv,MATCH(T10,cfg_pt,0))&"","")) | AU10: =IF(T10="","",IF(AS10="Alta",1,IF(AS10="Média",2,3))*1000000000+(999999-IF(ISNUMBER(U10),MIN(U10,999999),0))*1000+5) | AV10: =IF(T10<>"",1,0) -> 0 | AW10: =IF(Z10=0,"",IF(AA10=1,"Cancelamento informado; ","")&IF(AE10=1,"Campos essenciais ou itens faltando; ","")&IF(AC10=1,"Possível duplicidade do número; ","")&IF(AD10=1,"Cadastro ou datas a revisar; ","")&IF(AF10>0,"Item de resíduo com dado a revisar; ","")&IF(AH10>0,"Diferença de quantidade a analisar; ","")&IF(AK10>0,"Recebimento com alerta; ","")&IF(AL10>0,"Vínculo de CDF com alerta; ","")&IF(AND(AA10=0,AN10=0),"Recebimento não confirmado; ","")&IF(AND(AA10=0,AN10=1,AO10=0),"CDF pendente ou a conferir; ","")) | AX10: =IF(Z10=0,0,IF(AND(OR(f_ini="",AND(ISNUMBER(E10),E10>=f_ini)),OR(f_fim="",AND(ISNUMBER(E10),E10<=f_fim)),OR(f_un="",f_un="(Todas)",G10=f_un),OR(f_tr="",f_tr="(Todos)",H10=f_tr),OR(f_de="",f_de="(Todos)",I10=f_de),OR(f_sit="",f_sit="(Todas)",S10=f_sit)),1,0)) -> 0 | AY10: =IF(AX10=0,0,IF(OR(f_res="",f_res="(Todos)"),1,IF(COUNTIFS('ITENS_MTR'!$S$6:$S$1005,A10,'ITENS_MTR'!$C$6:$C$1005,f_res)>0,1,0))) -> 0 | AZ10: =IF(ISNUMBER(E10),DATE(YEAR(E10),MONTH(E10),1),"") | BA10: =IF(Z10=0,0,IF(AND(OR(r_ini="",AND(ISNUMBER(E10),E10>=r_ini)),OR(r_fim="",AND(ISNUMBER(E10),E10<=r_fim)),OR(r_un="",r_un="(Todas)",G10=r_un),OR(r_de="",r_de="(Todos)",I10=r_de)),1,0)) -> 0 | BB10: =IF(BA10=1,COUNTIF($BA$6:BA10,1),"") | BC10: =IF(AND(AU10<>"",OR(r_un="",r_un="(Todas)",G10=r_un),OR(r_de="",r_de="(Todos)",I10=r_de)),AU10,"") | BD10: =IF(Z10=1,A10&" | nº "&IF(B10="","(sem número)",B10)&" | "&IF(G10="","(sem unidade)",G10),"") | BE10: =IF(Z10=1,COUNTIF($Z$6:Z10,1),"") | BF10: =IF(T10="","",IF(T10="RECEBIMENTO NÃO CONFIRMADO","Transp.: "&H10&" | Dest.: "&I10,IF(OR(T10="CDF NÃO LOCALIZADO",T10="VÍNCULO INCOMPLETO",T10="CDF A CONFERIR"),"Dest.: "&I10,"Gerador: "&G10)))
A11: MTR-000006 | P11: =IF(Z11=0,"",SUMIFS('ITENS_MTR'!$I$6:$I$1005,'ITENS_MTR'!$S$6:$S$1005,A11,'ITENS_MTR'!$Y$6:$Y$1005,1)) | Q11: =IF(Z11=0,"",SUMIFS('RECEBIMENTOS'!$H$6:$H$1005,'RECEBIMENTOS'!$B$6:$B$1005,A11,'RECEBIMENTOS'!$X$6:$X$1005,1)) | R11: =IF(Z11=0,"",SUMIFS('VÍNCULOS_CDF'!$H$6:$H$1005,'VÍNCULOS_CDF'!$D$6:$D$1005,A11,'VÍNCULOS_CDF'!$V$6:$V$1005,1)) | S11: =IF(Z11=0,"",IF(AA11=1,"Cancelado (informado)",IF(AE11=1,"Cadastro incompleto",IF(OR(AC11=1,AD11=1,AF11>0,AH11>0,AK11>0,AL11>0),"Informação a revisar",IF(AN11=0,"Aguardando recebimento",IF(N(R11)=0,"Aguardando CDF",IF(AJ11<N(W11),"Vínculo de CDF parcial",IF(AO11=0,"CDF localizado, a conferir","Documentação conferida")))))))) | T11: =IF(Z11=0,"",IF(S11="Cadastro incompleto","MTR INCOMPLETO",IF(S11="Informação a revisar",IF(AND(AH11>0,AC11=0,AD11=0,AF11=0,AK11=0,AL11=0),"QUANTIDADE A REVISAR","IDENTIFICAÇÃO A REVISAR"),IF(S11="Aguardando recebimento","RECEBIMENTO NÃO CONFIRMADO",IF(S11="Aguardando CDF","CDF NÃO LOCALIZADO",IF(S11="Vínculo de CDF parcial","VÍNCULO INCOMPLETO",IF(S11="CDF localizado, a conferir","CDF A CONFERIR",""))))))) | U11: =IF(T11="","",IF(AQ11="","Não calculável",IF(AQ11>TODAY(),"Data futura",TODAY()-AQ11))) | V11: =IF(Z11=0,"",SUMIFS('RECEBIMENTOS'!$H$6:$H$1005,'RECEBIMENTOS'!$B$6:$B$1005,A11,'RECEBIMENTOS'!$Z$6:$Z$1005,1)) | W11: =IF(Z11=0,"",COUNTIFS('ITENS_MTR'!$S$6:$S$1005,A11,'ITENS_MTR'!$R$6:$R$1005,1)) | X11: =IF(AC11=1,"POSSÍVEL DUPLICIDADE","") | Y11: =IF(Z11=0,"",IF(AW11="","Nenhuma",LEFT(AW11,LEN(AW11)-2))) | Z11: =IF(COUNTA(B11:O11)>0,1,0) -> 0 | AA11: =IF(AND(Z11=1,K11<>""),IF(TRIM(K11)=TRIM(cfg_cancel),1,0),0) -> 0 | AB11: =IF(AND(Z11=1,B11<>""),C11&"|"&D11&"|"&G11&"|"&TRIM(B11),"") | AC11: =IF(AB11="",0,IF(SUMPRODUCT(--($AB$6:$AB$505=AB11))>1,1,0)) -> 0 | AD11: =IF(Z11=0,0,IF(OR(AND(G11<>"",ISNA(MATCH(G11,'CAD_UNIDADES'!$C$6:$C$105,0))),AND(H11<>"",ISNA(MATCH(H11,cmp_transp,0))),AND(I11<>"",ISNA(MATCH(I11,cmp_dest,0))),AND(E11<>"",NOT(ISNUMBER(E11))),AND(F11<>"",NOT(ISNUMBER(F11))),AND(ISNUMBER(E11),ISNUMBER(F11),F11<E11)),1,0)) -> 0 | AE11: =IF(Z11=0,0,IF(OR(B11="",C11="",E11="",G11="",H11="",I11="",N(W11)=0),1,0)) -> 0 | AF11: =IF(Z11=0,0,COUNTIFS('ITENS_MTR'!$S$6:$S$1005,A11,'ITENS_MTR'!$AI$6:$AI$1005,1)) -> 0 | AG11: =IF(Z11=0,0,COUNTIFS('ITENS_MTR'!$S$6:$S$1005,A11,'ITENS_MTR'!$AJ$6:$AJ$1005,1)) -> 0 | AH11: =IF(Z11=0,0,COUNTIFS('ITENS_MTR'!$S$6:$S$1005,A11,'ITENS_MTR'!$AM$6:$AM$1005,1)) -> 0 | AI11: =IF(Z11=0,0,COUNTIFS('ITENS_MTR'!$S$6:$S$1005,A11,'ITENS_MTR'!$AO$6:$AO$1005,1)) -> 0 | AJ11: =IF(Z11=0,0,COUNTIFS('ITENS_MTR'!$S$6:$S$1005,A11,'ITENS_MTR'!$AN$6:$AN$1005,1)) -> 0 | AK11: =IF(Z11=0,0,COUNTIFS('RECEBIMENTOS'!$B$6:$B$1005,A11,'RECEBIMENTOS'!$Y$6:$Y$1005,1)) -> 0 | AL11: =IF(Z11=0,0,COUNTIFS('VÍNCULOS_CDF'!$D$6:$D$1005,A11,'VÍNCULOS_CDF'!$Y$6:$Y$1005,1)) -> 0 | AM11: =IF(Z11=0,0,COUNTIFS('RECEBIMENTOS'!$B$6:$B$1005,A11,'RECEBIMENTOS'!$Q$6:$Q$1005,1)) -> 0 | AN11: =IF(AND(Z11=1,N(W11)>0,AG11=N(W11)),1,0) -> 0 | AO11: =IF(AND(Z11=1,N(W11)>0,AI11=N(W11)),1,0) -> 0 | AP11: =IF(Z11=0,0,_xlfn.MAXIFS('RECEBIMENTOS'!$E$6:$E$1005,'RECEBIMENTOS'!$B$6:$B$1005,A11)) -> 0 | AQ11: =IF(T11="","",IF(T11="RECEBIMENTO NÃO CONFIRMADO",IF(ISNUMBER(F11),F11,IF(ISNUMBER(E11),E11,"")),IF(OR(T11="CDF NÃO LOCALIZADO",T11="VÍNCULO INCOMPLETO",T11="CDF A CONFERIR"),IF(AP11>0,AP11,IF(ISNUMBER(E11),E11,"")),IF(ISNUMBER(E11),E11,"")))) | AR11: =IF(NOT(ISNUMBER(U11)),0,IF(T11="RECEBIMENTO NÃO CONFIRMADO",IF(AND(ISNUMBER(cfg_rec),U11>cfg_rec),1,0),IF(OR(T11="CDF NÃO LOCALIZADO",T11="VÍNCULO INCOMPLETO",T11="CDF A CONFERIR"),IF(AND(ISNUMBER(cfg_cdf),U11>cfg_cdf),1,0),0))) -> 0 | AS11: =IF(T11="","",IF(AR11=1,"Alta",IFERROR(INDEX(cfg_pp,MATCH(T11,cfg_pt,0))&"","Média"))) | AT11: =IF(T11="","",IFERROR(INDEX(cfg_pv,MATCH(T11,cfg_pt,0))&"","")) | AU11: =IF(T11="","",IF(AS11="Alta",1,IF(AS11="Média",2,3))*1000000000+(999999-IF(ISNUMBER(U11),MIN(U11,999999),0))*1000+6) | AV11: =IF(T11<>"",1,0) -> 0 | AW11: =IF(Z11=0,"",IF(AA11=1,"Cancelamento informado; ","")&IF(AE11=1,"Campos essenciais ou itens faltando; ","")&IF(AC11=1,"Possível duplicidade do número; ","")&IF(AD11=1,"Cadastro ou datas a revisar; ","")&IF(AF11>0,"Item de resíduo com dado a revisar; ","")&IF(AH11>0,"Diferença de quantidade a analisar; ","")&IF(AK11>0,"Recebimento com alerta; ","")&IF(AL11>0,"Vínculo de CDF com alerta; ","")&IF(AND(AA11=0,AN11=0),"Recebimento não confirmado; ","")&IF(AND(AA11=0,AN11=1,AO11=0),"CDF pendente ou a conferir; ","")) | AX11: =IF(Z11=0,0,IF(AND(OR(f_ini="",AND(ISNUMBER(E11),E11>=f_ini)),OR(f_fim="",AND(ISNUMBER(E11),E11<=f_fim)),OR(f_un="",f_un="(Todas)",G11=f_un),OR(f_tr="",f_tr="(Todos)",H11=f_tr),OR(f_de="",f_de="(Todos)",I11=f_de),OR(f_sit="",f_sit="(Todas)",S11=f_sit)),1,0)) -> 0 | AY11: =IF(AX11=0,0,IF(OR(f_res="",f_res="(Todos)"),1,IF(COUNTIFS('ITENS_MTR'!$S$6:$S$1005,A11,'ITENS_MTR'!$C$6:$C$1005,f_res)>0,1,0))) -> 0 | AZ11: =IF(ISNUMBER(E11),DATE(YEAR(E11),MONTH(E11),1),"") | BA11: =IF(Z11=0,0,IF(AND(OR(r_ini="",AND(ISNUMBER(E11),E11>=r_ini)),OR(r_fim="",AND(ISNUMBER(E11),E11<=r_fim)),OR(r_un="",r_un="(Todas)",G11=r_un),OR(r_de="",r_de="(Todos)",I11=r_de)),1,0)) -> 0 | BB11: =IF(BA11=1,COUNTIF($BA$6:BA11,1),"") | BC11: =IF(AND(AU11<>"",OR(r_un="",r_un="(Todas)",G11=r_un),OR(r_de="",r_de="(Todos)",I11=r_de)),AU11,"") | BD11: =IF(Z11=1,A11&" | nº "&IF(B11="","(sem número)",B11)&" | "&IF(G11="","(sem unidade)",G11),"") | BE11: =IF(Z11=1,COUNTIF($Z$6:Z11,1),"") | BF11: =IF(T11="","",IF(T11="RECEBIMENTO NÃO CONFIRMADO","Transp.: "&H11&" | Dest.: "&I11,IF(OR(T11="CDF NÃO LOCALIZADO",T11="VÍNCULO INCOMPLETO",T11="CDF A CONFERIR"),"Dest.: "&I11,"Gerador: "&G11)))
A12: MTR-000007 | P12: =IF(Z12=0,"",SUMIFS('ITENS_MTR'!$I$6:$I$1005,'ITENS_MTR'!$S$6:$S$1005,A12,'ITENS_MTR'!$Y$6:$Y$1005,1)) | Q12: =IF(Z12=0,"",SUMIFS('RECEBIMENTOS'!$H$6:$H$1005,'RECEBIMENTOS'!$B$6:$B$1005,A12,'RECEBIMENTOS'!$X$6:$X$1005,1)) | R12: =IF(Z12=0,"",SUMIFS('VÍNCULOS_CDF'!$H$6:$H$1005,'VÍNCULOS_CDF'!$D$6:$D$1005,A12,'VÍNCULOS_CDF'!$V$6:$V$1005,1)) | S12: =IF(Z12=0,"",IF(AA12=1,"Cancelado (informado)",IF(AE12=1,"Cadastro incompleto",IF(OR(AC12=1,AD12=1,AF12>0,AH12>0,AK12>0,AL12>0),"Informação a revisar",IF(AN12=0,"Aguardando recebimento",IF(N(R12)=0,"Aguardando CDF",IF(AJ12<N(W12),"Vínculo de CDF parcial",IF(AO12=0,"CDF localizado, a conferir","Documentação conferida")))))))) | T12: =IF(Z12=0,"",IF(S12="Cadastro incompleto","MTR INCOMPLETO",IF(S12="Informação a revisar",IF(AND(AH12>0,AC12=0,AD12=0,AF12=0,AK12=0,AL12=0),"QUANTIDADE A REVISAR","IDENTIFICAÇÃO A REVISAR"),IF(S12="Aguardando recebimento","RECEBIMENTO NÃO CONFIRMADO",IF(S12="Aguardando CDF","CDF NÃO LOCALIZADO",IF(S12="Vínculo de CDF parcial","VÍNCULO INCOMPLETO",IF(S12="CDF localizado, a conferir","CDF A CONFERIR",""))))))) | U12: =IF(T12="","",IF(AQ12="","Não calculável",IF(AQ12>TODAY(),"Data futura",TODAY()-AQ12))) | V12: =IF(Z12=0,"",SUMIFS('RECEBIMENTOS'!$H$6:$H$1005,'RECEBIMENTOS'!$B$6:$B$1005,A12,'RECEBIMENTOS'!$Z$6:$Z$1005,1)) | W12: =IF(Z12=0,"",COUNTIFS('ITENS_MTR'!$S$6:$S$1005,A12,'ITENS_MTR'!$R$6:$R$1005,1)) | X12: =IF(AC12=1,"POSSÍVEL DUPLICIDADE","") | Y12: =IF(Z12=0,"",IF(AW12="","Nenhuma",LEFT(AW12,LEN(AW12)-2))) | Z12: =IF(COUNTA(B12:O12)>0,1,0) -> 0 | AA12: =IF(AND(Z12=1,K12<>""),IF(TRIM(K12)=TRIM(cfg_cancel),1,0),0) -> 0 | AB12: =IF(AND(Z12=1,B12<>""),C12&"|"&D12&"|"&G12&"|"&TRIM(B12),"") | AC12: =IF(AB12="",0,IF(SUMPRODUCT(--($AB$6:$AB$505=AB12))>1,1,0)) -> 0 | AD12: =IF(Z12=0,0,IF(OR(AND(G12<>"",ISNA(MATCH(G12,'CAD_UNIDADES'!$C$6:$C$105,0))),AND(H12<>"",ISNA(MATCH(H12,cmp_transp,0))),AND(I12<>"",ISNA(MATCH(I12,cmp_dest,0))),AND(E12<>"",NOT(ISNUMBER(E12))),AND(F12<>"",NOT(ISNUMBER(F12))),AND(ISNUMBER(E12),ISNUMBER(F12),F12<E12)),1,0)) -> 0 | AE12: =IF(Z12=0,0,IF(OR(B12="",C12="",E12="",G12="",H12="",I12="",N(W12)=0),1,0)) -> 0 | AF12: =IF(Z12=0,0,COUNTIFS('ITENS_MTR'!$S$6:$S$1005,A12,'ITENS_MTR'!$AI$6:$AI$1005,1)) -> 0 | AG12: =IF(Z12=0,0,COUNTIFS('ITENS_MTR'!$S$6:$S$1005,A12,'ITENS_MTR'!$AJ$6:$AJ$1005,1)) -> 0 | AH12: =IF(Z12=0,0,COUNTIFS('ITENS_MTR'!$S$6:$S$1005,A12,'ITENS_MTR'!$AM$6:$AM$1005,1)) -> 0 | AI12: =IF(Z12=0,0,COUNTIFS('ITENS_MTR'!$S$6:$S$1005,A12,'ITENS_MTR'!$AO$6:$AO$1005,1)) -> 0 | AJ12: =IF(Z12=0,0,COUNTIFS('ITENS_MTR'!$S$6:$S$1005,A12,'ITENS_MTR'!$AN$6:$AN$1005,1)) -> 0 | AK12: =IF(Z12=0,0,COUNTIFS('RECEBIMENTOS'!$B$6:$B$1005,A12,'RECEBIMENTOS'!$Y$6:$Y$1005,1)) -> 0 | AL12: =IF(Z12=0,0,COUNTIFS('VÍNCULOS_CDF'!$D$6:$D$1005,A12,'VÍNCULOS_CDF'!$Y$6:$Y$1005,1)) -> 0 | AM12: =IF(Z12=0,0,COUNTIFS('RECEBIMENTOS'!$B$6:$B$1005,A12,'RECEBIMENTOS'!$Q$6:$Q$1005,1)) -> 0 | AN12: =IF(AND(Z12=1,N(W12)>0,AG12=N(W12)),1,0) -> 0 | AO12: =IF(AND(Z12=1,N(W12)>0,AI12=N(W12)),1,0) -> 0 | AP12: =IF(Z12=0,0,_xlfn.MAXIFS('RECEBIMENTOS'!$E$6:$E$1005,'RECEBIMENTOS'!$B$6:$B$1005,A12)) -> 0 | AQ12: =IF(T12="","",IF(T12="RECEBIMENTO NÃO CONFIRMADO",IF(ISNUMBER(F12),F12,IF(ISNUMBER(E12),E12,"")),IF(OR(T12="CDF NÃO LOCALIZADO",T12="VÍNCULO INCOMPLETO",T12="CDF A CONFERIR"),IF(AP12>0,AP12,IF(ISNUMBER(E12),E12,"")),IF(ISNUMBER(E12),E12,"")))) | AR12: =IF(NOT(ISNUMBER(U12)),0,IF(T12="RECEBIMENTO NÃO CONFIRMADO",IF(AND(ISNUMBER(cfg_rec),U12>cfg_rec),1,0),IF(OR(T12="CDF NÃO LOCALIZADO",T12="VÍNCULO INCOMPLETO",T12="CDF A CONFERIR"),IF(AND(ISNUMBER(cfg_cdf),U12>cfg_cdf),1,0),0))) -> 0 | AS12: =IF(T12="","",IF(AR12=1,"Alta",IFERROR(INDEX(cfg_pp,MATCH(T12,cfg_pt,0))&"","Média"))) | AT12: =IF(T12="","",IFERROR(INDEX(cfg_pv,MATCH(T12,cfg_pt,0))&"","")) | AU12: =IF(T12="","",IF(AS12="Alta",1,IF(AS12="Média",2,3))*1000000000+(999999-IF(ISNUMBER(U12),MIN(U12,999999),0))*1000+7) | AV12: =IF(T12<>"",1,0) -> 0 | AW12: =IF(Z12=0,"",IF(AA12=1,"Cancelamento informado; ","")&IF(AE12=1,"Campos essenciais ou itens faltando; ","")&IF(AC12=1,"Possível duplicidade do número; ","")&IF(AD12=1,"Cadastro ou datas a revisar; ","")&IF(AF12>0,"Item de resíduo com dado a revisar; ","")&IF(AH12>0,"Diferença de quantidade a analisar; ","")&IF(AK12>0,"Recebimento com alerta; ","")&IF(AL12>0,"Vínculo de CDF com alerta; ","")&IF(AND(AA12=0,AN12=0),"Recebimento não confirmado; ","")&IF(AND(AA12=0,AN12=1,AO12=0),"CDF pendente ou a conferir; ","")) | AX12: =IF(Z12=0,0,IF(AND(OR(f_ini="",AND(ISNUMBER(E12),E12>=f_ini)),OR(f_fim="",AND(ISNUMBER(E12),E12<=f_fim)),OR(f_un="",f_un="(Todas)",G12=f_un),OR(f_tr="",f_tr="(Todos)",H12=f_tr),OR(f_de="",f_de="(Todos)",I12=f_de),OR(f_sit="",f_sit="(Todas)",S12=f_sit)),1,0)) -> 0 | AY12: =IF(AX12=0,0,IF(OR(f_res="",f_res="(Todos)"),1,IF(COUNTIFS('ITENS_MTR'!$S$6:$S$1005,A12,'ITENS_MTR'!$C$6:$C$1005,f_res)>0,1,0))) -> 0 | AZ12: =IF(ISNUMBER(E12),DATE(YEAR(E12),MONTH(E12),1),"") | BA12: =IF(Z12=0,0,IF(AND(OR(r_ini="",AND(ISNUMBER(E12),E12>=r_ini)),OR(r_fim="",AND(ISNUMBER(E12),E12<=r_fim)),OR(r_un="",r_un="(Todas)",G12=r_un),OR(r_de="",r_de="(Todos)",I12=r_de)),1,0)) -> 0 | BB12: =IF(BA12=1,COUNTIF($BA$6:BA12,1),"") | BC12: =IF(AND(AU12<>"",OR(r_un="",r_un="(Todas)",G12=r_un),OR(r_de="",r_de="(Todos)",I12=r_de)),AU12,"") | BD12: =IF(Z12=1,A12&" | nº "&IF(B12="","(sem número)",B12)&" | "&IF(G12="","(sem unidade)",G12),"") | BE12: =IF(Z12=1,COUNTIF($Z$6:Z12,1),"") | BF12: =IF(T12="","",IF(T12="RECEBIMENTO NÃO CONFIRMADO","Transp.: "&H12&" | Dest.: "&I12,IF(OR(T12="CDF NÃO LOCALIZADO",T12="VÍNCULO INCOMPLETO",T12="CDF A CONFERIR"),"Dest.: "&I12,"Gerador: "&G12)))
