Workbook

Sheet Início
B2: KIT DE FORMULÁRIOS PARA A GESTÃO DE RESÍDUOS · VERSÃO 1.0
B3: KIT PRÉ-MTR
B4: 15 Formulários Prontos para Coletas e Movimentação de Resíduos
B5: Modelos editáveis para organizar, conferir, registrar e acompanhar informações da rotina ambiental. 15 formulários | 3 categorias | Prontos para preencher
B7: ⓘ Os formulários deste kit são modelos internos de organização e registro. Não substituem documentos oficiais, avaliações técnicas ou procedimentos exigidos pelos órgãos competentes.
B9: COMO UTILIZAR
B10: 1 | C10: Escolha o formulário | D10: Clique em Abrir no índice abaixo ou use as abas F01 a F15.
B11: 2 | C11: Preencha as informações | D11: Digite nas células em tom claro com borda. Nas células com seta, escolha na lista.
B12: 3 | C12: Confira com os responsáveis | D12: Valide os dados com o setor, o transportador ou o destinador antes de usar.
B13: 4 | C13: Salve ou imprima | D13: Salve uma cópia da planilha ou use Arquivo > Imprimir (cada aba já está ajustada para A4).
B15: LEGENDA DAS CÉLULAS
C16: Célula clara com borda: campo para preencher. As demais células são títulos e orientações.
B17: X | C17: Marcação: escolha X na lista. Situações (Conferido, Pendente, Não aplicável) e outras opções também abrem em lista.
B18: Exemplo de formato: data 23/10/2026 · horário 14:30 · quantidade 1250,5 com a unidade kg no campo ao lado.
B20: ÍNDICE DOS FORMULÁRIOS
B21: Código | C21: Formulário | D21: Para que serve | E21: Registro nº | F21: Andamento | G21: Abrir
B22: Categoria 01 · Preparação da coleta
B23: F01 | C23: Solicitação de coleta de resíduos | D23: Registre o pedido de retirada de resíduos e acompanhe a confirmação. | E23: =IF(F01!L3="","",F01!L3) | F23: =IF(COUNTA(F01!L3:M3,F01!B10:G10,F01!H10:M10,F01!B12:F12,F01!G12:J12,F01!K12:M12,F01!C16:C16,F01!G16:G16,F01!I16:I16,F01!K16:K16,F01!C17:C17,F01!G17:G17,F01!I17:I17,F01!K17:K17,F01!C18:C18,F01!G18:G18,F01!I18:I18,F01!K18:K18,F01!C19:C19,F01!G19:G19,F01!I19:I19,F01!K19:K19,F01!C20:C20,F01!G20:G20,F01!I20:I20,F01!K20:K20,F01!B25:J25,F01!K25:M25,F01!B27:M27,F01!B31:M31,F01!B33:G33,F01!H33:J33,F01!K33:M33,F01!B35:M35,F01!B39:J39,F01!K39:M39)=0,"Em branco",COUNTA(F01!L3:M3,F01!B10:G10,F01!H10:M10,F01!B12:F12,F01!G12:J12,F01!K12:M12,F01!C16:C16,F01!G16:G16,F01!I16:I16,F01!K16:K16,F01!C17:C17,F01!G17:G17,F01!I17:I17,F01!K17:K17,F01!C18:C18,F01!G18:G18,F01!I18:I18,F01!K18:K18,F01!C19:C19,F01!G19:G19,F01!I19:I19,F01!K19:K19,F01!C20:C20,F01!G20:G20,F01!I20:I20,F01!K20:K20,F01!B25:J25,F01!K25:M25,F01!B27:M27,F01!B31:M31,F01!B33:G33,F01!H33:J33,F01!K33:M33,F01!B35:M35,F01!B39:J39,F01!K39:M39)&" de 36 campos") -> Em branco | G23: Abrir ›
B24: F02 | C24: Ficha de identificação do resíduo | D24: Organize em um só lugar as informações disponíveis sobre um resíduo. | E24: =IF(F02!L3="","",F02!L3) | F24: =IF(COUNTA(F02!L3:M3,F02!B10:G10,F02!H10:M10,F02!B12:G12,F02!H12:J12,F02!K12:M12,F02!B16:I16,F02!J16:M16,F02!B18:M18,F02!B20:M20,F02!B24:H24,F02!I24:M24,F02!B26:M26,F02!B28:J28,F02!K28:M28,F02!B32:D32,F02!E32:G32,F02!H32:M32,F02!B34:M34,F02!B38:M38,F02!B40:G40,F02!H40:J40,F02!K40:M40)=0,"Em branco",COUNTA(F02!L3:M3,F02!B10:G10,F02!H10:M10,F02!B12:G12,F02!H12:J12,F02!K12:M12,F02!B16:I16,F02!J16:M16,F02!B18:M18,F02!B20:M20,F02!B24:H24,F02!I24:M24,F02!B26:M26,F02!B28:J28,F02!K28:M28,F02!B32:D32,F02!E32:G32,F02!H32:M32,F02!B34:M34,F02!B38:M38,F02!B40:G40,F02!H40:J40,F02!K40:M40)&" de 23 campos") -> Em branco | G24: Abrir ›
B25: F03 | C25: Levantamento de quantidades de resíduos | D25: Anote quantidades estimadas ou verificadas, resíduo por resíduo. | E25: =IF(F03!L3="","",F03!L3) | F25: =IF(COUNTA(F03!L3:M3,F03!B10:G10,F03!H10:M10,F03!B12:G12,F03!H12:J12,F03!K12:M12,F03!C16:C16,F03!G16:G16,F03!H16:H16,F03!J16:J16,F03!L16:L16,F03!C17:C17,F03!G17:G17,F03!H17:H17,F03!J17:J17,F03!L17:L17,F03!C18:C18,F03!G18:G18,F03!H18:H18,F03!J18:J18,F03!L18:L18,F03!C19:C19,F03!G19:G19,F03!H19:H19,F03!J19:J19,F03!L19:L19,F03!C20:C20,F03!G20:G20,F03!H20:H20,F03!J20:J20,F03!L20:L20,F03!C21:C21,F03!G21:G21,F03!H21:H21,F03!J21:J21,F03!L21:L21,F03!C22:C22,F03!G22:G22,F03!H22:H22,F03!J22:J22,F03!L22:L22,F03!C23:C23,F03!G23:G23,F03!H23:H23,F03!J23:J23,F03!L23:L23,F03!C24:C24,F03!G24:G24,F03!H24:H24,F03!J24:J24,F03!L24:L24,F03!C25:C25,F03!G25:G25,F03!H25:H25,F03!J25:J25,F03!L25:L25,F03!C26:C26,F03!G26:G26,F03!H26:H26,F03!J26:J26,F03!L26:L26,F03!C27:C27,F03!G27:G27,F03!H27:H27,F03!J27:J27,F03!L27:L27,F03!C28:C28,F03!G28:G28,F03!H28:H28,F03!J28:J28,F03!L28:L28,F03!C29:C29,F03!G29:G29,F03!H29:H29,F03!J29:J29,F03!L29:L29,F03!B34:M34,F03!B36:G36,F03!H36:J36)=0,"Em branco",COUNTA(F03!L3:M3,F03!B10:G10,F03!H10:M10,F03!B12:G12,F03!H12:J12,F03!K12:M12,F03!C16:C16,F03!G16:G16,F03!H16:H16,F03!J16:J16,F03!L16:L16,F03!C17:C17,F03!G17:G17,F03!H17:H17,F03!J17:J17,F03!L17:L17,F03!C18:C18,F03!G18:G18,F03!H18:H18,F03!J18:J18,F03!L18:L18,F03!C19:C19,F03!G19:G19,F03!H19:H19,F03!J19:J19,F03!L19:L19,F03!C20:C20,F03!G20:G20,F03!H20:H20,F03!J20:J20,F03!L20:L20,F03!C21:C21,F03!G21:G21,F03!H21:H21,F03!J21:J21,F03!L21:L21,F03!C22:C22,F03!G22:G22,F03!H22:H22,F03!J22:J22,F03!L22:L22,F03!C23:C23,F03!G23:G23,F03!H23:H23,F03!J23:J23,F03!L23:L23,F03!C24:C24,F03!G24:G24,F03!H24:H24,F03!J24:J24,F03!L24:L24,F03!C25:C25,F03!G25:G25,F03!H25:H25,F03!J25:J25,F03!L25:L25,F03!C26:C26,F03!G26:G26,F03!H26:H26,F03!J26:J26,F03!L26:L26,F03!C27:C27,F03!G27:G27,F03!H27:H27,F03!J27:J27,F03!L27:L27,F03!C28:C28,F03!G28:G28,F03!H28:H28,F03!J28:J28,F03!L28:L28,F03!C29:C29,F03!G29:G29,F03!H29:H29,F03!J29:J29,F03!L29:L29,F03!B34:M34,F03!B36:G36,F03!H36:J36)&" de 79 campos") -> Em branco | G25: Abrir ›
B26: F04 | C26: Conferência de acondicionamento | D26: Faça uma conferência visual dos recipientes e registre o que precisa ser verificado. | E26: =IF(F04!L3="","",F04!L3) | F26: =IF(COUNTA(F04!L3:M3,F04!B10:G10,F04!H10:J10,F04!K10:M10,F04!B12:J12,F04!K12:M12,F04!C16:C16,F04!E16:E16,F04!G16:G16,F04!I16:I16,F04!K16:K16,F04!C17:C17,F04!E17:E17,F04!G17:G17,F04!I17:I17,F04!K17:K17,F04!C18:C18,F04!E18:E18,F04!G18:G18,F04!I18:I18,F04!K18:K18,F04!C19:C19,F04!E19:E19,F04!G19:G19,F04!I19:I19,F04!K19:K19,F04!C20:C20,F04!E20:E20,F04!G20:G20,F04!I20:I20,F04!K20:K20,F04!C21:C21,F04!E21:E21,F04!G21:G21,F04!I21:I21,F04!K21:K21,F04!B26:M26,F04!B28:M28,F04!B32:G32,F04!H32:J32,F04!K32:M32,F04!B34:M34,F04!B36:M36)=0,"Em branco",COUNTA(F04!L3:M3,F04!B10:G10,F04!H10:J10,F04!K10:M10,F04!B12:J12,F04!K12:M12,F04!C16:C16,F04!E16:E16,F04!G16:G16,F04!I16:I16,F04!K16:K16,F04!C17:C17,F04!E17:E17,F04!G17:G17,F04!I17:I17,F04!K17:K17,F04!C18:C18,F04!E18:E18,F04!G18:G18,F04!I18:I18,F04!K18:K18,F04!C19:C19,F04!E19:E19,F04!G19:G19,F04!I19:I19,F04!K19:K19,F04!C20:C20,F04!E20:E20,F04!G20:G20,F04!I20:I20,F04!K20:K20,F04!C21:C21,F04!E21:E21,F04!G21:G21,F04!I21:I21,F04!K21:K21,F04!B26:M26,F04!B28:M28,F04!B32:G32,F04!H32:J32,F04!K32:M32,F04!B34:M34,F04!B36:M36)&" de 43 campos") -> Em branco | G26: Abrir ›
B27: F05 | C27: Agendamento de coleta | D27: Organize data, transportador, carga prevista e orientações de acesso. | E27: =IF(F05!L3="","",F05!L3) | F27: =IF(COUNTA(F05!L3:M3,F05!B10:G10,F05!H10:M10,F05!B12:D12,F05!E12:F12,F05!G12:H12,F05!I12:M12,F05!B14:G14,F05!H14:M14,F05!C18:C18,F05!G18:G18,F05!I18:I18,F05!K18:K18,F05!C19:C19,F05!G19:G19,F05!I19:I19,F05!K19:K19,F05!C20:C20,F05!G20:G20,F05!I20:I20,F05!K20:K20,F05!C21:C21,F05!G21:G21,F05!I21:I21,F05!K21:K21,F05!C22:C22,F05!G22:G22,F05!I22:I22,F05!K22:K22,F05!B27:M27,F05!B29:M29,F05!B33:G33,F05!H33:M33,F05!B35:M35,F05!B37:D37,F05!E37:M37)=0,"Em branco",COUNTA(F05!L3:M3,F05!B10:G10,F05!H10:M10,F05!B12:D12,F05!E12:F12,F05!G12:H12,F05!I12:M12,F05!B14:G14,F05!H14:M14,F05!C18:C18,F05!G18:G18,F05!I18:I18,F05!K18:K18,F05!C19:C19,F05!G19:G19,F05!I19:I19,F05!K19:K19,F05!C20:C20,F05!G20:G20,F05!I20:I20,F05!K20:K20,F05!C21:C21,F05!G21:G21,F05!I21:I21,F05!K21:K21,F05!C22:C22,F05!G22:G22,F05!I22:I22,F05!K22:K22,F05!B27:M27,F05!B29:M29,F05!B33:G33,F05!H33:M33,F05!B35:M35,F05!B37:D37,F05!E37:M37)&" de 36 campos") -> Em branco | G27: Abrir ›
B28: Categoria 02 · Dados e movimentação
B29: F06 | C29: Ficha cadastral do transportador | D29: Reúna os dados do transportador e acompanhe o que precisa ser conferido. | E29: =IF(F06!L3="","",F06!L3) | F29: =IF(COUNTA(F06!L3:M3,F06!B10:I10,F06!J10:M10,F06!B12:M12,F06!B14:G14,F06!H14:M14,F06!B18:G18,F06!H18:M18,F06!B20:M20,F06!H24:H24,F06!J24:J24,F06!L24:L24,F06!H25:H25,F06!J25:J25,F06!L25:L25,F06!H26:H26,F06!J26:J26,F06!L26:L26,F06!H27:H27,F06!J27:J27,F06!L27:L27,F06!C28:C28,F06!H28:H28,F06!J28:J28,F06!L28:L28,F06!C29:C29,F06!H29:H29,F06!J29:J29,F06!L29:L29,F06!B34:G34,F06!H34:J34,F06!K34:M34,F06!B36:M36)=0,"Em branco",COUNTA(F06!L3:M3,F06!B10:I10,F06!J10:M10,F06!B12:M12,F06!B14:G14,F06!H14:M14,F06!B18:G18,F06!H18:M18,F06!B20:M20,F06!H24:H24,F06!J24:J24,F06!L24:L24,F06!H25:H25,F06!J25:J25,F06!L25:L25,F06!H26:H26,F06!J26:J26,F06!L26:L26,F06!H27:H27,F06!J27:J27,F06!L27:L27,F06!C28:C28,F06!H28:H28,F06!J28:J28,F06!L28:L28,F06!C29:C29,F06!H29:H29,F06!J29:J29,F06!L29:L29,F06!B34:G34,F06!H34:J34,F06!K34:M34,F06!B36:M36)&" de 33 campos") -> Em branco | G29: Abrir ›
B30: F07 | C30: Ficha cadastral do destinador | D30: Registre os dados da unidade destinadora, os resíduos previstos e as referências a conferir. | E30: =IF(F07!L3="","",F07!L3) | F30: =IF(COUNTA(F07!L3:M3,F07!B10:I10,F07!J10:M10,F07!B12:G12,F07!H12:M12,F07!B14:G14,F07!H14:M14,F07!C18:C18,F07!G18:G18,F07!K18:K18,F07!C19:C19,F07!G19:G19,F07!K19:K19,F07!C20:C20,F07!G20:G20,F07!K20:K20,F07!C21:C21,F07!G21:G21,F07!K21:K21,F07!H26:H26,F07!J26:J26,F07!L26:L26,F07!H27:H27,F07!J27:J27,F07!L27:L27,F07!H28:H28,F07!J28:J28,F07!L28:L28,F07!H29:H29,F07!J29:J29,F07!L29:L29,F07!C30:C30,F07!H30:H30,F07!J30:J30,F07!L30:L30,F07!B35:M35,F07!B37:J37,F07!K37:M37,F07!B39:M39)=0,"Em branco",COUNTA(F07!L3:M3,F07!B10:I10,F07!J10:M10,F07!B12:G12,F07!H12:M12,F07!B14:G14,F07!H14:M14,F07!C18:C18,F07!G18:G18,F07!K18:K18,F07!C19:C19,F07!G19:G19,F07!K19:K19,F07!C20:C20,F07!G20:G20,F07!K20:K20,F07!C21:C21,F07!G21:G21,F07!K21:K21,F07!H26:H26,F07!J26:J26,F07!L26:L26,F07!H27:H27,F07!J27:J27,F07!L27:L27,F07!H28:H28,F07!J28:J28,F07!L28:L28,F07!H29:H29,F07!J29:J29,F07!L29:L29,F07!C30:C30,F07!H30:H30,F07!J30:J30,F07!L30:L30,F07!B35:M35,F07!B37:J37,F07!K37:M37,F07!B39:M39)&" de 39 campos") -> Em branco | G30: Abrir ›
B31: F08 | C31: Ficha preparatória de informações para MTR | D31: Reúna e confira os dados antes de lançar o MTR no sistema. | E31: =IF(F08!L3="","",F08!L3) | F31: =IF(COUNTA(F08!L3:M3,F08!B11:F11,F08!G11:M11,F08!B13:J13,F08!K13:M13,F08!B18:G18,F08!H18:J18,F08!K18:M18,F08!B20:G20,F08!B23:G23,F08!H23:J23,F08!K23:M23,F08!B25:G25,F08!B28:G28,F08!H28:J28,F08!K28:M28,F08!B30:G30,F08!B33:G33,F08!H33:J33,F08!K33:M33,F08!B35:B35,F08!C39:C39,F08!F39:F39,F08!H39:H39,F08!I39:I39,F08!K39:K39,F08!M39:M39,F08!C40:C40,F08!F40:F40,F08!H40:H40,F08!I40:I40,F08!K40:K40,F08!M40:M40,F08!C41:C41,F08!F41:F41,F08!H41:H41,F08!I41:I41,F08!K41:K41,F08!M41:M41,F08!C42:C42,F08!F42:F42,F08!H42:H42,F08!I42:I42,F08!K42:K42,F08!M42:M42,F08!B47:M47,F08!C49:C49,F08!I49:I49,F08!L49:L49,F08!M49:M49,F08!C50:C50,F08!I50:I50,F08!L50:L50,F08!M50:M50,F08!C51:C51,F08!I51:I51,F08!L51:L51,F08!M51:M51,F08!C52:C52,F08!I52:I52,F08!L52:L52,F08!M52:M52,F08!C53:C53,F08!I53:I53,F08!L53:L53,F08!M53:M53,F08!C54:C54,F08!I54:I54,F08!L54:L54,F08!M54:M54,F08!C55:C55,F08!I55:I55,F08!L55:L55,F08!M55:M55,F08!B58:M58)=0,"Em branco",COUNTA(F08!L3:M3,F08!B11:F11,F08!G11:M11,F08!B13:J13,F08!K13:M13,F08!B18:G18,F08!H18:J18,F08!K18:M18,F08!B20:G20,F08!B23:G23,F08!H23:J23,F08!K23:M23,F08!B25:G25,F08!B28:G28,F08!H28:J28,F08!K28:M28,F08!B30:G30,F08!B33:G33,F08!H33:J33,F08!K33:M33,F08!B35:B35,F08!C39:C39,F08!F39:F39,F08!H39:H39,F08!I39:I39,F08!K39:K39,F08!M39:M39,F08!C40:C40,F08!F40:F40,F08!H40:H40,F08!I40:I40,F08!K40:K40,F08!M40:M40,F08!C41:C41,F08!F41:F41,F08!H41:H41,F08!I41:I41,F08!K41:K41,F08!M41:M41,F08!C42:C42,F08!F42:F42,F08!H42:H42,F08!I42:I42,F08!K42:K42,F08!M42:M42,F08!B47:M47,F08!C49:C49,F08!I49:I49,F08!L49:L49,F08!M49:M49,F08!C50:C50,F08!I50:I50,F08!L50:L50,F08!M50:M50,F08!C51:C51,F08!I51:I51,F08!L51:L51,F08!M51:M51,F08!C52:C52,F08!I52:I52,F08!L52:L52,F08!M52:M52,F08!C53:C53,F08!I53:I53,F08!L53:L53,F08!M53:M53,F08!C54:C54,F08!I54:I54,F08!L54:L54,F08!M54:M54,F08!C55:C55,F08!I55:I55,F08!L55:L55,F08!M55:M55,F08!B58:M58)&" de 75 campos") -> Em branco | G31: Abrir ›
B32: F09 | C32: Checklist de conferência documental pré-saída | D32: Confira os itens documentais e operacionais antes da saída da carga. | E32: =IF(F09!L3="","",F09!L3) | F32: =IF(COUNTA(F09!L3:M3,F09!B10:E10,F09!F10:J10,F09!K10:M10,F09!I14:I14,F09!K14:K14,F09!I15:I15,F09!K15:K15,F09!I16:I16,F09!K16:K16,F09!I17:I17,F09!K17:K17,F09!I18:I18,F09!K18:K18,F09!I19:I19,F09!K19:K19,F09!I20:I20,F09!K20:K20,F09!I21:I21,F09!K21:K21,F09!C22:C22,F09!I22:I22,F09!K22:K22,F09!C23:C23,F09!I23:I23,F09!K23:K23,F09!B28:M28,F09!B30:M30,F09!B34:G34,F09!H34:J34,F09!K34:M34,F09!B36:M36)=0,"Em branco",COUNTA(F09!L3:M3,F09!B10:E10,F09!F10:J10,F09!K10:M10,F09!I14:I14,F09!K14:K14,F09!I15:I15,F09!K15:K15,F09!I16:I16,F09!K16:K16,F09!I17:I17,F09!K17:K17,F09!I18:I18,F09!K18:K18,F09!I19:I19,F09!K19:K19,F09!I20:I20,F09!K20:K20,F09!I21:I21,F09!K21:K21,F09!C22:C22,F09!I22:I22,F09!K22:K22,F09!C23:C23,F09!I23:I23,F09!K23:K23,F09!B28:M28,F09!B30:M30,F09!B34:G34,F09!H34:J34,F09!K34:M34,F09!B36:M36)&" de 32 campos") -> Em branco | G32: Abrir ›
B33: F10 | C33: Registro de confirmação de retirada | D33: Registre como foi a retirada: horário, transportador, resíduos e divergências. | E33: =IF(F10!L3="","",F10!L3) | F33: =IF(COUNTA(F10!L3:M3,F10!B11:G11,F10!H11:M11,F10!B13:D13,F10!E13:F13,F10!G13:M13,F10!B15:G15,F10!H15:M15,F10!C19:C19,F10!G19:G19,F10!I19:I19,F10!J19:J19,F10!K19:K19,F10!C20:C20,F10!G20:G20,F10!I20:I20,F10!J20:J20,F10!K20:K20,F10!C21:C21,F10!G21:G21,F10!I21:I21,F10!J21:J21,F10!K21:K21,F10!C22:C22,F10!G22:G22,F10!I22:I22,F10!J22:J22,F10!K22:K22,F10!C23:C23,F10!G23:G23,F10!I23:I23,F10!J23:J23,F10!K23:K23,F10!C24:C24,F10!G24:G24,F10!I24:I24,F10!J24:J24,F10!K24:K24,F10!B29:M29,F10!B31:M31,F10!B35:J35,F10!K35:M35,F10!B37:M37)=0,"Em branco",COUNTA(F10!L3:M3,F10!B11:G11,F10!H11:M11,F10!B13:D13,F10!E13:F13,F10!G13:M13,F10!B15:G15,F10!H15:M15,F10!C19:C19,F10!G19:G19,F10!I19:I19,F10!J19:J19,F10!K19:K19,F10!C20:C20,F10!G20:G20,F10!I20:I20,F10!J20:J20,F10!K20:K20,F10!C21:C21,F10!G21:G21,F10!I21:I21,F10!J21:J21,F10!K21:K21,F10!C22:C22,F10!G22:G22,F10!I22:I22,F10!J22:J22,F10!K22:K22,F10!C23:C23,F10!G23:G23,F10!I23:I23,F10!J23:J23,F10!K23:K23,F10!C24:C24,F10!G24:G24,F10!I24:I24,F10!J24:J24,F10!K24:K24,F10!B29:M29,F10!B31:M31,F10!B35:J35,F10!K35:M35,F10!B37:M37)&" de 43 campos") -> Em branco | G33: Abrir ›
B34: Categoria 03 · Acompanhamento operacional
B35: F11 | C35: Registro de informações do recebimento | D35: Organize as informações recebidas sobre a chegada da carga ao destino. | E35: =IF(F11!L3="","",F11!L3) | F35: =IF(COUNTA(F11!L3:M3,F11!B10:E10,F11!F10:M10,F11!B12:G12,F11!H12:M12,F11!C16:C16,F11!G16:G16,F11!I16:I16,F11!K16:K16,F11!L16:L16,F11!C17:C17,F11!G17:G17,F11!I17:I17,F11!K17:K17,F11!L17:L17,F11!C18:C18,F11!G18:G18,F11!I18:I18,F11!K18:K18,F11!L18:L18,F11!C19:C19,F11!G19:G19,F11!I19:I19,F11!K19:K19,F11!L19:L19,F11!C20:C20,F11!G20:G20,F11!I20:I20,F11!K20:K20,F11!L20:L20,F11!B25:D25,F11!E25:G25,F11!H25:M25,F11!B27:M27,F11!B31:M31,F11!B33:M33,F11!B35:J35,F11!K35:M35)=0,"Em branco",COUNTA(F11!L3:M3,F11!B10:E10,F11!F10:M10,F11!B12:G12,F11!H12:M12,F11!C16:C16,F11!G16:G16,F11!I16:I16,F11!K16:K16,F11!L16:L16,F11!C17:C17,F11!G17:G17,F11!I17:I17,F11!K17:K17,F11!L17:L17,F11!C18:C18,F11!G18:G18,F11!I18:I18,F11!K18:K18,F11!L18:L18,F11!C19:C19,F11!G19:G19,F11!I19:I19,F11!K19:K19,F11!L19:L19,F11!C20:C20,F11!G20:G20,F11!I20:I20,F11!K20:K20,F11!L20:L20,F11!B25:D25,F11!E25:G25,F11!H25:M25,F11!B27:M27,F11!B31:M31,F11!B33:M33,F11!B35:J35,F11!K35:M35)&" de 38 campos") -> Em branco | G35: Abrir ›
B36: F12 | C36: Registro de divergência de quantidade | D36: Documente uma diferença entre a quantidade informada e a verificada. | E36: =IF(F12!L3="","",F12!L3) | F36: =IF(COUNTA(F12!L3:M3,F12!B10:G10,F12!H10:M10,F12!B12:J12,F12!K12:M12,F12!B17:D17,F12!E17:G17,F12!H17:M17,F12!B20:D20,F12!E20:G20,F12!H20:M20,F12!B27:M27,F12!B31:G31,F12!H31:J31,F12!K31:M31,F12!B33:M33,F12!B35:M35,F12!B37:M37)=0,"Em branco",COUNTA(F12!L3:M3,F12!B10:G10,F12!H10:M10,F12!B12:J12,F12!K12:M12,F12!B17:D17,F12!E17:G17,F12!H17:M17,F12!B20:D20,F12!E20:G20,F12!H20:M20,F12!B27:M27,F12!B31:G31,F12!H31:J31,F12!K31:M31,F12!B33:M33,F12!B35:M35,F12!B37:M37)&" de 18 campos") -> Em branco | G36: Abrir ›
B37: F13 | C37: Registro de ocorrência na coleta ou movimentação | D37: Registre fatos operacionais que precisam de acompanhamento. | E37: =IF(F13!L3="","",F13!L3) | F37: =IF(COUNTA(F13!L3:M3,F13!B10:D10,F13!E10:F10,F13!G10:M10,F13!B12:G12,F13!H12:M12,F13!B16:B16,F13!H16:H16,F13!B17:B17,F13!H17:H17,F13!B18:B18,F13!H18:H18,F13!B19:B19,F13!B21:M21,F13!B23:M23,F13!C27:C27,F13!H27:H27,F13!K27:K27,F13!C28:C28,F13!H28:H28,F13!K28:K28,F13!B31:M31,F13!B35:G35,F13!H35:K35,F13!L35:M35,F13!B37:M37)=0,"Em branco",COUNTA(F13!L3:M3,F13!B10:D10,F13!E10:F10,F13!G10:M10,F13!B12:G12,F13!H12:M12,F13!B16:B16,F13!H16:H16,F13!B17:B17,F13!H17:H17,F13!B18:B18,F13!H18:H18,F13!B19:B19,F13!B21:M21,F13!B23:M23,F13!C27:C27,F13!H27:H27,F13!K27:K27,F13!C28:C28,F13!H28:H28,F13!K28:K28,F13!B31:M31,F13!B35:G35,F13!H35:K35,F13!L35:M35,F13!B37:M37)&" de 26 campos") -> Em branco | G37: Abrir ›
B38: F14 | C38: Registro de pendência documental | D38: Detalhe uma pendência específica e acompanhe cada contato até o encerramento. | E38: =IF(F14!L3="","",F14!L3) | F38: =IF(COUNTA(F14!L3:M3,F14!B10:F10,F14!G10:M10,F14!B12:M12,F14!B14:D14,F14!E14:M14,F14!B18:G18,F14!H18:M18,F14!B20:J20,F14!K20:M20,F14!C24:C24,F14!E24:E24,F14!L24:L24,F14!C25:C25,F14!E25:E25,F14!L25:L25,F14!C26:C26,F14!E26:E26,F14!L26:L26,F14!C27:C27,F14!E27:E27,F14!L27:L27,F14!C28:C28,F14!E28:E28,F14!L28:L28,F14!C29:C29,F14!E29:E29,F14!L29:L29,F14!C30:C30,F14!E30:E30,F14!L30:L30,F14!B35:M35,F14!B37:D37,F14!E37:J37,F14!K37:M37)=0,"Em branco",COUNTA(F14!L3:M3,F14!B10:F10,F14!G10:M10,F14!B12:M12,F14!B14:D14,F14!E14:M14,F14!B18:G18,F14!H18:M18,F14!B20:J20,F14!K20:M20,F14!C24:C24,F14!E24:E24,F14!L24:L24,F14!C25:C25,F14!E25:E25,F14!L25:L25,F14!C26:C26,F14!E26:E26,F14!L26:L26,F14!C27:C27,F14!E27:E27,F14!L27:L27,F14!C28:C28,F14!E28:E28,F14!L28:L28,F14!C29:C29,F14!E29:E29,F14!L29:L29,F14!C30:C30,F14!E30:E30,F14!L30:L30,F14!B35:M35,F14!B37:D37,F14!E37:J37,F14!K37:M37)&" de 35 campos") -> Em branco | G38: Abrir ›
B39: F15 | C39: Registro de encerramento do acompanhamento | D39: Registre o encerramento interno de um acompanhamento específico. | E39: =IF(F15!L3="","",F15!L3) | F39: =IF(COUNTA(F15!L3:M3,F15!B11:E11,F15!F11:I11,F15!J11:M11,F15!G15:G15,F15!J15:J15,F15!L15:L15,F15!G16:G16,F15!J16:J16,F15!L16:L16,F15!G17:G17,F15!J17:J17,F15!L17:L17,F15!C18:C18,F15!G18:G18,F15!J18:J18,F15!L18:L18,F15!B23:M23,F15!B25:M25,F15!B27:M27,F15!B29:M29,F15!B31:M31,F15!B35:M35,F15!B37:J37,F15!K37:M37)=0,"Em branco",COUNTA(F15!L3:M3,F15!B11:E11,F15!F11:I11,F15!J11:M11,F15!G15:G15,F15!J15:J15,F15!L15:L15,F15!G16:G16,F15!J16:J16,F15!L16:L16,F15!G17:G17,F15!J17:J17,F15!L17:L17,F15!C18:C18,F15!G18:G18,F15!J18:J18,F15!L18:L18,F15!B23:M23,F15!B25:M25,F15!B27:M27,F15!B29:M29,F15!B31:M31,F15!B35:M35,F15!B37:J37,F15!K37:M37)&" de 25 campos") -> Em branco | G39: Abrir ›
B40: Orientações finais de utilização ›
B41: Andamento conta as células preenchidas de cada formulário, incluindo o Registro nº. Os itens sugeridos já escritos nas tabelas não entram na contagem.

Sheet F01
K1: ‹ Voltar ao índice
B2: FORMULÁRIO 01 · CATEGORIA: PREPARAÇÃO DA COLETA | J2: Código | K2: Versão | L2: Registro nº
B3: Solicitação de coleta de resíduos | J3: F01 | K3: 1.0
B5: Finalidade de uso: Registrar internamente um pedido de coleta e acompanhar sua confirmação.
B6: ⓘ Use quando um setor ou unidade pedir a retirada de resíduos. Preencha com os dados disponíveis e atualize a situação até a coleta ser confirmada.
B8: A | C8: Identificação da solicitação
B9: Empresa solicitante | H9: Unidade ou local de origem
B11: Responsável pela solicitação | G11: Contato profissional (telefone ou e-mail) | K11: Data da solicitação
B14: B | C14: Resíduos a coletar
B15: Nº | C15: Tipo ou descrição do resíduo | G15: Quantidade estimada | I15: Unidade de medida | K15: Forma de acondicionamento
B16: 1
B17: 2
B18: 3
B19: 4
B20: 5
B21: Para mais linhas, selecione a última linha da tabela, copie e use Inserir células copiadas.
B23: C | C23: Retirada
B24: Local previsto para retirada | K24: Data preferencial
B26: Observações operacionais
B29: D | C29: Acompanhamento da solicitação
B30: Situação da solicitação (escolha na lista)
B32: Confirmado com (nome e empresa) | H32: Data da confirmação | K32: Data acertada para a coleta
B34: Informações de confirmação
B37: E | C37: Registro
B38: Preenchido por | K38: Data do registro
B41: F01 · Solicitação de coleta de resíduos | I41: Modelo interno de organização e registro · Versão 1.0

Sheet F02
K1: ‹ Voltar ao índice
B2: FORMULÁRIO 02 · CATEGORIA: PREPARAÇÃO DA COLETA | J2: Código | K2: Versão | L2: Registro nº
B3: Ficha de identificação do resíduo | J3: F02 | K3: 1.0
B5: Finalidade de uso: Organizar as informações disponíveis sobre um resíduo gerado.
B6: ⓘ Use uma ficha para cada resíduo, registrando de onde veio cada informação. A ficha organiza dados e não substitui a avaliação técnica nem a documentação exigível.
B8: A | C8: Origem
B9: Unidade geradora | H9: Setor ou atividade de origem
B11: Responsável pelas informações | H11: Contato profissional | K11: Data do levantamento
B14: B | C14: Identificação do resíduo
B15: Identificação do resíduo (nome usado internamente) | J15: Código de identificação, quando aplicável
B17: Descrição
B19: Estado físico, quando pertinente (escolha na lista)
B22: C | C22: Classificação técnica
B23: Classificação técnica informada ou verificada | I23: Responsável técnico consultado, se houver
B25: Origem da informação (escolha na lista)
B27: Referência utilizada para conferência | K27: Data da referência
B30: D | C30: Quantidade e acondicionamento
B31: Quantidade estimada | E31: Unidade de medida | H31: Período de referência
B33: Forma de acondicionamento
B36: E | C36: Observações e registro
B37: Observações
B39: Preenchido por | H39: Data do registro | K39: Próxima revisão
B42: F02 · Ficha de identificação do resíduo | I42: Modelo interno de organização e registro · Versão 1.0

Sheet F03
K1: ‹ Voltar ao índice
B2: FORMULÁRIO 03 · CATEGORIA: PREPARAÇÃO DA COLETA | J2: Código | K2: Versão | L2: Registro nº
B3: Levantamento de quantidades de resíduos | J3: F03 | K3: 1.0
B5: Finalidade de uso: Registrar quantidades estimadas ou verificadas de cada resíduo.
B6: ⓘ Use em levantamentos periódicos ou antes de programar uma coleta. Indique sempre a unidade de medida e de onde veio cada valor.
B8: A | C8: Identificação do levantamento
B9: Empresa | H9: Unidade
B11: Setor | H11: Responsável pelo levantamento | K11: Data do levantamento
B14: B | C14: Quantidades levantadas
B15: Nº | C15: Identificação ou descrição do resíduo | G15: Quantidade | H15: Unidade de medida | J15: Origem da informação | L15: Observações
B16: 1
B17: 2
B18: 3
B19: 4
B20: 5
B21: 6
B22: 7
B23: 8
B24: 9
B25: 10
B26: 11
B27: 12
... B29: 14
B30: Os valores não são somados automaticamente, porque podem estar em unidades diferentes. Peso, volume e número de volumes não são equivalentes entre si. Para mais linhas, selecione a última linha da tabela, copie e use Inserir células copiadas.
B32: C | C32: Observações e conferência
B33: Observações gerais
B35: Conferido por | H35: Data da conferência
B38: F03 · Levantamento de quantidades de resíduos | I38: Modelo interno de organização e registro · Versão 1.0

Sheet F04
K1: ‹ Voltar ao índice
B2: FORMULÁRIO 04 · CATEGORIA: PREPARAÇÃO DA COLETA | J2: Código | K2: Versão | L2: Registro nº
B3: Conferência de acondicionamento | J3: F04 | K3: 1.0
B5: Finalidade de uso: Apoiar a conferência visual do acondicionamento antes da coleta.
B6: ⓘ Registre o que foi observado em cada recipiente e encaminhe os pontos que precisam de verificação. Esta ficha não substitui inspeções, normas técnicas ou procedimentos internos.
B8: A | C8: Identificação da conferência
B9: Local | H9: Área ou setor | K9: Data
B11: Responsável pela conferência | K11: Horário
B14: B | C14: Itens observados
B15: Nº | C15: Resíduo identificado | E15: Recipiente ou acondicionamento observado | G15: Identificação disponível | I15: Condição visual observada | K15: Ponto a verificar
B16: 1
B17: 2
B18: 3
B19: 4
B20: 5
B21: 6
B22: V = Verificado · NC = Necessita conferência · NA = Não aplicável Para mais linhas, selecione a última linha da tabela, copie e use Inserir células copiadas.
B24: C | C24: Pontos para verificação
B25: Pontos que necessitam de verificação
B27: Observações
B30: D | C30: Encaminhamento
B31: Encaminhado a (responsável competente) | H31: Área | K31: Data do encaminhamento
B33: Forma de comunicação (escolha na lista)
B35: Retorno recebido
B38: F04 · Conferência de acondicionamento | I38: Modelo interno de organização e registro · Versão 1.0

Sheet F05
K1: ‹ Voltar ao índice
B2: FORMULÁRIO 05 · CATEGORIA: PREPARAÇÃO DA COLETA | J2: Código | K2: Versão | L2: Registro nº
B3: Agendamento de coleta | J3: F05 | K3: 1.0
B5: Finalidade de uso: Organizar as informações de uma coleta programada.
B6: ⓘ Use depois que a coleta for combinada com o transportador. Deixe registradas as orientações de acesso e o responsável que vai acompanhar a retirada.
B8: A | C8: Dados da coleta
B9: Empresa geradora | H9: Local de coleta
B11: Data programada | E11: Janela prevista: das | G11: às | I11: Referência da movimentação
B13: Empresa transportadora | H13: Contato de referência (nome e telefone)
B16: B | C16: Carga prevista
B17: Nº | C17: Resíduo ou carga prevista | G17: Quantidade estimada | I17: Unidade de medida | K17: Acondicionamento
B18: 1
B19: 2
B20: 3
B21: 4
B22: 5
B23: Para mais linhas, selecione a última linha da tabela, copie e use Inserir células copiadas.
B25: C | C25: Acesso e orientações
B26: Informações de acesso ao local
B28: Orientações operacionais internas
B31: D | C31: Acompanhamento
B32: Responsável pelo acompanhamento | H32: Contato do responsável
B34: Situação do agendamento (escolha na lista)
B36: Nova data, se reprogramado | E36: Observações
B39: F05 · Agendamento de coleta | I39: Modelo interno de organização e registro · Versão 1.0

Sheet F06
K1: ‹ Voltar ao índice
B2: FORMULÁRIO 06 · CATEGORIA: DADOS E MOVIMENTAÇÃO | J2: Código | K2: Versão | L2: Registro nº
B3: Ficha cadastral do transportador | J3: F06 | K3: 1.0
B5: Finalidade de uso: Organizar os dados cadastrais de um transportador e as conferências realizadas.
B6: ⓘ Atualize a ficha a cada conferência e registre a fonte das informações. A ficha organiza dados e não comprova habilitação, licenciamento ou regularidade.
B8: A | C8: Dados da empresa
B9: Razão social | J9: CNPJ
B11: Endereço ou unidade de referência
B13: Contato profissional | H13: Telefone ou e-mail corporativo
B16: B | C16: Sistema de registro
B17: Sistema aplicável, quando pertinente | H17: Identificação ou cadastro no sistema
B19: Informações cadastrais no sistema
B22: C | C22: Documentos ou informações a conferir
B23: Nº | C23: Documento ou informação | H23: Número ou referência | J23: Validade informada | L23: Situação
B24: 1 | C24: Licença ou autorização ambiental aplicável
B25: 2 | C25: Cadastro no sistema de MTR, se aplicável
B26: 3 | C26: Documentos do veículo (procedimento interno)
B27: 4 | C27: Contato operacional atualizado
B28: 5
B29: 6
B30: C = Conferido · P = Pendente · NA = Não aplicável Para mais linhas, selecione a última linha da tabela, copie e use Inserir células copiadas.
B32: D | C32: Conferência
B33: Responsável pela conferência | H33: Data da última conferência | K33: Próxima conferência prevista
B35: Observações
B38: F06 · Ficha cadastral do transportador | I38: Modelo interno de organização e registro · Versão 1.0

Sheet F07
K1: ‹ Voltar ao índice
B2: FORMULÁRIO 07 · CATEGORIA: DADOS E MOVIMENTAÇÃO | J2: Código | K2: Versão | L2: Registro nº
B3: Ficha cadastral do destinador | J3: F07 | K3: 1.0
B5: Finalidade de uso: Organizar os dados de uma unidade destinadora e as referências conferidas.
B6: ⓘ Use uma ficha para cada unidade destinadora. Registre os resíduos previstos e o serviço pretendido para cada um.
B8: A | C8: Dados da empresa
B9: Razão social | J9: CNPJ
B11: Unidade destinadora | H11: Localização (endereço, município e UF)
B13: Contato profissional | H13: Telefone ou e-mail corporativo
B16: B | C16: Resíduos e serviço
B17: Nº | C17: Resíduo previsto | G17: Serviço ou destinação pretendida | K17: Observações
B18: 1
B19: 2
B20: 3
B21: 4
B22: Para mais linhas, selecione a última linha da tabela, copie e use Inserir células copiadas.
B24: C | C24: Referências documentais a conferir
B25: Nº | C25: Referência documental | H25: Número ou referência | J25: Validade informada | L25: Situação
B26: 1 | C26: Licença ambiental da unidade, conforme atividade
B27: 2 | C27: Cadastro no sistema de MTR, se aplicável
B28: 3 | C28: Contrato ou proposta de serviço
B29: 4 | C29: Emissão do comprovante de destinação
B30: 5
B31: C = Conferido · P = Pendente · NA = Não aplicável Para mais linhas, selecione a última linha da tabela, copie e use Inserir células copiadas.
B33: D | C33: Conferência
B34: Sistema de registro aplicável, quando identificado
B36: Responsável pela conferência | K36: Data
B38: Observações
B41: F07 · Ficha cadastral do destinador | I41: Modelo interno de organização e registro · Versão 1.0

Sheet F08
K1: ‹ Voltar ao índice
B2: FORMULÁRIO 08 · CATEGORIA: DADOS E MOVIMENTAÇÃO | J2: Código | K2: Versão | L2: Registro nº
B3: Ficha preparatória de informações para MTR | J3: F08 | K3: 1.0
B5: Finalidade de uso: Reunir e conferir previamente os dados que podem ser necessários ao preenchimento do MTR.
B6: ⓘ Preencha antes de acessar o sistema e confira cada participante. Os campos exigidos podem variar conforme o sistema utilizado.
B7: ⚠ Ficha interna preparatória. Não substitui o MTR emitido no sistema aplicável.
B9: A | C9: Identificação
B10: Referência interna da movimentação | G10: Sistema a ser utilizado, quando identificado
B12: Responsável pela conferência | K12: Data
B15: B | C15: Participantes da movimentação
B16: GERADOR
B17: Razão social | H17: CNPJ | K17: Dados (escolha na lista)
B19: Unidade de origem
B21: TRANSPORTADOR
B22: Razão social | H22: CNPJ | K22: Dados (escolha na lista)
B24: Veículo ou placa, quando informado
B26: DESTINADOR
B27: Razão social | H27: CNPJ | K27: Dados (escolha na lista)
B29: Unidade destinadora
B31: ARMAZENADOR TEMPORÁRIO, SE APLICÁVEL
B32: Razão social | H32: CNPJ | K32: Dados (escolha na lista)
C35: Não se aplica a esta movimentação
B37: C | C37: Resíduos da movimentação
B38: Nº | C38: Resíduo | F38: Código ou identificação aplicável | H38: Quantidade | I38: Unidade de medida | K38: Acondicionamento | M38: Conferido
B39: 1
B40: 2
B41: 3
B42: 4
B43: Para mais linhas, selecione a última linha da tabela, copie e use Inserir células copiadas.
B45: D | C45: Observações e pendências
B46: Observações sobre a movimentação
B48: Nº | C48: Informação pendente | I48: Quem vai informar | L48: Prazo | M48: Resolvida
B49: 1
B50: 2
B51: 3
B52: 4
B53: 5
B54: 6
B55: 7
B56: Para mais linhas, selecione a última linha da tabela, copie e use Inserir células copiadas.
...

Sheet F09
K1: ‹ Voltar ao índice
B2: FORMULÁRIO 09 · CATEGORIA: DADOS E MOVIMENTAÇÃO | J2: Código | K2: Versão | L2: Registro nº
B3: Checklist de conferência documental pré-saída | J3: F09 | K3: 1.0
B5: Finalidade de uso: Apoiar a conferência documental interna antes da saída da carga.
B6: ⓘ Marque cada item antes da saída e registre o que ficou pendente. O checklist apoia a conferência interna e não comprova o cumprimento de todas as obrigações aplicáveis.
B8: A | C8: Identificação
B9: Referência da movimentação | F9: Local de saída | K9: Data
B12: B | C12: Itens de conferência
B13: Nº | C13: Item de conferência | I13: Situação | K13: Observação
B14: 1 | C14: Identificação do resíduo conferida
B15: 2 | C15: Quantidade informada conferida
B16: 3 | C16: Dados do transportador verificados
B17: 4 | C17: Dados do destinador verificados
B18: 5 | C18: Documento de transporte aplicável verificado, conforme o sistema utilizado
B19: 6 | C19: Informações operacionais da coleta confirmadas
B20: 7 | C20: Pendências registradas
B21: 8 | C21: Referências adicionais aplicáveis verificadas, quando houver
B22: 9
B23: 10
B24: Escolha Conferido, Pendente ou Não aplicável em cada item. As últimas linhas ficam livres para itens próprios da sua empresa.
B26: C | C26: Resultado da conferência
B27: Resultado (escolha na lista)
B29: Pendências e encaminhamentos
B32: D | C32: Registro
B33: Responsável pela conferência | H33: Data | K33: Horário
B35: Observações
B38: F09 · Checklist de conferência documental pré-saída | I38: Modelo interno de organização e registro · Versão 1.0

Sheet F10
K1: ‹ Voltar ao índice
B2: FORMULÁRIO 10 · CATEGORIA: DADOS E MOVIMENTAÇÃO | J2: Código | K2: Versão | L2: Registro nº
B3: Registro de confirmação de retirada | J3: F10 | K3: 1.0
B5: Finalidade de uso: Registrar internamente a retirada dos resíduos no local de origem.
B6: ⓘ Preencha no momento da retirada ou logo depois, com as informações observadas.
B7: ⚠ Registro interno. Não substitui os documentos de transporte aplicáveis.
B9: A | C9: Dados da retirada
B10: Empresa ou unidade geradora | H10: Local da retirada
B12: Data | E12: Horário | G12: Transportador informado
B14: Referência da movimentação | H14: Veículo ou placa, quando informado
B17: B | C17: Resíduos retirados
B18: Nº | C18: Resíduo | G18: Quantidade informada | I18: Quantidade observada | J18: Unidade de medida | K18: Observação
B19: 1
B20: 2
B21: 3
B22: 4
B23: 5
B24: 6
B25: Para mais linhas, selecione a última linha da tabela, copie e use Inserir células copiadas.
B27: C | C27: Divergências
B28: Divergências (escolha na lista)
B30: Divergências registradas
B33: D | C33: Acompanhamento
B34: Responsável pelo acompanhamento | K34: Data do registro
B36: Observações
B39: F10 · Registro de confirmação de retirada | I39: Modelo interno de organização e registro · Versão 1.0

Sheet F11
K1: ‹ Voltar ao índice
B2: FORMULÁRIO 11 · CATEGORIA: ACOMPANHAMENTO OPERACIONAL | J2: Código | K2: Versão | L2: Registro nº
B3: Registro de informações do recebimento | J3: F11 | K3: 1.0
B5: Finalidade de uso: Organizar as informações recebidas sobre a chegada da carga ao destino.
B6: ⓘ Registre a confirmação de recebimento e a fonte da informação. O recebimento pode acontecer antes da destinação final, que deve ser acompanhada à parte.
B8: A | C8: Movimentação
B9: Referência do MTR, quando aplicável | F9: Gerador
B11: Transportador | H11: Destinador
B14: B | C14: Resíduos e quantidades
B15: Nº | C15: Resíduo | G15: Quantidade enviada | I15: Quantidade recebida informada | K15: Unidade de medida | L15: Divergência
B16: 1
B17: 2
B18: 3
B19: 4
B20: 5
B21: Para mais linhas, selecione a última linha da tabela, copie e use Inserir células copiadas.
B23: C | C23: Confirmação do recebimento
B24: Data informada do recebimento | E24: Data em que a informação foi obtida | H24: Quem informou
B26: Fonte da confirmação (escolha na lista)
B29: D | C29: Divergências e registro
B30: Divergências identificadas
B32: Observações
B34: Responsável pelo registro | K34: Data do registro
B37: F11 · Registro de informações do recebimento | I37: Modelo interno de organização e registro · Versão 1.0

Sheet F12
K1: ‹ Voltar ao índice
B2: FORMULÁRIO 12 · CATEGORIA: ACOMPANHAMENTO OPERACIONAL | J2: Código | K2: Versão | L2: Registro nº
B3: Registro de divergência de quantidade | J3: F12 | K3: 1.0
B5: Finalidade de uso: Documentar internamente uma possível divergência de quantidade.
B6: ⓘ Registre os dois valores com a unidade e a fonte de cada um. A diferença só é calculada quando as unidades forem iguais.
B8: A | C8: Identificação
B9: Identificação da movimentação | H9: Resíduo
B11: Responsável pelo registro | K11: Data da identificação
B14: B | C14: Valores comparados
B15: QUANTIDADE ORIGINALMENTE INFORMADA
B16: Quantidade | E16: Unidade de medida | H16: Fonte do valor
B18: QUANTIDADE RECEBIDA OU VERIFICADA
B19: Quantidade | E19: Unidade de medida | H19: Fonte do valor
B21: Diferença, quando as unidades forem comparáveis | H21: Unidade | J21: % sobre a quantidade informada
B22: =IF(OR(B17="",B20=""),"",IF(OR(TRIM(E17)="",TRIM(E20)=""),"Não calculada: informe as duas unidades",IF(LOWER(TRIM(E17))<>LOWER(TRIM(E20)),"Não calculada: unidades diferentes",B20-B17))) | H22: =IF(ISNUMBER(B22),TRIM(E20),"") | J22: =IF(AND(ISNUMBER(B22),B17<>0),B22/B17,"")
B23: Cálculo automático: quantidade verificada menos quantidade informada, e o percentual sobre a quantidade informada. Só é feito quando as duas unidades de medida são iguais. Peso, volume e número de volumes não são convertidos.
B25: C | C25: Descrição da divergência
B26: Descrição da divergência
B29: D | C29: Comunicação e acompanhamento
B30: Responsável comunicado | H30: Empresa ou área | K30: Data da comunicação
B32: Forma de comunicação (escolha na lista)
B34: Situação do acompanhamento (escolha na lista)
B36: Observações finais
B39: F12 · Registro de divergência de quantidade | I39: Modelo interno de organização e registro · Versão 1.0

Sheet F13
K1: ‹ Voltar ao índice
B2: FORMULÁRIO 13 · CATEGORIA: ACOMPANHAMENTO OPERACIONAL | J2: Código | K2: Versão | L2: Registro nº
B3: Registro de ocorrência na coleta ou movimentação | J3: F13 | K3: 1.0
B5: Finalidade de uso: Registrar situações operacionais que precisam de acompanhamento.
B6: ⓘ Descreva os fatos de forma objetiva, sem suposições. Em situações de emergência, as equipes devem seguir os procedimentos de segurança aplicáveis.
B8: A | C8: Identificação
B9: Data | E9: Horário | G9: Local
B11: Unidade ou empresa envolvida | H11: Referência da movimentação
B14: B | C14: Ocorrência
B15: Tipo de ocorrência (marque com X as opções que se aplicam)
C16: Atraso ou não comparecimento na coleta | I16: Reprogramação
C17: Divergência de informação ou documento | I17: Carga recusada ou devolvida
C18: Dificuldade de acesso ao local | I18: Condição de acondicionamento observada
C19: Outra
B20: Se outra, especifique
B22: Descrição objetiva dos fatos
B25: C | C25: Comunicação e encaminhamento
B26: Nº | C26: Pessoa ou área profissional comunicada | H26: Forma | K26: Data
B27: 1
B28: 2
B29: Para mais linhas, selecione a última linha da tabela, copie e use Inserir células copiadas.
B30: Encaminhamento informado
B33: D | C33: Acompanhamento
B34: Situação do acompanhamento (escolha na lista) | H34: Responsável pelo registro | L34: Data do registro
B36: Observações adicionais
B39: F13 · Registro de ocorrência na coleta ou movimentação | I39: Modelo interno de organização e registro · Versão 1.0

Sheet F14
K1: ‹ Voltar ao índice
B2: FORMULÁRIO 14 · CATEGORIA: ACOMPANHAMENTO OPERACIONAL | J2: Código | K2: Versão | L2: Registro nº
B3: Registro de pendência documental | J3: F14 | K3: 1.0
B5: Finalidade de uso: Detalhar e acompanhar uma pendência documental específica.
B6: ⓘ Use uma ficha para cada pendência que exige acompanhamento próximo. O controle geral continua na planilha ou no sistema que você já utiliza.
B8: A | C8: Pendência
B9: Referência da movimentação | G9: Documento relacionado
B11: Pendência identificada
B13: Data de identificação | E13: Responsável pelo acompanhamento
B16: B | C16: Providência solicitada
B17: Empresa ou setor contatado | H17: Contato
B19: Providência solicitada | K19: Data da solicitação
B22: C | C22: Histórico de acompanhamento
B23: Nº | C23: Data | E23: Informações recebidas ou contato realizado | L23: Próxima verificação
B24: 1
B25: 2
B26: 3
B27: 4
B28: 5
B29: 6
B30: 7
B31: Para mais linhas, selecione a última linha da tabela, copie e use Inserir células copiadas.
B33: D | C33: Situação e encerramento
B34: Situação atual (escolha na lista)
B36: Próxima verificação | E36: Evidência ou referência do encerramento | K36: Data do encerramento
B39: F14 · Registro de pendência documental | I39: Modelo interno de organização e registro · Versão 1.0

Sheet F15
K1: ‹ Voltar ao índice
B2: FORMULÁRIO 15 · CATEGORIA: ACOMPANHAMENTO OPERACIONAL | J2: Código | K2: Versão | L2: Registro nº
B3: Registro de encerramento do acompanhamento | J3: F15 | K3: 1.0
B5: Encerramento do acompanhamento interno
B6: Finalidade de uso: Registrar o encerramento administrativo de um acompanhamento interno.
B7: ⓘ Preencha quando o acompanhamento de uma movimentação for concluído internamente. Este registro não é certificado de destinação nem declaração de conformidade.
B9: A | C9: Identificação
B10: Identificação da movimentação | F10: Unidade geradora | J10: Resíduo
B13: B | C13: Referências documentais disponíveis
B14: Nº | C14: Documento | G14: Número ou referência | J14: Data | L14: Consultado
B15: 1 | C15: MTR, quando aplicável
B16: 2 | C16: Comprovante de recebimento
B17: 3 | C17: CDF ou comprovante de destinação
B18: 4
B19: Para mais linhas, selecione a última linha da tabela, copie e use Inserir células copiadas.
B21: C | C21: Histórico do acompanhamento
B22: Situação inicialmente acompanhada
B24: Providências realizadas
B26: Evidências documentais consultadas
B28: Pendências remanescentes (escolha na lista)
B30: Descrição das pendências remanescentes
B33: D | C33: Encerramento do acompanhamento interno
B34: Observações de encerramento
B36: Responsável pelo registro | K36: Data
B39: F15 · Registro de encerramento do acompanhamento | I39: Modelo interno de organização e registro · Versão 1.0

Sheet Orientações
C1: ‹ Voltar ao índice
B2: Orientações finais de utilização
B4: 1 | C4: Confira os dados antes do uso | D4: Compare as informações registradas com os documentos e com os responsáveis por cada etapa antes de lançar dados em qualquer sistema.
B5: 2 | C5: Adapte os campos à sua empresa | D5: Use os campos de observação e as linhas adicionais para incluir o que for próprio dos seus procedimentos internos.
B6: 3 | C6: Guarde cópias de forma organizada | D6: Salve as cópias com nomes claros, por exemplo F08_2026-10_Unidade-A, conforme a organização interna.
B7: 4 | C7: Consulte os procedimentos oficiais | D7: Quando houver dúvida sobre documentos exigidos, prazos ou classificação, siga os procedimentos oficiais e o sistema aplicável.
B9: Em que momento usar cada formulário
B10: Antes da coleta
B11: F01 | C11: Solicitação de coleta de resíduos
B12: F02 | C12: Ficha de identificação do resíduo
B13: F03 | C13: Levantamento de quantidades de resíduos
B14: F04 | C14: Conferência de acondicionamento
B15: F05 | C15: Agendamento de coleta
B16: F06 | C16: Ficha cadastral do transportador
B17: F07 | C17: Ficha cadastral do destinador
B18: Preparação da saída
B19: F08 | C19: Ficha preparatória de informações para MTR
B20: F09 | C20: Checklist de conferência documental pré-saída
B21: F10 | C21: Registro de confirmação de retirada
B22: Depois da saída
B23: F11 | C23: Registro de informações do recebimento
B24: F12 | C24: Registro de divergência de quantidade
B25: F13 | C25: Registro de ocorrência na coleta ou movimentação
B26: F14 | C26: Registro de pendência documental
B27: F15 | C27: Registro de encerramento do acompanhamento
B29: O Kit Pré-MTR foi pensado para ser usado junto com os 70 Fluxos Visuais de MTR, CDF e Controle de Resíduos. Os fluxos ajudam a entender cada etapa, a planilha de controle acompanha os registros de MTR e CDF, e estes formulários organizam as informações de cada coleta e de cada situação específica.

Sheet Listas
A1: dl-unidades | B1: Situação da solicitação | C1: Estado físico, quando pertinente | D1: Origem da informação | E1: dl-origem | F1: situação | G1: Forma de comunicação | H1: Situação do agendamento | I1: situação | J1: dl-destinacao | K1: Dados | L1: marcação | M1: Situação da ficha | N1: Resultado | O1: Divergências | P1: Fonte da confirmação | Q1: Situação do acompanhamento | R1: Situação do acompanhamento | S1: Situação atual | T1: Pendências remanescentes
A2: kg | B2: Registrada | C2: Sólido | D2: Informada | E2: Estimativa | F2: Verificado | G2: E-mail | H2: A confirmar | I2: Conferido | J2: Reciclagem | K2: Conferidos | L2: X | M2: Pronta para lançamento no sistema | N2: Sem pendências registradas | O2: Nenhuma identificada | P2: Sistema de MTR | Q2: Aberta | R2: Aberta | S2: Aberta | T2: Nenhuma identificada
A3: t | B3: Em análise | C3: Pastoso | D3: Verificada em documento | E3: Pesagem | F3: Necessita conferência | G3: Mensagem | H3: Confirmado | I3: Pendente | J3: Recuperação ou reaproveitamento | K3: A conferir | M3: Com pendências | N3: Com pendências registradas | O3: Identificadas e descritas abaixo | P3: E-mail do destinador | Q3: Aguardando retorno | R3: Em acompanhamento | S3: Aguardando retorno | T3: Há pendências, descritas abaixo
A4: L | B4: Confirmada | C4: Líquido | D4: A confirmar | E4: Contagem de volumes | F4: Não aplicável | G4: Telefone | H4: Reprogramado | I4: Não aplicável | J4: Tratamento | P4: Comprovante ou ticket | Q4: Em análise | R4: Encerrada | S4: Em análise
A5: m³ | B5: Reprogramada | C5: Outro | E5: Informação do setor | G5: Reunião | H5: Realizado | J5: Coprocessamento | P5: Contato telefônico | Q5: Esclarecida | S5: Resolvida
A6: unidade(s) | B6: Cancelada | C6: Não informado | E6: Documento ou registro | G6: Outra | H6: Cancelado | J6: Disposição final | P6: Outra | Q6: Encerrada | S6: Encerrada
A7: tambor(es) | J7: Armazenamento temporário
A8: bombona(s) | J8: A definir
A9: contêiner(es)
A10: big bag(s)
A11: caçamba(s)
