Workbook

Sheet 00 — Painel Inicial
B2: KIT DE 6 CALCULADORAS AUTOMÁTICAS DE ENGENHARIA AMBIENTAL
B3: Resolva, confira e entenda cálculos de hidráulica, carga poluidora, eficiência, balanço de massa, diluição e dosagem química. Tudo automático, com a fórmula explicada passo a passo.
B6: 📘 COMECE AQUI (GUIA) | D6: 📚 BIBLIOTECA DE EXEMPLOS | F6: ▶ COMO USAR EM 5 PASSOS
B8: ESCOLHA SUA CALCULADORA
B9: 💧 CALCULADORA 01 | D9: 🏭 CALCULADORA 02 | F9: 📉 CALCULADORA 03
B10: Vazão e Hidráulica | D10: Carga Poluidora | F10: Eficiência de Tratamento
B11: Calcule vazão por volume e tempo, vazão em tubulações, velocidade do escoamento e tempo de detenção hidráulica, com conversão automática de unidades. | D11: Descubra quantos kg por dia de DBO, DQO, SST, nitrogênio ou fósforo uma corrente transporta. Também calcula a concentração ou a vazão a partir da carga. | F11: Avalie quanto um sistema de tratamento removeu, por concentração ou por carga, com gráfico de antes e depois e interpretação automática.
B12: 4 ferramentas · m³/s, L/s, m³/h, m³/dia · aba 02 | D12: 3 ferramentas · kg/dia, mg/L, m³/dia · aba 03 | F12: 2 ferramentas · % de remoção e gráficos · aba 04
B13: Abrir calculadora ▶ | D13: Abrir calculadora ▶ | F13: Abrir calculadora ▶
B16: ⚖️ CALCULADORA 04 | D16: 🧪 CALCULADORA 05 | F16: ⚗️ CALCULADORA 06
B17: Balanço de Massa | D17: Diluição de Soluções | F17: Dosagem de Produtos Químicos
B18: Misture duas correntes, feche o balanço de um decantador e calcule o acúmulo de massa em um sistema, com cada etapa explicada. | D18: Prepare soluções no laboratório com C₁V₁ = C₂V₂. Escolha o que quer descobrir e receba a instrução de preparo pronta. | F18: Calcule a massa de componente ativo, a massa de produto comercial e o volume diário de produto líquido para uma dosagem definida.
B19: 3 ferramentas · mistura, decantador, acúmulo · aba 05 | D19: 1 fórmula · 4 incógnitas possíveis · aba 06 | F19: 3 etapas · kg/dia e L/dia · aba 07
B20: Abrir calculadora ▶ | D20: Abrir calculadora ▶ | F20: Abrir calculadora ▶
B23: COMO COMEÇAR | F23: LEGENDA DAS CORES
B24: 1. Escolha uma calculadora e clique em Abrir calculadora. | F24: Amarelo-claro: campo para você digitar ou escolher
B25: 2. Na lista Cenário, escolha Exemplo 01, Exemplo 02 ou Meu cálculo. | F25: Verde: resultado automático e indicadores positivos
B26: 3. Em Meu cálculo, preencha os campos amarelos da coluna MEU CÁLCULO. | F26: Azul-claro: valor em uso, que entrou na conta
B27: 4. Confira o resultado automático destacado em verde. | F27: Azul: botão de navegação (clique)
B28: 5. Leia a explicação em Entenda o cálculo e verifique as unidades. | F28: Cinza-claro: explicações e exemplos cadastrados
B29: Dúvidas? Abra o guia completo na aba 01: Comece Aqui. | F29: Vermelho suave: avisos e dados inválidos
B31: Importante: os resultados são cálculos teóricos de apoio ao estudo. Projetos, laudos e decisões operacionais exigem normas técnicas, legislação aplicável e responsável técnico. Guarde uma cópia original deste arquivo e salve cada trabalho com outro nome.
B32: Sem macros · Sem internet · Excel e Google Planilhas · Abas protegidas sem senha contra alterações acidentais

Sheet 01 — Comece Aqui
B1: 📘 COMECE AQUI: GUIA COMPLETO
B2: Leia esta página uma vez e você saberá usar todo o kit.
B3: 🏠 Painel Inicial | C3: 📚 Exemplos Resolvidos | D3: Primeira calculadora ▶
B6: 1 O QUE É O KIT
B7: Este kit reúne 6 calculadoras automáticas para os cálculos mais comuns da Engenharia Ambiental: vazão e hidráulica, carga poluidora, eficiência de tratamento, balanço de massa, diluição de soluções e dosagem de produtos químicos. Você informa os dados, a planilha calcula na hora e mostra a fórmula usada, a substituição dos valores e uma explicação do resultado. Funciona como um pequeno aplicativo dentro da planilha, sem macros e sem internet.
B9: 2 PARA QUEM FOI DESENVOLVIDO
B10: Para estudantes de Engenharia Ambiental e de cursos próximos (Sanitária, Civil, Química, Gestão Ambiental) que precisam resolver listas de exercícios, conferir contas de provas e trabalhos, preparar relatórios de laboratório ou apoiar atividades de estágio. Você não precisa saber Excel: basta escolher opções nas listas e digitar números nos campos amarelos.
B12: 3 COMO USAR EM 5 PASSOS
B13: PASSO 1 | C13: Escolha uma calculadora. No Painel Inicial, clique no card da calculadora que resolve o seu problema. Na dúvida, use a tabela Qual calculadora usar, logo abaixo.
B14: PASSO 2 | C14: Selecione um exemplo ou a opção "Meu cálculo". Cada ferramenta tem a lista Cenário. Exemplo 01 e Exemplo 02 carregam dados prontos. Meu cálculo usa os valores que você digitar.
B15: PASSO 3 | C15: Preencha os campos amarelos. Digite seus valores na coluna MEU CÁLCULO e escolha as unidades nas listas. A coluna Valor em uso mostra exatamente o que está entrando na conta.
B16: PASSO 4 | C16: Confira o resultado automático destacado em verde. O card verde mostra o resultado principal, outras unidades, uma interpretação e o status dos dados. Se faltar algo, aparece uma mensagem em vermelho dizendo o que corrigir.
B17: PASSO 5 | C17: Leia a explicação e verifique as unidades utilizadas. Em Entenda o cálculo você vê a fórmula, os valores usados e a conta montada. Confira se as unidades fazem sentido para o seu exercício.
B19: 4 QUAIS CÁLCULOS ESTÃO DISPONÍVEIS
B20: Calculadora (clique para abrir) | C20: Onde fica | D20: O que ela resolve
B21: 💧 01 · Vazão e Hidráulica | C21: Aba 02 — Vazão e Hidráulica | D21: Vazão a partir de volume e tempo; Vazão em tubulações; Velocidade do escoamento; Tempo de detenção hidráulica (TDH)
B22: 🏭 02 · Carga Poluidora | C22: Aba 03 — Carga Poluidora | D22: Calcular carga poluidora; Descobrir a concentração; Descobrir a vazão
B23: 📉 03 · Eficiência | C23: Aba 04 — Eficiência de Tratamento | D23: Eficiência por concentração; Eficiência por carga
B24: ⚖️ 04 · Balanço de Massa | C24: Aba 05 — Balanço de Massa | D24: Mistura de duas correntes; Balanço de massa em decantadores; Acúmulo de massa
B25: 🧪 05 · Diluição | C25: Aba 06 — Diluição de Soluções | D25: Volume de estoque, concentração final, volume final ou concentração do estoque
B26: ⚗️ 06 · Dosagem Química | C26: Aba 07 — Dosagem Química | D26: Massa de ativo; massa de produto comercial; volume de produto líquido
B28: 5 COMO ESCOLHER A CALCULADORA CERTA
B29: Preciso calcular | C29: Qual calculadora utilizar | D29: Exemplo de aplicação
B30: Descobrir a vazão de uma tubulação | C30: 02 · Vazão e Hidráulica (Ferramenta 2) | D30: Tubo de 0,30 m com água a 1,5 m/s.
B31: Descobrir a vazão a partir de volume e tempo | C31: 02 · Vazão e Hidráulica (Ferramenta 1) | D31: Tanque de 360 m³ que enche em 2 horas.
B32: Verificar a velocidade da água em um tubo | C32: 02 · Vazão e Hidráulica (Ferramenta 3) | D32: 0,05 m³/s passando em tubo de 0,20 m.
B33: Calcular o tempo de detenção de um tanque | C33: 02 · Vazão e Hidráulica (Ferramenta 4) | D33: Tanque de 500 m³ recebendo 50 m³/h.
B34: Calcular a carga de DBO de um efluente | C34: 03 · Carga Poluidora (Ferramenta 1) | D34: 400 m³/dia com 180 mg/L de DBO.
B35: Descobrir a concentração a partir da carga | C35: 03 · Carga Poluidora (Ferramenta 2) | D35: 24 kg/dia de DBO em 400 m³/dia.
B36: Avaliar a eficiência de uma ETE | C36: 04 · Eficiência de Tratamento | D36: DBO de 250 mg/L na entrada e 50 mg/L na saída.
B37: Calcular a concentração após misturar dois efluentes | C37: 05 · Balanço de Massa (Ferramenta 1) | D37: 120 m³/dia a 200 mg/L + 80 m³/dia a 50 mg/L.
B38: Calcular a concentração do lodo de um decantador | C38: 05 · Balanço de Massa (Ferramenta 2) | D38: Entrada, clarificado e lodo de um decantador primário.
B39: Saber se a massa está acumulando em um sistema | C39: 05 · Balanço de Massa (Ferramenta 3) | D39: Tanque que recebe mais sólidos do que descarta.
B40: Preparar uma solução diluída | C40: 06 · Diluição de Soluções | D40: 500 mL a 200 mg/L a partir de um padrão de 1.000 mg/L.
B41: Calcular a quantidade diária de um produto químico | C41: 07 · Dosagem Química | D41: 4 mg/L de ativo em 500 m³/dia com produto a 50%.
B43: 6 COMO INFORMAR OS DADOS
B44: • Digite somente nos campos amarelos da coluna MEU CÁLCULO. As outras células estão protegidas para evitar que uma fórmula seja apagada sem querer.
B45: • Use vírgula para decimais (0,5), como no padrão brasileiro. Não digite a unidade junto do número: escreva 500, e não 500 m³.
B46: • Ao clicar em um campo amarelo aparece uma dica com o que deve ser digitado.
B47: • Se você digitar algo inválido (texto ou número negativo), a planilha avisa e não aceita.
...

Sheet 02 — Vazão e Hidráulica
B1: 💧 CALCULADORA 01 · VAZÃO E HIDRÁULICA | K1: ÁREA TÉCNICA · cálculos auxiliares (não editar)
B2: KIT DE 6 CALCULADORAS AUTOMÁTICAS DE ENGENHARIA AMBIENTAL | K2: Descrição | L2: Valor
B3: 🏠 Painel | C3: 📘 Guia | E3: 📚 Exemplos | G3: ◀ Anterior | H3: Próxima aba ▶ | K3: ferramenta escolhida (número) | L3: =IFERROR(MATCH($C$18,{"Ferramenta 1: Vazão por volume e tempo","Ferramenta 2: Vazão em tubulações","Ferramenta 3: Velocidade do escoamento","Ferramenta 4: Tempo de detenção (TDH)"},0),0) -> 1
K4: índice do cenário (1, 2 ou 3) | L4: =IFERROR(MATCH($C$26,{"Exemplo 01","Exemplo 02","Meu cálculo"},0),0) -> 1
B5: COMO USAR: ① Escolha a ferramenta abaixo ② Escolha o cenário na lista amarela ③ Para usar seus dados, escolha Meu cálculo e digite na coluna amarela ④ Veja o resultado no card verde ⑤ Confira a conta em ENTENDA O CÁLCULO | K5: [Vazão por volume e tempo] fV | L5: =IFERROR(CHOOSE(MATCH($G$31,{"m³","L"},0),1,0.001),"") -> 1
K6: [Vazão por volume e tempo] ft | L6: =IFERROR(CHOOSE(MATCH($G$33,{"s","min","h","dia"},0),1,60,3600,86400),"") -> 3600
B7: A · IDENTIFICAÇÃO | K7: [Vazão por volume e tempo] Vm | L7: =IFERROR($G$30*$L$5,"") -> 360
B8: O que calcula | C8: Vazão (volume por tempo), área da seção de tubos, velocidade do escoamento e tempo de detenção hidráulica (TDH). | K8: [Vazão por volume e tempo] ts | L8: =IFERROR($G$32*$L$6,"") -> 7200
B9: Quando usar | C9: Conferência de tubulações, bombas, tanques, reservatórios, lagoas e unidades de tratamento. Útil em Hidráulica, Saneamento e Tratamento de Água e Esgoto. | K9: [Vazão por volume e tempo] Qs | L9: =IFERROR($L$7/$L$8,"") -> 0.05
B10: Exemplo prático | C10: Descobrir a vazão de uma bomba que enche um tanque de 360 m³ em 2 horas, ou quanto tempo o esgoto fica em um tanque de equalização. | K10: [Vazão por volume e tempo] Qh | L10: =IFERROR($L$9*3600,"") -> 180
K11: [Vazão por volume e tempo] Ql | L11: =IFERROR($L$9*1000,"") -> 50
B12: FERRAMENTAS DESTA CALCULADORA | K12: [Vazão por volume e tempo] Qd | L12: =IFERROR($L$9*86400,"") -> 4320
B13: ▶ Ferramenta 1 | C13: Vazão a partir de volume e tempo: Calcula a vazão quando você sabe quanto volume passou e em quanto tempo. O resultado sai automaticamente em m³/s, m³/h, L/s e m³/dia. | K13: [Vazão por volume e tempo] mensagem de validação | L13: =IFERROR(IF($L$4=0,"Escolha um cenário na lista: Exemplo 01, Exemplo 02 ou Meu cálculo.",IF($G$30="","Informe o volume para continuar.",IF(NOT(ISNUMBER($G$30)),"O volume precisa ser um número. Confira o valor digitado.",IF($G$30<=0,"O volume deve ser maior que zero.",IF($L$5="","Confira a unidade selecionada para o volume.",IF($G$32="","Informe o tempo para continuar.",IF(NOT(ISNUMBER($G$32)),"O tempo precisa ser um número. Confira o valor digitado.",IF($G$32<=0,"O tempo deve ser maior que zero.",IF($L$6="","Confira a unidade selecionada para o tempo.",""))))))))),"Resultado indisponível: existem dados inválidos.")
B14: ▶ Ferramenta 2 | C14: Vazão em tubulações: Calcula a área da seção de um tubo circular e a vazão transportada a partir do diâmetro interno e da velocidade média do escoamento. | K14: [Vazão por volume e tempo] dados válidos? | L14: =$L$13="" -> TRUE
B15: ▶ Ferramenta 3 | C15: Velocidade do escoamento: Calcula a velocidade média do líquido dentro de um tubo circular a partir da vazão e do diâmetro interno. | K15: [Vazão por volume e tempo] Qd (arredondado) | L15: =IFERROR(ROUND($L$12,IF($L$12=0,0,4-INT(LOG10(ABS($L$12))))),"") -> 4320
B16: ▶ Ferramenta 4 | C16: Tempo de detenção hidráulica (TDH): Calcula quanto tempo, em média, o líquido permanece dentro de um tanque, reator ou lagoa. | K16: [Vazão por volume e tempo] Qd (texto) | L16: =IF(ISNUMBER($L$15),FIXED($L$15,IF(ROUND($L$15,0)=$L$15,0,IF(ROUND($L$15,1)=$L$15,1,IF(ROUND($L$15,2)=$L$15,2,IF(ROUND($L$15,3)=$L$15,3,IF(ROUND($L$15,4)=$L$15,4,IF(ROUND($L$15,5)=$L$15,5,IF(ROUND($L$15,6)=$L$15,6,7)))))))),"?") -> 4.320
K17: [Vazão por volume e tempo] Qh (arredondado) | L17: =IFERROR(ROUND($L$10,IF($L$10=0,0,4-INT(LOG10(ABS($L$10))))),"") -> 180
B18: Ferramenta escolhida ▼ | C18: Ferramenta 1: Vazão por volume e tempo | F18: A ferramenta escolhida fica com o título em verde. Use os botões azuis acima para ir até ela. | K18: [Vazão por volume e tempo] Qh (texto) | L18: =IF(ISNUMBER($L$17),FIXED($L$17,IF(ROUND($L$17,0)=$L$17,0,IF(ROUND($L$17,1)=$L$17,1,IF(ROUND($L$17,2)=$L$17,2,IF(ROUND($L$17,3)=$L$17,3,IF(ROUND($L$17,4)=$L$17,4,IF(ROUND($L$17,5)=$L$17,5,IF(ROUND($L$17,6)=$L$17,6,7)))))))),"?") -> 180
B19: Resultado atual | C19: =IFERROR(CHOOSE($L$3,$L$31,$L$55,$L$77,$L$100),"—") -> 180 m³/h | K19: [Vazão por volume e tempo] Ql (arredondado) | L19: =IFERROR(ROUND($L$11,IF($L$11=0,0,4-INT(LOG10(ABS($L$11))))),"") -> 50
B20: Status | C20: =IFERROR(CHOOSE($L$3,C42,C77,C113,C149),"Escolha uma ferramenta.") -> ✔ Dados válidos. Resultado calculado automaticamente. | K20: [Vazão por volume e tempo] Ql (texto) | L20: =IF(ISNUMBER($L$19),FIXED($L$19,IF(ROUND($L$19,0)=$L$19,0,IF(ROUND($L$19,1)=$L$19,1,IF(ROUND($L$19,2)=$L$19,2,IF(ROUND($L$19,3)=$L$19,3,IF(ROUND($L$19,4)=$L$19,4,IF(ROUND($L$19,5)=$L$19,5,IF(ROUND($L$19,6)=$L$19,6,7)))))))),"?") -> 50
K21: [Vazão por volume e tempo] V (arredondado) | L21: =IFERROR(ROUND($G$30,IF($G$30=0,0,4-INT(LOG10(ABS($G$30))))),"") -> 360
B22: FERRAMENTA 1 · VAZÃO A PARTIR DE VOLUME E TEMPO | H22: ▲ Voltar ao topo | K22: [Vazão por volume e tempo] V (texto) | L22: =IF(ISNUMBER($L$21),FIXED($L$21,IF(ROUND($L$21,0)=$L$21,0,IF(ROUND($L$21,1)=$L$21,1,IF(ROUND($L$21,2)=$L$21,2,IF(ROUND($L$21,3)=$L$21,3,IF(ROUND($L$21,4)=$L$21,4,IF(ROUND($L$21,5)=$L$21,5,IF(ROUND($L$21,6)=$L$21,6,7)))))))),"?") -> 360
B23: Calcula a vazão quando você sabe quanto volume passou e em quanto tempo. O resultado sai automaticamente em m³/s, m³/h, L/s e m³/dia. | K23: [Vazão por volume e tempo] t (arredondado) | L23: =IFERROR(ROUND($G$32,IF($G$32=0,0,4-INT(LOG10(ABS($G$32))))),"") -> 2
K24: [Vazão por volume e tempo] t (texto) | L24: =IF(ISNUMBER($L$23),FIXED($L$23,IF(ROUND($L$23,0)=$L$23,0,IF(ROUND($L$23,1)=$L$23,1,IF(ROUND($L$23,2)=$L$23,2,IF(ROUND($L$23,3)=$L$23,3,IF(ROUND($L$23,4)=$L$23,4,IF(ROUND($L$23,5)=$L$23,5,IF(ROUND($L$23,6)=$L$23,6,7)))))))),"?") -> 2
B25: B · ESCOLHA DO CENÁRIO | K25: [Vazão por volume e tempo] Qs (arredondado) | L25: =IFERROR(ROUND($L$9,IF($L$9=0,0,4-INT(LOG10(ABS($L$9))))),"") -> 0.05
B26: Cenário ▼ | C26: Exemplo 01 | E26: Exemplo 01 e Exemplo 02 usam dados prontos. Meu cálculo usa os valores que você digitar na coluna amarela. | K26: [Vazão por volume e tempo] Qs (texto) | L26: =IF(ISNUMBER($L$25),FIXED($L$25,IF(ROUND($L$25,0)=$L$25,0,IF(ROUND($L$25,1)=$L$25,1,IF(ROUND($L$25,2)=$L$25,2,IF(ROUND($L$25,3)=$L$25,3,IF(ROUND($L$25,4)=$L$25,4,IF(ROUND($L$25,5)=$L$25,5,IF(ROUND($L$25,6)=$L$25,6,7)))))))),"?") -> 0,05
K27: [Vazão por volume e tempo] Vm (arredondado) | L27: =IFERROR(ROUND($L$7,IF($L$7=0,0,4-INT(LOG10(ABS($L$7))))),"") -> 360
B28: C · DADOS DE ENTRADA | K28: [Vazão por volume e tempo] Vm (texto) | L28: =IF(ISNUMBER($L$27),FIXED($L$27,IF(ROUND($L$27,0)=$L$27,0,IF(ROUND($L$27,1)=$L$27,1,IF(ROUND($L$27,2)=$L$27,2,IF(ROUND($L$27,3)=$L$27,3,IF(ROUND($L$27,4)=$L$27,4,IF(ROUND($L$27,5)=$L$27,5,IF(ROUND($L$27,6)=$L$27,6,7)))))))),"?") -> 360
B29: Variável | C29: Exemplo 01 | D29: Exemplo 02 | E29: MEU CÁLCULO | F29: Unidade | G29: Valor em uso | H29: Orientação de preenchimento | K29: [Vazão por volume e tempo] ts (arredondado) | L29: =IFERROR(ROUND($L$8,IF($L$8=0,0,4-INT(LOG10(ABS($L$8))))),"") -> 7200
B30: Volume | C30: 360 | D30: 15000 | F30: =$G$31 -> m³ | G30: =IF($L$4=1,C30,IF($L$4=2,D30,IF($L$4=3,IF(E30="","",E30),""))) -> 360 | H30: Volume que passou, encheu ou esvaziou. Ex.: 360 | K30: [Vazão por volume e tempo] ts (texto) | L30: =IF(ISNUMBER($L$29),FIXED($L$29,IF(ROUND($L$29,0)=$L$29,0,IF(ROUND($L$29,1)=$L$29,1,IF(ROUND($L$29,2)=$L$29,2,IF(ROUND($L$29,3)=$L$29,3,IF(ROUND($L$29,4)=$L$29,4,IF(ROUND($L$29,5)=$L$29,5,IF(ROUND($L$29,6)=$L$29,6,7)))))))),"?") -> 7.200
B31: Unidade do volume | C31: m³ | D31: L | E31: m³ | F31: lista ▼ | G31: =IF($L$4=1,C31,IF($L$4=2,D31,IF($L$4=3,IF(E31="","",E31),""))) -> m³ | H31: Escolha m³ ou L na lista. | K31: [Vazão por volume e tempo] resumo | L31: =IF($L$14,$L$18&" "&"m³/h","—") -> 180 m³/h
B32: Tempo | C32: 2 | D32: 25 | F32: =$G$33 -> h | G32: =IF($L$4=1,C32,IF($L$4=2,D32,IF($L$4=3,IF(E32="","",E32),""))) -> 2 | H32: Tempo gasto para esse volume passar. Ex.: 2 | K32: índice do cenário (1, 2 ou 3) | L32: =IFERROR(MATCH($C$62,{"Exemplo 01","Exemplo 02","Meu cálculo"},0),0) -> 1
B33: Unidade do tempo | C33: h | D33: min | E33: h | F33: lista ▼ | G33: =IF($L$4=1,C33,IF($L$4=2,D33,IF($L$4=3,IF(E33="","",E33),""))) -> h | H33: Escolha s, min, h ou dia. | K33: [Vazão em tubulações] fD | L33: =IFERROR(CHOOSE(MATCH($G$67,{"m","cm","mm","pol"},0),1,0.01,0.001,0.0254),"") -> 1
K34: [Vazão em tubulações] Dm | L34: =IFERROR($G$66*$L$33,"") -> 0.3
B35: D · RESULTADO AUTOMÁTICO | K35: [Vazão em tubulações] A | L35: =IFERROR(PI()*$L$34^2/4,"") -> 0.070685835
B36: VAZÃO EM m³/h | E36: OUTROS RESULTADOS | K36: [Vazão em tubulações] Q | L36: =IFERROR($L$35*$G$68,"") -> 0.10602875
B37: =IF($L$14,$L$10,"—") -> 180 | D37: m³/h | E37: Vazão em m³/s | G37: =IF($L$14,$L$9,"—") -> 0.05 | H37: m³/s | K37: [Vazão em tubulações] Ql | L37: =IFERROR($L$36*1000,"") -> 106.02875
E38: Vazão em L/s | G38: =IF($L$14,$L$11,"—") -> 50 | H38: L/s | K38: [Vazão em tubulações] Qh | L38: =IFERROR($L$36*3600,"") -> 381.70351
E39: Vazão em m³/dia | G39: =IF($L$14,$L$12,"—") -> 4320 | H39: m³/dia | K39: [Vazão em tubulações] mensagem de validação | L39: =IFERROR(IF($L$32=0,"Escolha um cenário na lista: Exemplo 01, Exemplo 02 ou Meu cálculo.",IF($G$66="","Informe o diâmetro para continuar.",IF(NOT(ISNUMBER($G$66)),"O diâmetro precisa ser um número. Confira o valor digitado.",IF($G$66<=0,"O diâmetro deve ser maior que zero.",IF($L$33="","Confira a unidade selecionada para o diâmetro.",IF($G$68="","Informe a velocidade para continuar.",IF(NOT(ISNUMBER($G$68)),"A velocidade precisa ser um número. Confira o valor digitado.",IF($G$68<=0,"A velocidade deve ser maior que zero.","")))))))),"Resultado indisponível: existem dados inválidos.")
K40: [Vazão em tubulações] dados válidos? | L40: =$L$39="" -> TRUE
...

Sheet 03 — Carga Poluidora
B1: 🏭 CALCULADORA 02 · CARGA POLUIDORA | K1: ÁREA TÉCNICA · cálculos auxiliares (não editar)
B2: KIT DE 6 CALCULADORAS AUTOMÁTICAS DE ENGENHARIA AMBIENTAL | K2: Descrição | L2: Valor
B3: 🏠 Painel | C3: 📘 Guia | E3: 📚 Exemplos | G3: ◀ Anterior | H3: Próxima aba ▶ | K3: ferramenta escolhida (número) | L3: =IFERROR(MATCH($C$17,{"Ferramenta 1: Calcular carga","Ferramenta 2: Descobrir concentração","Ferramenta 3: Descobrir vazão"},0),0) -> 1
K4: índice do cenário (1, 2 ou 3) | L4: =IFERROR(MATCH($C$25,{"Exemplo 01","Exemplo 02","Meu cálculo"},0),0) -> 1
B5: COMO USAR: ① Escolha a ferramenta abaixo ② Escolha o cenário na lista amarela ③ Para usar seus dados, escolha Meu cálculo e digite na coluna amarela ④ Veja o resultado no card verde ⑤ Confira a conta em ENTENDA O CÁLCULO | K5: [Calcular carga] fQ | L5: =IFERROR(CHOOSE(MATCH($G$31,{"m³/dia","m³/h","L/s"},0),1,24,86.4),"") -> 1
K6: [Calcular carga] Qd | L6: =IFERROR($G$30*$L$5,"") -> 400
B7: A · IDENTIFICAÇÃO | K7: [Calcular carga] kg | L7: =IFERROR($L$6*$G$32*0.001,"") -> 72
B8: O que calcula | C8: A massa de poluente que uma corrente leva por dia (carga), a partir da vazão e da concentração. Também faz o caminho inverso. | K8: [Calcular carga] g | L8: =IFERROR($L$7*1000,"") -> 72000
B9: Quando usar | C9: Caracterização de efluentes, estudos de impacto em rios, comparação entre fontes, equivalente populacional e relatórios de monitoramento. | K9: [Calcular carga] ano | L9: =IFERROR($L$7*365,"") -> 26280
B10: Exemplo prático | C10: Um efluente de 400 m³/dia com DBO de 180 mg/L lança 72 kg de DBO por dia. | K10: [Calcular carga] hab | L10: =IFERROR(ROUND($L$7*1000/54,0),"") -> 1333
K11: [Calcular carga] mensagem de validação | L11: =IFERROR(IF($L$4=0,"Escolha um cenário na lista: Exemplo 01, Exemplo 02 ou Meu cálculo.",IF($L$5="","Confira a unidade selecionada para a vazão.",IF($G$30="","Informe a vazão para continuar.",IF(NOT(ISNUMBER($G$30)),"A vazão precisa ser um número. Confira o valor digitado.",IF($G$30<=0,"A vazão deve ser maior que zero.",IF($G$32="","Informe a concentração para continuar (digite 0 se for o caso).",IF(NOT(ISNUMBER($G$32)),"A concentração precisa ser um número. Confira o valor digitado.",IF($G$32<0,"A concentração não pode ser negativa.","")))))))),"Resultado indisponível: existem dados inválidos.")
B12: FERRAMENTAS DESTA CALCULADORA | K12: [Calcular carga] dados válidos? | L12: =$L$11="" -> TRUE
B13: ▶ Ferramenta 1 | C13: Calcular carga poluidora: Calcula a massa de poluente transportada por dia a partir da vazão e da concentração. O parâmetro escolhido só identifica o cálculo; a fórmula é a mesma para todos. | K13: [Calcular carga] hab (arredondado) | L13: =IFERROR(ROUND($L$10,IF($L$10=0,0,4-INT(LOG10(ABS($L$10))))),"") -> 1333
B14: ▶ Ferramenta 2 | C14: Descobrir a concentração: Calcula a concentração média de um parâmetro quando você conhece a carga diária e a vazão. | K14: [Calcular carga] hab (texto) | L14: =IF(ISNUMBER($L$13),FIXED($L$13,IF(ROUND($L$13,0)=$L$13,0,IF(ROUND($L$13,1)=$L$13,1,IF(ROUND($L$13,2)=$L$13,2,IF(ROUND($L$13,3)=$L$13,3,IF(ROUND($L$13,4)=$L$13,4,IF(ROUND($L$13,5)=$L$13,5,IF(ROUND($L$13,6)=$L$13,6,7)))))))),"?") -> 1.333
B15: ▶ Ferramenta 3 | C15: Descobrir a vazão: Calcula a vazão que transporta uma carga conhecida com uma concentração conhecida. | K15: [Calcular carga] kg (arredondado) | L15: =IFERROR(ROUND($L$7,IF($L$7=0,0,4-INT(LOG10(ABS($L$7))))),"") -> 72
K16: [Calcular carga] kg (texto) | L16: =IF(ISNUMBER($L$15),FIXED($L$15,IF(ROUND($L$15,0)=$L$15,0,IF(ROUND($L$15,1)=$L$15,1,IF(ROUND($L$15,2)=$L$15,2,IF(ROUND($L$15,3)=$L$15,3,IF(ROUND($L$15,4)=$L$15,4,IF(ROUND($L$15,5)=$L$15,5,IF(ROUND($L$15,6)=$L$15,6,7)))))))),"?") -> 72
B17: Ferramenta escolhida ▼ | C17: Ferramenta 1: Calcular carga | F17: A ferramenta escolhida fica com o título em verde. Use os botões azuis acima para ir até ela. | K17: [Calcular carga] C (arredondado) | L17: =IFERROR(ROUND($G$32,IF($G$32=0,0,4-INT(LOG10(ABS($G$32))))),"") -> 180
B18: Resultado atual | C18: =IFERROR(CHOOSE($L$3,$L$25,$L$42,$L$60),"—") -> 72 kg/dia | K18: [Calcular carga] C (texto) | L18: =IF(ISNUMBER($L$17),FIXED($L$17,IF(ROUND($L$17,0)=$L$17,0,IF(ROUND($L$17,1)=$L$17,1,IF(ROUND($L$17,2)=$L$17,2,IF(ROUND($L$17,3)=$L$17,3,IF(ROUND($L$17,4)=$L$17,4,IF(ROUND($L$17,5)=$L$17,5,IF(ROUND($L$17,6)=$L$17,6,7)))))))),"?") -> 180
B19: Status | C19: =IFERROR(CHOOSE($L$3,C41,C77,C112),"Escolha uma ferramenta.") -> ✔ Dados válidos. Resultado calculado automaticamente. | K19: [Calcular carga] Q (arredondado) | L19: =IFERROR(ROUND($G$30,IF($G$30=0,0,4-INT(LOG10(ABS($G$30))))),"") -> 400
K20: [Calcular carga] Q (texto) | L20: =IF(ISNUMBER($L$19),FIXED($L$19,IF(ROUND($L$19,0)=$L$19,0,IF(ROUND($L$19,1)=$L$19,1,IF(ROUND($L$19,2)=$L$19,2,IF(ROUND($L$19,3)=$L$19,3,IF(ROUND($L$19,4)=$L$19,4,IF(ROUND($L$19,5)=$L$19,5,IF(ROUND($L$19,6)=$L$19,6,7)))))))),"?") -> 400
B21: FERRAMENTA 1 · CALCULAR CARGA POLUIDORA | H21: ▲ Voltar ao topo | K21: [Calcular carga] Qd (arredondado) | L21: =IFERROR(ROUND($L$6,IF($L$6=0,0,4-INT(LOG10(ABS($L$6))))),"") -> 400
B22: Calcula a massa de poluente transportada por dia a partir da vazão e da concentração. O parâmetro escolhido só identifica o cálculo; a fórmula é a mesma para todos. | K22: [Calcular carga] Qd (texto) | L22: =IF(ISNUMBER($L$21),FIXED($L$21,IF(ROUND($L$21,0)=$L$21,0,IF(ROUND($L$21,1)=$L$21,1,IF(ROUND($L$21,2)=$L$21,2,IF(ROUND($L$21,3)=$L$21,3,IF(ROUND($L$21,4)=$L$21,4,IF(ROUND($L$21,5)=$L$21,5,IF(ROUND($L$21,6)=$L$21,6,7)))))))),"?") -> 400
K23: [Calcular carga] g (arredondado) | L23: =IFERROR(ROUND($L$8,IF($L$8=0,0,4-INT(LOG10(ABS($L$8))))),"") -> 72000
B24: B · ESCOLHA DO CENÁRIO | K24: [Calcular carga] g (texto) | L24: =IF(ISNUMBER($L$23),FIXED($L$23,IF(ROUND($L$23,0)=$L$23,0,IF(ROUND($L$23,1)=$L$23,1,IF(ROUND($L$23,2)=$L$23,2,IF(ROUND($L$23,3)=$L$23,3,IF(ROUND($L$23,4)=$L$23,4,IF(ROUND($L$23,5)=$L$23,5,IF(ROUND($L$23,6)=$L$23,6,7)))))))),"?") -> 72.000
B25: Cenário ▼ | C25: Exemplo 01 | E25: Exemplo 01 e Exemplo 02 usam dados prontos. Meu cálculo usa os valores que você digitar na coluna amarela. | K25: [Calcular carga] resumo | L25: =IF($L$12,$L$16&" "&"kg/dia","—") -> 72 kg/dia
K26: índice do cenário (1, 2 ou 3) | L26: =IFERROR(MATCH($C$61,{"Exemplo 01","Exemplo 02","Meu cálculo"},0),0) -> 1
B27: C · DADOS DE ENTRADA | K27: [Descobrir concentração] fQ | L27: =IFERROR(CHOOSE(MATCH($G$68,{"m³/dia","m³/h","L/s"},0),1,24,86.4),"") -> 1
B28: Variável | C28: Exemplo 01 | D28: Exemplo 02 | E28: MEU CÁLCULO | F28: Unidade | G28: Valor em uso | H28: Orientação de preenchimento | K28: [Descobrir concentração] Qd | L28: =IFERROR($G$67*$L$27,"") -> 400
B29: Parâmetro | C29: DBO | D29: SST | E29: DBO | F29: lista ▼ | G29: =IF($L$4=1,C29,IF($L$4=2,D29,IF($L$4=3,IF(E29="","",E29),""))) -> DBO | H29: Escolha o parâmetro (serve para identificar o resultado). | K29: [Descobrir concentração] Lg | L29: =IFERROR($G$66*1000,"") -> 24000
B30: Vazão | C30: 400 | D30: 5 | F30: =$G$31 -> m³/dia | G30: =IF($L$4=1,C30,IF($L$4=2,D30,IF($L$4=3,IF(E30="","",E30),""))) -> 400 | H30: Vazão da corrente. Ex.: 400 | K30: [Descobrir concentração] C | L30: =IFERROR($L$29/$L$28,"") -> 60
B31: Unidade da vazão | C31: m³/dia | D31: L/s | E31: m³/dia | F31: lista ▼ | G31: =IF($L$4=1,C31,IF($L$4=2,D31,IF($L$4=3,IF(E31="","",E31),""))) -> m³/dia | H31: Escolha m³/dia, m³/h ou L/s. | K31: [Descobrir concentração] kgm3 | L31: =IFERROR($L$30/1000,"") -> 0.06
B32: Concentração | C32: 180 | D32: 250 | F32: mg/L | G32: =IF($L$4=1,C32,IF($L$4=2,D32,IF($L$4=3,IF(E32="","",E32),""))) -> 180 | H32: Concentração do parâmetro em mg/L. Ex.: 180 | K32: [Descobrir concentração] mensagem de validação | L32: =IFERROR(IF($L$26=0,"Escolha um cenário na lista: Exemplo 01, Exemplo 02 ou Meu cálculo.",IF($G$66="","Informe a carga para continuar (digite 0 se for o caso).",IF(NOT(ISNUMBER($G$66)),"A carga precisa ser um número. Confira o valor digitado.",IF($G$66<0,"A carga não pode ser negativa.",IF($L$27="","Confira a unidade selecionada para a vazão.",IF($G$67="","Informe a vazão para continuar.",IF(NOT(ISNUMBER($G$67)),"A vazão precisa ser um número. Confira o valor digitado.",IF($G$67<=0,"A vazão deve ser maior que zero.","")))))))),"Resultado indisponível: existem dados inválidos.")
K33: [Descobrir concentração] dados válidos? | L33: =$L$32="" -> TRUE
B34: D · RESULTADO AUTOMÁTICO | K34: [Descobrir concentração] C (arredondado) | L34: =IFERROR(ROUND($L$30,IF($L$30=0,0,4-INT(LOG10(ABS($L$30))))),"") -> 60
B35: ="CARGA DE "&UPPER($G$29) -> CARGA DE DBO | E35: OUTROS RESULTADOS | K35: [Descobrir concentração] C (texto) | L35: =IF(ISNUMBER($L$34),FIXED($L$34,IF(ROUND($L$34,0)=$L$34,0,IF(ROUND($L$34,1)=$L$34,1,IF(ROUND($L$34,2)=$L$34,2,IF(ROUND($L$34,3)=$L$34,3,IF(ROUND($L$34,4)=$L$34,4,IF(ROUND($L$34,5)=$L$34,5,IF(ROUND($L$34,6)=$L$34,6,7)))))))),"?") -> 60
B36: =IF($L$12,$L$7,"—") -> 72 | D36: kg/dia | E36: Carga em g/dia | G36: =IF($L$12,$L$8,"—") -> 72000 | H36: g/dia | K36: [Descobrir concentração] L (arredondado) | L36: =IFERROR(ROUND($G$66,IF($G$66=0,0,4-INT(LOG10(ABS($G$66))))),"") -> 24
E37: Carga anual (365 dias) | G37: =IF($L$12,$L$9,"—") -> 26280 | H37: kg/ano | K37: [Descobrir concentração] L (texto) | L37: =IF(ISNUMBER($L$36),FIXED($L$36,IF(ROUND($L$36,0)=$L$36,0,IF(ROUND($L$36,1)=$L$36,1,IF(ROUND($L$36,2)=$L$36,2,IF(ROUND($L$36,3)=$L$36,3,IF(ROUND($L$36,4)=$L$36,4,IF(ROUND($L$36,5)=$L$36,5,IF(ROUND($L$36,6)=$L$36,6,7)))))))),"?") -> 24
E38: Vazão usada | G38: =IF($L$12,$L$6,"—") -> 400 | H38: m³/dia | K38: [Descobrir concentração] Q (arredondado) | L38: =IFERROR(ROUND($G$67,IF($G$67=0,0,4-INT(LOG10(ABS($G$67))))),"") -> 400
K39: [Descobrir concentração] Q (texto) | L39: =IF(ISNUMBER($L$38),FIXED($L$38,IF(ROUND($L$38,0)=$L$38,0,IF(ROUND($L$38,1)=$L$38,1,IF(ROUND($L$38,2)=$L$38,2,IF(ROUND($L$38,3)=$L$38,3,IF(ROUND($L$38,4)=$L$38,4,IF(ROUND($L$38,5)=$L$38,5,IF(ROUND($L$38,6)=$L$38,6,7)))))))),"?") -> 400
B40: Interpretação | C40: =IF($L$12,"Por dia, a corrente transporta "&$L$16&" kg de "&$G$29&". Essa é a massa que chega ao destino em 24 horas."&IF($G$29="DBO"," Isso equivale ao esgoto de aproximadamente "&$L$14&" pessoas (referência usual de 54 g de DBO por habitante por dia).",""),"Resultado indisponível: corrija o item indicado em Status dos dados.") -> Por dia, a corrente transporta 72 kg de DBO. Essa é a massa que chega ao destino em 24 horas. Isso equivale ao esgoto de aproximadamente 1.333 pessoas (referência usual de 54 g de DBO por habitante por dia). | K40: [Descobrir concentração] Qd (arredondado) | L40: =IFERROR(ROUND($L$28,IF($L$28=0,0,4-INT(LOG10(ABS($L$28))))),"") -> 400
...

Sheet 04 — Eficiência de Tratamento
B1: 📉 CALCULADORA 03 · EFICIÊNCIA DE TRATAMENTO | K1: ÁREA TÉCNICA · cálculos auxiliares (não editar)
B2: KIT DE 6 CALCULADORAS AUTOMÁTICAS DE ENGENHARIA AMBIENTAL | K2: Descrição | L2: Valor
B3: 🏠 Painel | C3: 📘 Guia | E3: 📚 Exemplos | G3: ◀ Anterior | H3: Próxima aba ▶ | K3: ferramenta escolhida (número) | L3: =IFERROR(MATCH($C$16,{"Ferramenta 1: Eficiência por concentração","Ferramenta 2: Eficiência por carga"},0),0) -> 1
K4: índice do cenário (1, 2 ou 3) | L4: =IFERROR(MATCH($C$24,{"Exemplo 01","Exemplo 02","Meu cálculo"},0),0) -> 1
B5: COMO USAR: ① Escolha a ferramenta abaixo ② Escolha o cenário na lista amarela ③ Para usar seus dados, escolha Meu cálculo e digite na coluna amarela ④ Veja o resultado no card verde ⑤ Confira a conta em ENTENDA O CÁLCULO | K5: [Eficiência por concentração] dif | L5: =IFERROR($G$29-$G$30,"") -> 200
K6: [Eficiência por concentração] E | L6: =IFERROR($L$5/$G$29*100,"") -> 80
B7: A · IDENTIFICAÇÃO | K7: [Eficiência por concentração] Efr | L7: =IFERROR($L$5/$G$29,"") -> 0.8
B8: O que calcula | C8: Quanto do poluente foi removido em um sistema de tratamento, em porcentagem, usando concentrações ou cargas. | K8: [Eficiência por concentração] negE | L8: =IFERROR(-$L$6,"") -> -80
B9: Quando usar | C9: Avaliação de ETEs, reatores, decantadores, filtros e lagoas; relatórios de monitoramento e aulas práticas. | K9: [Eficiência por concentração] rem | L9: =IFERROR($G$30/$G$29*100,"") -> 20
B10: Exemplo prático | C10: DBO de 250 mg/L na entrada e 50 mg/L na saída: eficiência de 80%. | K10: [Eficiência por concentração] mensagem de validação | L10: =IFERROR(IF($L$4=0,"Escolha um cenário na lista: Exemplo 01, Exemplo 02 ou Meu cálculo.",IF($G$29="","Informe a concentração de entrada para continuar.",IF(NOT(ISNUMBER($G$29)),"A concentração de entrada precisa ser um número. Confira o valor digitado.",IF($G$29<=0,"A concentração de entrada deve ser maior que zero.",IF($G$30="","Informe a concentração de saída para continuar (digite 0 se for o caso).",IF(NOT(ISNUMBER($G$30)),"A concentração de saída precisa ser um número. Confira o valor digitado.",IF($G$30<0,"A concentração de saída não pode ser negativa.",""))))))),"Resultado indisponível: existem dados inválidos.")
K11: [Eficiência por concentração] dados válidos? | L11: =$L$10="" -> TRUE
B12: FERRAMENTAS DESTA CALCULADORA | K12: [Eficiência por concentração] E (arredondado) | L12: =IFERROR(ROUND($L$6,IF($L$6=0,0,4-INT(LOG10(ABS($L$6))))),"") -> 80
B13: ▶ Ferramenta 1 | C13: Eficiência por concentração: Calcula a porcentagem de redução entre a concentração de entrada e a de saída de um sistema de tratamento. | K13: [Eficiência por concentração] E (texto) | L13: =IF(ISNUMBER($L$12),FIXED($L$12,IF(ROUND($L$12,0)=$L$12,0,IF(ROUND($L$12,1)=$L$12,1,IF(ROUND($L$12,2)=$L$12,2,IF(ROUND($L$12,3)=$L$12,3,IF(ROUND($L$12,4)=$L$12,4,IF(ROUND($L$12,5)=$L$12,5,IF(ROUND($L$12,6)=$L$12,6,7)))))))),"?") -> 80
B14: ▶ Ferramenta 2 | C14: Eficiência por carga: Calcula a remoção de massa poluidora. Use quando as vazões de entrada e de saída forem diferentes. | K14: [Eficiência por concentração] negE (arredondado) | L14: =IFERROR(ROUND($L$8,IF($L$8=0,0,4-INT(LOG10(ABS($L$8))))),"") -> -80
K15: [Eficiência por concentração] negE (texto) | L15: =IF(ISNUMBER($L$14),FIXED($L$14,IF(ROUND($L$14,0)=$L$14,0,IF(ROUND($L$14,1)=$L$14,1,IF(ROUND($L$14,2)=$L$14,2,IF(ROUND($L$14,3)=$L$14,3,IF(ROUND($L$14,4)=$L$14,4,IF(ROUND($L$14,5)=$L$14,5,IF(ROUND($L$14,6)=$L$14,6,7)))))))),"?") -> -80
B16: Ferramenta escolhida ▼ | C16: Ferramenta 1: Eficiência por concentração | F16: A ferramenta escolhida fica com o título em verde. Use os botões azuis acima para ir até ela. | K16: [Eficiência por concentração] Ce (arredondado) | L16: =IFERROR(ROUND($G$29,IF($G$29=0,0,4-INT(LOG10(ABS($G$29))))),"") -> 250
B17: Resultado atual | C17: =IFERROR(CHOOSE($L$3,$L$22,$L$50),"—") -> 80 % | K17: [Eficiência por concentração] Ce (texto) | L17: =IF(ISNUMBER($L$16),FIXED($L$16,IF(ROUND($L$16,0)=$L$16,0,IF(ROUND($L$16,1)=$L$16,1,IF(ROUND($L$16,2)=$L$16,2,IF(ROUND($L$16,3)=$L$16,3,IF(ROUND($L$16,4)=$L$16,4,IF(ROUND($L$16,5)=$L$16,5,IF(ROUND($L$16,6)=$L$16,6,7)))))))),"?") -> 250
B18: Status | C18: =IFERROR(CHOOSE($L$3,C39,C93),"Escolha uma ferramenta.") -> ✔ Dados válidos. Resultado calculado automaticamente. | K18: [Eficiência por concentração] Cs (arredondado) | L18: =IFERROR(ROUND($G$30,IF($G$30=0,0,4-INT(LOG10(ABS($G$30))))),"") -> 50
K19: [Eficiência por concentração] Cs (texto) | L19: =IF(ISNUMBER($L$18),FIXED($L$18,IF(ROUND($L$18,0)=$L$18,0,IF(ROUND($L$18,1)=$L$18,1,IF(ROUND($L$18,2)=$L$18,2,IF(ROUND($L$18,3)=$L$18,3,IF(ROUND($L$18,4)=$L$18,4,IF(ROUND($L$18,5)=$L$18,5,IF(ROUND($L$18,6)=$L$18,6,7)))))))),"?") -> 50
B20: FERRAMENTA 1 · EFICIÊNCIA POR CONCENTRAÇÃO | H20: ▲ Voltar ao topo | K20: [Eficiência por concentração] dif (arredondado) | L20: =IFERROR(ROUND($L$5,IF($L$5=0,0,4-INT(LOG10(ABS($L$5))))),"") -> 200
B21: Calcula a porcentagem de redução entre a concentração de entrada e a de saída de um sistema de tratamento. | K21: [Eficiência por concentração] dif (texto) | L21: =IF(ISNUMBER($L$20),FIXED($L$20,IF(ROUND($L$20,0)=$L$20,0,IF(ROUND($L$20,1)=$L$20,1,IF(ROUND($L$20,2)=$L$20,2,IF(ROUND($L$20,3)=$L$20,3,IF(ROUND($L$20,4)=$L$20,4,IF(ROUND($L$20,5)=$L$20,5,IF(ROUND($L$20,6)=$L$20,6,7)))))))),"?") -> 200
K22: [Eficiência por concentração] resumo | L22: =IF($L$11,$L$13&" "&"%","—") -> 80 %
B23: B · ESCOLHA DO CENÁRIO | K23: índice do cenário (1, 2 ou 3) | L23: =IFERROR(MATCH($C$76,{"Exemplo 01","Exemplo 02","Meu cálculo"},0),0) -> 1
B24: Cenário ▼ | C24: Exemplo 01 | E24: Exemplo 01 e Exemplo 02 usam dados prontos. Meu cálculo usa os valores que você digitar na coluna amarela. | K24: [Eficiência por carga] Le | L24: =IFERROR($G$81*$G$82*0.001,"") -> 100
K25: [Eficiência por carga] Ls | L25: =IFERROR($G$83*$G$84*0.001,"") -> 20
B26: C · DADOS DE ENTRADA | K26: [Eficiência por carga] Lr | L26: =IFERROR($L$24-$L$25,"") -> 80
B27: Variável | C27: Exemplo 01 | D27: Exemplo 02 | E27: MEU CÁLCULO | F27: Unidade | G27: Valor em uso | H27: Orientação de preenchimento | K27: [Eficiência por carga] E | L27: =IFERROR($L$26/$L$24*100,"") -> 80
B28: Parâmetro | C28: DBO | D28: DQO | E28: DBO | F28: lista ▼ | G28: =IF($L$4=1,C28,IF($L$4=2,D28,IF($L$4=3,IF(E28="","",E28),""))) -> DBO | H28: Escolha o parâmetro avaliado. | K28: [Eficiência por carga] negE | L28: =IFERROR(-$L$27,"") -> -80
B29: Concentração de entrada | C29: 250 | D29: 600 | F29: mg/L | G29: =IF($L$4=1,C29,IF($L$4=2,D29,IF($L$4=3,IF(E29="","",E29),""))) -> 250 | H29: Concentração antes do tratamento. Ex.: 250 | K29: [Eficiência por carga] Ec | L29: =IFERROR(($G$82-$G$84)/$G$82*100,"") -> 75
B30: Concentração de saída | C30: 50 | D30: 180 | F30: mg/L | G30: =IF($L$4=1,C30,IF($L$4=2,D30,IF($L$4=3,IF(E30="","",E30),""))) -> 50 | H30: Concentração depois do tratamento. Ex.: 50 | K30: [Eficiência por carga] mensagem de validação | L30: =IFERROR(IF($L$23=0,"Escolha um cenário na lista: Exemplo 01, Exemplo 02 ou Meu cálculo.",IF($G$81="","Informe a vazão de entrada para continuar.",IF(NOT(ISNUMBER($G$81)),"A vazão de entrada precisa ser um número. Confira o valor digitado.",IF($G$81<=0,"A vazão de entrada deve ser maior que zero.",IF($G$82="","Informe a concentração de entrada para continuar.",IF(NOT(ISNUMBER($G$82)),"A concentração de entrada precisa ser um número. Confira o valor digitado.",IF($G$82<=0,"A concentração de entrada deve ser maior que zero.",IF($G$83="","Informe a vazão de saída para continuar (digite 0 se for o caso).",IF(NOT(ISNUMBER($G$83)),"A vazão de saída precisa ser um número. Confira o valor digitado.",IF($G$83<0,"A vazão de saída não pode ser negativa.",IF($G$84="","Informe a concentração de saída para continuar (digite 0 se for o caso).",IF(NOT(ISNUMBER($G$84)),"A concentração de saída precisa ser um número. Confira o valor digitado.",IF($G$84<0,"A concentração de saída não pode ser negativa.",""))))))))))))),"Resultado indisponível: existem dados inválidos.")
K31: [Eficiência por carga] dados válidos? | L31: =$L$30="" -> TRUE
B32: D · RESULTADO AUTOMÁTICO | K32: [Eficiência por carga] E (arredondado) | L32: =IFERROR(ROUND($L$27,IF($L$27=0,0,4-INT(LOG10(ABS($L$27))))),"") -> 80
B33: EFICIÊNCIA DE REMOÇÃO | E33: OUTROS RESULTADOS | K33: [Eficiência por carga] E (texto) | L33: =IF(ISNUMBER($L$32),FIXED($L$32,IF(ROUND($L$32,0)=$L$32,0,IF(ROUND($L$32,1)=$L$32,1,IF(ROUND($L$32,2)=$L$32,2,IF(ROUND($L$32,3)=$L$32,3,IF(ROUND($L$32,4)=$L$32,4,IF(ROUND($L$32,5)=$L$32,5,IF(ROUND($L$32,6)=$L$32,6,7)))))))),"?") -> 80
B34: =IF($L$11,$L$6,"—") -> 80 | D34: % | E34: Diferença (entrada − saída) | G34: =IF($L$11,$L$5,"—") -> 200 | H34: mg/L | K34: [Eficiência por carga] Ec (arredondado) | L34: =IFERROR(ROUND($L$29,IF($L$29=0,0,4-INT(LOG10(ABS($L$29))))),"") -> 75
E35: Parcela que permanece | G35: =IF($L$11,$L$9,"—") -> 20 | H35: % | K35: [Eficiência por carga] Ec (texto) | L35: =IF(ISNUMBER($L$34),FIXED($L$34,IF(ROUND($L$34,0)=$L$34,0,IF(ROUND($L$34,1)=$L$34,1,IF(ROUND($L$34,2)=$L$34,2,IF(ROUND($L$34,3)=$L$34,3,IF(ROUND($L$34,4)=$L$34,4,IF(ROUND($L$34,5)=$L$34,5,IF(ROUND($L$34,6)=$L$34,6,7)))))))),"?") -> 75
K36: [Eficiência por carga] negE (arredondado) | L36: =IFERROR(ROUND($L$28,IF($L$28=0,0,4-INT(LOG10(ABS($L$28))))),"") -> -80
K37: [Eficiência por carga] negE (texto) | L37: =IF(ISNUMBER($L$36),FIXED($L$36,IF(ROUND($L$36,0)=$L$36,0,IF(ROUND($L$36,1)=$L$36,1,IF(ROUND($L$36,2)=$L$36,2,IF(ROUND($L$36,3)=$L$36,3,IF(ROUND($L$36,4)=$L$36,4,IF(ROUND($L$36,5)=$L$36,5,IF(ROUND($L$36,6)=$L$36,6,7)))))))),"?") -> -80
B38: Interpretação | C38: =IF($L$11,IF($L$6>0,"Houve redução de "&$G$28&": o sistema removeu "&$L$13&"% da concentração de entrada.",IF($L$6=0,"Não houve redução: o valor de saída é igual ao de entrada.","Houve aumento de "&$G$28&": a saída ficou "&$L$15&"% acima da entrada. Confira os dados e o funcionamento do sistema.")),"Resultado indisponível: corrija o item indicado em Status dos dados.") -> Houve redução de DBO: o sistema removeu 80% da concentração de entrada. | K38: [Eficiência por carga] Ce (arredondado) | L38: =IFERROR(ROUND($G$82,IF($G$82=0,0,4-INT(LOG10(ABS($G$82))))),"") -> 200
B39: Status dos dados | C39: =IF($L$11,"✔ Dados válidos. Resultado calculado automaticamente.","⚠ "&$L$10) -> ✔ Dados válidos. Resultado calculado automaticamente. | K39: [Eficiência por carga] Ce (texto) | L39: =IF(ISNUMBER($L$38),FIXED($L$38,IF(ROUND($L$38,0)=$L$38,0,IF(ROUND($L$38,1)=$L$38,1,IF(ROUND($L$38,2)=$L$38,2,IF(ROUND($L$38,3)=$L$38,3,IF(ROUND($L$38,4)=$L$38,4,IF(ROUND($L$38,5)=$L$38,5,IF(ROUND($L$38,6)=$L$38,6,7)))))))),"?") -> 200
K40: [Eficiência por carga] Cs (arredondado) | L40: =IFERROR(ROUND($G$84,IF($G$84=0,0,4-INT(LOG10(ABS($G$84))))),"") -> 50
...

Sheet 05 — Balanço de Massa
B1: ⚖️ CALCULADORA 04 · BALANÇO DE MASSA | K1: ÁREA TÉCNICA · cálculos auxiliares (não editar)
B2: KIT DE 6 CALCULADORAS AUTOMÁTICAS DE ENGENHARIA AMBIENTAL | K2: Descrição | L2: Valor
B3: 🏠 Painel | C3: 📘 Guia | E3: 📚 Exemplos | G3: ◀ Anterior | H3: Próxima aba ▶ | K3: ferramenta escolhida (número) | L3: =IFERROR(MATCH($C$17,{"Ferramenta 1: Mistura de duas correntes","Ferramenta 2: Balanço em decantadores","Ferramenta 3: Acúmulo de massa"},0),0) -> 1
K4: índice do cenário (1, 2 ou 3) | L4: =IFERROR(MATCH($C$25,{"Exemplo 01","Exemplo 02","Meu cálculo"},0),0) -> 1
B5: COMO USAR: ① Escolha a ferramenta abaixo ② Escolha o cenário na lista amarela ③ Para usar seus dados, escolha Meu cálculo e digite na coluna amarela ④ Veja o resultado no card verde ⑤ Confira a conta em ENTENDA O CÁLCULO | K5: [Mistura de duas correntes] Qt | L5: =IFERROR($G$29+$G$31,"") -> 200
K6: [Mistura de duas correntes] QC | L6: =IFERROR($G$29*$G$30+$G$31*$G$32,"") -> 28000
B7: A · IDENTIFICAÇÃO | K7: [Mistura de duas correntes] Cf | L7: =IFERROR($L$6/$L$5,"") -> 140
B8: O que calcula | C8: Concentrações e massas em sistemas com entradas e saídas, aplicando a conservação da massa. | K8: [Mistura de duas correntes] L1 | L8: =IFERROR($G$29*$G$30*0.001,"") -> 24
B9: Quando usar | C9: Mistura de efluentes, lançamento em rios, decantadores e adensadores, tanques e reatores, problemas de regime permanente. | K9: [Mistura de duas correntes] L2 | L9: =IFERROR($G$31*$G$32*0.001,"") -> 4
B10: Exemplo prático | C10: Duas correntes de 120 e 80 m³/dia, com 200 e 50 mg/L, formam uma mistura de 140 mg/L. | K10: [Mistura de duas correntes] Lt | L10: =IFERROR($L$8+$L$9,"") -> 28
K11: [Mistura de duas correntes] Cmin | L11: =IFERROR(MIN($G$30,$G$32),"") -> 50
B12: FERRAMENTAS DESTA CALCULADORA | K12: [Mistura de duas correntes] Cmax | L12: =IFERROR(MAX($G$30,$G$32),"") -> 200
B13: ▶ Ferramenta 1 | C13: Mistura de duas correntes: Calcula a vazão total e a concentração final quando duas correntes se juntam. Considera mistura completa, sem perdas e sem transformação do constituinte. | K13: [Mistura de duas correntes] mensagem de validação | L13: =IFERROR(IF($L$4=0,"Escolha um cenário na lista: Exemplo 01, Exemplo 02 ou Meu cálculo.",IF($G$29="","Informe a vazão da corrente 1 para continuar.",IF(NOT(ISNUMBER($G$29)),"A vazão da corrente 1 precisa ser um número. Confira o valor digitado.",IF($G$29<=0,"A vazão da corrente 1 deve ser maior que zero.",IF($G$30="","Informe a concentração da corrente 1 para continuar (digite 0 se for o caso).",IF(NOT(ISNUMBER($G$30)),"A concentração da corrente 1 precisa ser um número. Confira o valor digitado.",IF($G$30<0,"A concentração da corrente 1 não pode ser negativa.",IF($G$31="","Informe a vazão da corrente 2 para continuar.",IF(NOT(ISNUMBER($G$31)),"A vazão da corrente 2 precisa ser um número. Confira o valor digitado.",IF($G$31<=0,"A vazão da corrente 2 deve ser maior que zero.",IF($G$32="","Informe a concentração da corrente 2 para continuar (digite 0 se for o caso).",IF(NOT(ISNUMBER($G$32)),"A concentração da corrente 2 precisa ser um número. Confira o valor digitado.",IF($G$32<0,"A concentração da corrente 2 não pode ser negativa.",""))))))))))))),"Resultado indisponível: existem dados inválidos.")
B14: ▶ Ferramenta 2 | C14: Balanço de massa em decantadores: Calcula a concentração de sólidos no lodo a partir da entrada e do clarificado e confere se o balanço hidráulico fecha (Qe = Qa + Ql). | K14: [Mistura de duas correntes] dados válidos? | L14: =$L$13="" -> TRUE
B15: ▶ Ferramenta 3 | C15: Acúmulo de massa: Aplica a equação geral do balanço de massa para saber se o constituinte está acumulando, diminuindo ou estável dentro do sistema. Todos os termos precisam estar na mesma unidade de massa por tempo. | K15: [Mistura de duas correntes] Cf (arredondado) | L15: =IFERROR(ROUND($L$7,IF($L$7=0,0,4-INT(LOG10(ABS($L$7))))),"") -> 140
K16: [Mistura de duas correntes] Cf (texto) | L16: =IF(ISNUMBER($L$15),FIXED($L$15,IF(ROUND($L$15,0)=$L$15,0,IF(ROUND($L$15,1)=$L$15,1,IF(ROUND($L$15,2)=$L$15,2,IF(ROUND($L$15,3)=$L$15,3,IF(ROUND($L$15,4)=$L$15,4,IF(ROUND($L$15,5)=$L$15,5,IF(ROUND($L$15,6)=$L$15,6,7)))))))),"?") -> 140
B17: Ferramenta escolhida ▼ | C17: Ferramenta 1: Mistura de duas correntes | F17: A ferramenta escolhida fica com o título em verde. Use os botões azuis acima para ir até ela. | K17: [Mistura de duas correntes] Cmax (arredondado) | L17: =IFERROR(ROUND($L$12,IF($L$12=0,0,4-INT(LOG10(ABS($L$12))))),"") -> 200
B18: Resultado atual | C18: =IFERROR(CHOOSE($L$3,$L$35,$L$74,$L$94),"—") -> 140 mg/L | K18: [Mistura de duas correntes] Cmax (texto) | L18: =IF(ISNUMBER($L$17),FIXED($L$17,IF(ROUND($L$17,0)=$L$17,0,IF(ROUND($L$17,1)=$L$17,1,IF(ROUND($L$17,2)=$L$17,2,IF(ROUND($L$17,3)=$L$17,3,IF(ROUND($L$17,4)=$L$17,4,IF(ROUND($L$17,5)=$L$17,5,IF(ROUND($L$17,6)=$L$17,6,7)))))))),"?") -> 200
B19: Status | C19: =IFERROR(CHOOSE($L$3,C41,C94,C147),"Escolha uma ferramenta.") -> ✔ Dados válidos. Resultado calculado automaticamente. | K19: [Mistura de duas correntes] Cmin (arredondado) | L19: =IFERROR(ROUND($L$11,IF($L$11=0,0,4-INT(LOG10(ABS($L$11))))),"") -> 50
K20: [Mistura de duas correntes] Cmin (texto) | L20: =IF(ISNUMBER($L$19),FIXED($L$19,IF(ROUND($L$19,0)=$L$19,0,IF(ROUND($L$19,1)=$L$19,1,IF(ROUND($L$19,2)=$L$19,2,IF(ROUND($L$19,3)=$L$19,3,IF(ROUND($L$19,4)=$L$19,4,IF(ROUND($L$19,5)=$L$19,5,IF(ROUND($L$19,6)=$L$19,6,7)))))))),"?") -> 50
B21: FERRAMENTA 1 · MISTURA DE DUAS CORRENTES | H21: ▲ Voltar ao topo | K21: [Mistura de duas correntes] Lt (arredondado) | L21: =IFERROR(ROUND($L$10,IF($L$10=0,0,4-INT(LOG10(ABS($L$10))))),"") -> 28
B22: Calcula a vazão total e a concentração final quando duas correntes se juntam. Considera mistura completa, sem perdas e sem transformação do constituinte. | K22: [Mistura de duas correntes] Lt (texto) | L22: =IF(ISNUMBER($L$21),FIXED($L$21,IF(ROUND($L$21,0)=$L$21,0,IF(ROUND($L$21,1)=$L$21,1,IF(ROUND($L$21,2)=$L$21,2,IF(ROUND($L$21,3)=$L$21,3,IF(ROUND($L$21,4)=$L$21,4,IF(ROUND($L$21,5)=$L$21,5,IF(ROUND($L$21,6)=$L$21,6,7)))))))),"?") -> 28
K23: [Mistura de duas correntes] C1 (arredondado) | L23: =IFERROR(ROUND($G$30,IF($G$30=0,0,4-INT(LOG10(ABS($G$30))))),"") -> 200
B24: B · ESCOLHA DO CENÁRIO | K24: [Mistura de duas correntes] C1 (texto) | L24: =IF(ISNUMBER($L$23),FIXED($L$23,IF(ROUND($L$23,0)=$L$23,0,IF(ROUND($L$23,1)=$L$23,1,IF(ROUND($L$23,2)=$L$23,2,IF(ROUND($L$23,3)=$L$23,3,IF(ROUND($L$23,4)=$L$23,4,IF(ROUND($L$23,5)=$L$23,5,IF(ROUND($L$23,6)=$L$23,6,7)))))))),"?") -> 200
B25: Cenário ▼ | C25: Exemplo 01 | E25: Exemplo 01 e Exemplo 02 usam dados prontos. Meu cálculo usa os valores que você digitar na coluna amarela. | K25: [Mistura de duas correntes] C2 (arredondado) | L25: =IFERROR(ROUND($G$32,IF($G$32=0,0,4-INT(LOG10(ABS($G$32))))),"") -> 50
K26: [Mistura de duas correntes] C2 (texto) | L26: =IF(ISNUMBER($L$25),FIXED($L$25,IF(ROUND($L$25,0)=$L$25,0,IF(ROUND($L$25,1)=$L$25,1,IF(ROUND($L$25,2)=$L$25,2,IF(ROUND($L$25,3)=$L$25,3,IF(ROUND($L$25,4)=$L$25,4,IF(ROUND($L$25,5)=$L$25,5,IF(ROUND($L$25,6)=$L$25,6,7)))))))),"?") -> 50
B27: C · DADOS DE ENTRADA | K27: [Mistura de duas correntes] Q1 (arredondado) | L27: =IFERROR(ROUND($G$29,IF($G$29=0,0,4-INT(LOG10(ABS($G$29))))),"") -> 120
B28: Variável | C28: Exemplo 01 | D28: Exemplo 02 | E28: MEU CÁLCULO | F28: Unidade | G28: Valor em uso | H28: Orientação de preenchimento | K28: [Mistura de duas correntes] Q1 (texto) | L28: =IF(ISNUMBER($L$27),FIXED($L$27,IF(ROUND($L$27,0)=$L$27,0,IF(ROUND($L$27,1)=$L$27,1,IF(ROUND($L$27,2)=$L$27,2,IF(ROUND($L$27,3)=$L$27,3,IF(ROUND($L$27,4)=$L$27,4,IF(ROUND($L$27,5)=$L$27,5,IF(ROUND($L$27,6)=$L$27,6,7)))))))),"?") -> 120
B29: Vazão da corrente 1 | C29: 120 | D29: 432 | F29: m³/dia | G29: =IF($L$4=1,C29,IF($L$4=2,D29,IF($L$4=3,IF(E29="","",E29),""))) -> 120 | H29: Vazão da primeira corrente. Ex.: 120 | K29: [Mistura de duas correntes] Q2 (arredondado) | L29: =IFERROR(ROUND($G$31,IF($G$31=0,0,4-INT(LOG10(ABS($G$31))))),"") -> 80
B30: Concentração da corrente 1 | C30: 200 | D30: 60 | F30: mg/L | G30: =IF($L$4=1,C30,IF($L$4=2,D30,IF($L$4=3,IF(E30="","",E30),""))) -> 200 | H30: Concentração da primeira corrente. Ex.: 200 | K30: [Mistura de duas correntes] Q2 (texto) | L30: =IF(ISNUMBER($L$29),FIXED($L$29,IF(ROUND($L$29,0)=$L$29,0,IF(ROUND($L$29,1)=$L$29,1,IF(ROUND($L$29,2)=$L$29,2,IF(ROUND($L$29,3)=$L$29,3,IF(ROUND($L$29,4)=$L$29,4,IF(ROUND($L$29,5)=$L$29,5,IF(ROUND($L$29,6)=$L$29,6,7)))))))),"?") -> 80
B31: Vazão da corrente 2 | C31: 80 | D31: 8640 | F31: m³/dia | G31: =IF($L$4=1,C31,IF($L$4=2,D31,IF($L$4=3,IF(E31="","",E31),""))) -> 80 | H31: Vazão da segunda corrente. Ex.: 80 | K31: [Mistura de duas correntes] QC (arredondado) | L31: =IFERROR(ROUND($L$6,IF($L$6=0,0,4-INT(LOG10(ABS($L$6))))),"") -> 28000
B32: Concentração da corrente 2 | C32: 50 | D32: 2 | F32: mg/L | G32: =IF($L$4=1,C32,IF($L$4=2,D32,IF($L$4=3,IF(E32="","",E32),""))) -> 50 | H32: Concentração da segunda corrente. Ex.: 50 | K32: [Mistura de duas correntes] QC (texto) | L32: =IF(ISNUMBER($L$31),FIXED($L$31,IF(ROUND($L$31,0)=$L$31,0,IF(ROUND($L$31,1)=$L$31,1,IF(ROUND($L$31,2)=$L$31,2,IF(ROUND($L$31,3)=$L$31,3,IF(ROUND($L$31,4)=$L$31,4,IF(ROUND($L$31,5)=$L$31,5,IF(ROUND($L$31,6)=$L$31,6,7)))))))),"?") -> 28.000
K33: [Mistura de duas correntes] Qt (arredondado) | L33: =IFERROR(ROUND($L$5,IF($L$5=0,0,4-INT(LOG10(ABS($L$5))))),"") -> 200
B34: D · RESULTADO AUTOMÁTICO | K34: [Mistura de duas correntes] Qt (texto) | L34: =IF(ISNUMBER($L$33),FIXED($L$33,IF(ROUND($L$33,0)=$L$33,0,IF(ROUND($L$33,1)=$L$33,1,IF(ROUND($L$33,2)=$L$33,2,IF(ROUND($L$33,3)=$L$33,3,IF(ROUND($L$33,4)=$L$33,4,IF(ROUND($L$33,5)=$L$33,5,IF(ROUND($L$33,6)=$L$33,6,7)))))))),"?") -> 200
B35: CONCENTRAÇÃO FINAL DA MISTURA | E35: OUTROS RESULTADOS | K35: [Mistura de duas correntes] resumo | L35: =IF($L$14,$L$16&" "&"mg/L","—") -> 140 mg/L
B36: =IF($L$14,$L$7,"—") -> 140 | D36: mg/L | E36: Vazão total | G36: =IF($L$14,$L$5,"—") -> 200 | H36: m³/dia | K36: índice do cenário (1, 2 ou 3) | L36: =IFERROR(MATCH($C$77,{"Exemplo 01","Exemplo 02","Meu cálculo"},0),0) -> 1
E37: Carga da corrente 1 | G37: =IF($L$14,$L$8,"—") -> 24 | H37: kg/dia | K37: [Balanço em decantadores] QeCe | L37: =IFERROR($G$81*$G$82,"") -> 90000
E38: Carga da corrente 2 | G38: =IF($L$14,$L$9,"—") -> 4 | H38: kg/dia | K38: [Balanço em decantadores] QaCa | L38: =IFERROR($G$83*$G$84,"") -> 14700
E39: Carga total | G39: =IF($L$14,$L$10,"—") -> 28 | H39: kg/dia | K39: [Balanço em decantadores] Cl | L39: =IFERROR(($L$37-$L$38)/$G$85,"") -> 7530
B40: Interpretação | C40: =IF($L$14,IF($G$30=$G$32,"As duas correntes têm a mesma concentração, então a mistura também fica com "&$L$16&" mg/L.","A mistura fica com "&$L$16&" mg/L. O valor está entre "&$L$20&" e "&$L$18&" mg/L e fica mais perto da corrente de maior vazão, porque a média é ponderada pelas vazões.")&" A carga total ("&$L$22&" kg/dia) é a soma das cargas das duas correntes.","Resultado indisponível: corrija o item indicado em Status dos dados.") -> A mistura fica com 140 mg/L. O valor está entre 50 e 200 mg/L e fica mais perto da corrente de maior vazão, porque a média é ponderada pelas vazões. A carga total (28 kg/dia) é a soma das cargas das duas correntes. | K40: [Balanço em decantadores] Le | L40: =IFERROR($L$37*0.001,"") -> 90
...

Sheet 06 — Diluição de Soluções
B1: 🧪 CALCULADORA 05 · DILUIÇÃO DE SOLUÇÕES | K1: ÁREA TÉCNICA · cálculos auxiliares (não editar)
B2: KIT DE 6 CALCULADORAS AUTOMÁTICAS DE ENGENHARIA AMBIENTAL | K2: Descrição | L2: Valor
B3: 🏠 Painel | C3: 📘 Guia | E3: 📚 Exemplos | G3: ◀ Anterior | H3: Próxima aba ▶ | K3: índice do cenário (1, 2 ou 3) | L3: =IFERROR(MATCH($C$19,{"Exemplo 01","Exemplo 02","Meu cálculo"},0),0) -> 1
K4: [Diluição de soluções] m | L4: =IFERROR(IFERROR(MATCH($G$23,{"V₁ (volume de estoque)","C₂ (concentração final)","V₂ (volume final)","C₁ (concentração do estoque)"},0),0),"") -> 1
B5: COMO USAR: ① Escolha o cenário na lista amarela ② Para usar seus dados, escolha Meu cálculo e digite na coluna amarela MEU CÁLCULO ③ Veja o resultado no card verde ④ Confira a conta em ENTENDA O CÁLCULO | K5: [Diluição de soluções] ic1 | L5: =IFERROR(MATCH($G$25,{"mg/L","g/L","µg/L","% (m/v)","mol/L","mmol/L"},0),"") -> 1
K6: [Diluição de soluções] fc1 | L6: =IFERROR(CHOOSE($L$5,1,1000,0.001,10000,1,0.001),"") -> 1
B7: A · IDENTIFICAÇÃO | K7: [Diluição de soluções] fam1 | L7: =IFERROR(CHOOSE($L$5,1,1,1,1,2,2),"") -> 1
B8: O que calcula | C8: Volume de estoque, concentração final, volume final ou concentração do estoque, usando C₁ × V₁ = C₂ × V₂. | K8: [Diluição de soluções] ic2 | L8: =IFERROR(MATCH($G$29,{"mg/L","g/L","µg/L","% (m/v)","mol/L","mmol/L"},0),"") -> 1
B9: Quando usar | C9: Preparo de padrões e curvas de calibração, diluição de amostras para análises (DBO, DQO, metais) e aulas de laboratório. | K9: [Diluição de soluções] fc2 | L9: =IFERROR(CHOOSE($L$8,1,1000,0.001,10000,1,0.001),"") -> 1
B10: Exemplo prático | C10: Para preparar 500 mL a 200 mg/L com um padrão de 1.000 mg/L, use 100 mL do padrão e complete até 500 mL. | K10: [Diluição de soluções] fam2 | L10: =IFERROR(CHOOSE($L$8,1,1,1,1,2,2),"") -> 1
K11: [Diluição de soluções] fv1 | L11: =IFERROR(CHOOSE(MATCH($G$27,{"mL","L","µL"},0),1,1000,0.001),"") -> 1
B12: COMO ESTA CALCULADORA FUNCIONA | K12: [Diluição de soluções] fv2 | L12: =IFERROR(CHOOSE(MATCH($G$31,{"mL","L","µL"},0),1,1000,0.001),"") -> 1
B13: ▶ Ir para o cálculo | C13: Diluição: C₁ × V₁ = C₂ × V₂: Escolha o que deseja encontrar. A variável escolhida é calculada e o valor digitado nela é ignorado. Cada concentração e cada volume tem sua própria unidade. | K13: [Diluição de soluções] c1b | L13: =IFERROR(IF($L$4=4,"",$G$24*$L$6),"") -> 1000
K14: [Diluição de soluções] v1b | L14: =IFERROR(IF($L$4=1,"",$G$26*$L$11),"")
B15: DILUIÇÃO: C₁ × V₁ = C₂ × V₂ | H15: ▲ Voltar ao topo | K15: [Diluição de soluções] c2b | L15: =IFERROR(IF($L$4=2,"",$G$28*$L$9),"") -> 200
B16: Escolha o que deseja encontrar. A variável escolhida é calculada e o valor digitado nela é ignorado. Cada concentração e cada volume tem sua própria unidade. | K16: [Diluição de soluções] v2b | L16: =IFERROR(IF($L$4=3,"",$G$30*$L$12),"") -> 500
K17: [Diluição de soluções] rb | L17: =IFERROR(CHOOSE($L$4,$L$15*$L$16/$L$13,$L$13*$L$14/$L$16,$L$13*$L$14/$L$15,$L$15*$L$16/$L$14),"") -> 100
B18: B · ESCOLHA DO CENÁRIO | K18: [Diluição de soluções] r | L18: =IFERROR(CHOOSE($L$4,$L$17/$L$11,$L$17/$L$9,$L$17/$L$12,$L$17/$L$6),"") -> 100
B19: Cenário ▼ | C19: Exemplo 01 | E19: Exemplo 01 e Exemplo 02 usam dados prontos. Meu cálculo usa os valores que você digitar na coluna amarela. | K19: [Diluição de soluções] C1f | L19: =IFERROR(IF($L$4=4,$L$17,$L$13),"") -> 1000
K20: [Diluição de soluções] V1f | L20: =IFERROR(IF($L$4=1,$L$17,$L$14),"") -> 100
B21: C · DADOS DE ENTRADA | K21: [Diluição de soluções] C2f | L21: =IFERROR(IF($L$4=2,$L$17,$L$15),"") -> 200
B22: Variável | C22: Exemplo 01 | D22: Exemplo 02 | E22: MEU CÁLCULO | F22: Unidade | G22: Valor em uso | H22: Orientação de preenchimento | K22: [Diluição de soluções] V2f | L22: =IFERROR(IF($L$4=3,$L$17,$L$16),"") -> 500
B23: O que deseja encontrar? | C23: V₁ (volume de estoque) | D23: C₂ (concentração final) | E23: V₁ (volume de estoque) | F23: lista ▼ | G23: =IF($L$3=1,C23,IF($L$3=2,D23,IF($L$3=3,IF(E23="","",E23),""))) -> V₁ (volume de estoque) | H23: Escolha a incógnita do problema. | K23: [Diluição de soluções] C1u | L23: =IFERROR($L$19/$L$6,"") -> 1000
B24: C₁: concentração do estoque | C24: 1000 | D24: 1 | F24: =$G$25 -> mg/L | G24: =IF(IFERROR(MATCH($G$23,{"V₁ (volume de estoque)","C₂ (concentração final)","V₂ (volume final)","C₁ (concentração do estoque)"},0),0)=4,"calculado ▼",IF($L$3=1,C24,IF($L$3=2,D24,IF($L$3=3,IF(E24="","",E24),"")))) -> 1000 | H24: Concentração da solução concentrada. Ex.: 1000 | K24: [Diluição de soluções] V1u | L24: =IFERROR($L$20/$L$11,"") -> 100
B25: Unidade de C₁ | C25: mg/L | D25: g/L | E25: mg/L | F25: lista ▼ | G25: =IF($L$3=1,C25,IF($L$3=2,D25,IF($L$3=3,IF(E25="","",E25),""))) -> mg/L | H25: Unidade da concentração do estoque. | K25: [Diluição de soluções] C2u | L25: =IFERROR($L$21/$L$9,"") -> 200
B26: V₁: volume do estoque | C26: — | D26: 5 | F26: =$G$27 -> mL | G26: =IF(IFERROR(MATCH($G$23,{"V₁ (volume de estoque)","C₂ (concentração final)","V₂ (volume final)","C₁ (concentração do estoque)"},0),0)=1,"calculado ▼",IF($L$3=1,C26,IF($L$3=2,D26,IF($L$3=3,IF(E26="","",E26),"")))) -> calculado ▼ | H26: Volume de estoque que será transferido. Ex.: 100 | K26: [Diluição de soluções] V2u | L26: =IFERROR($L$22/$L$12,"") -> 500
B27: Unidade de V₁ | C27: mL | D27: mL | E27: mL | F27: lista ▼ | G27: =IF($L$3=1,C27,IF($L$3=2,D27,IF($L$3=3,IF(E27="","",E27),""))) -> mL | H27: Unidade do volume de estoque. | K27: [Diluição de soluções] solvml | L27: =IFERROR($L$22-$L$20,"") -> 400
B28: C₂: concentração final | C28: 200 | D28: — | F28: =$G$29 -> mg/L | G28: =IF(IFERROR(MATCH($G$23,{"V₁ (volume de estoque)","C₂ (concentração final)","V₂ (volume final)","C₁ (concentração do estoque)"},0),0)=2,"calculado ▼",IF($L$3=1,C28,IF($L$3=2,D28,IF($L$3=3,IF(E28="","",E28),"")))) -> 200 | H28: Concentração desejada na solução final. Ex.: 200 | K28: [Diluição de soluções] solv | L28: =IFERROR($L$27/$L$12,"") -> 400
B29: Unidade de C₂ | C29: mg/L | D29: mg/L | E29: mg/L | F29: lista ▼ | G29: =IF($L$3=1,C29,IF($L$3=2,D29,IF($L$3=3,IF(E29="","",E29),""))) -> mg/L | H29: Unidade da concentração final. | K29: [Diluição de soluções] fd | L29: =IFERROR($L$19/$L$21,"") -> 5
B30: V₂: volume final | C30: 500 | D30: 250 | F30: =$G$31 -> mL | G30: =IF(IFERROR(MATCH($G$23,{"V₁ (volume de estoque)","C₂ (concentração final)","V₂ (volume final)","C₁ (concentração do estoque)"},0),0)=3,"calculado ▼",IF($L$3=1,C30,IF($L$3=2,D30,IF($L$3=3,IF(E30="","",E30),"")))) -> 500 | H30: Volume final da solução (balão). Ex.: 500 | K30: [Diluição de soluções] bu | L30: =IFERROR(IF($L$7=1,"mg/L","mol/L"),"") -> mg/L
B31: Unidade de V₂ | C31: mL | D31: mL | E31: mL | F31: lista ▼ | G31: =IF($L$3=1,C31,IF($L$3=2,D31,IF($L$3=3,IF(E31="","",E31),""))) -> mL | H31: Unidade do volume final. | K31: [Diluição de soluções] rlabel | L31: =IFERROR(CHOOSE($L$4,"VOLUME DE ESTOQUE (V₁)","CONCENTRAÇÃO FINAL (C₂)","VOLUME FINAL (V₂)","CONCENTRAÇÃO DO ESTOQUE (C₁)"),"") -> VOLUME DE ESTOQUE (V₁)
K32: [Diluição de soluções] rsym | L32: =IFERROR(CHOOSE($L$4,"V₁","C₂","V₂","C₁"),"") -> V₁
B33: D · RESULTADO AUTOMÁTICO | K33: [Diluição de soluções] runit | L33: =IFERROR(CHOOSE($L$4,$G$27,$G$29,$G$31,$G$25),"") -> mL
